Workbook

Sheet Gantt
A1: Planning — Diagramme de Gantt (charge en heures)
A2: Planning de 09/2026 à 02/2028. Cellules jaunes pâles = saisie ; une cellule mois > 0 colore la barre. Ajouter une tâche = remplir une ligne vide ; ajouter un projet, une personne ou une source = onglets dédiés.
A3: Lot | B3: Projet | C3: Tâche | D3: Responsable | E3: Statut | F3: Financement | G3: Charge | H3: Début | I3: Fin | J3: 46266 | K3: 46296 | L3: 46327 | M3: 46357 | N3: 46388 | O3: 46419 | P3: 46447 | Q3: 46478 | R3: 46508 | S3: 46539 | T3: 46569 | U3: 46600 | V3: 46631 | W3: 46661 | X3: 46692 | Y3: 46722 | Z3: 46753 | AA3: 46784 | AC3: Avancement | AD3: Tâches | AE3: Heures
A4: Lot 1 | B4: Projet A | C4: Conception d'actifs 3D | D4: Personne A | E4: En cours | F4: {=IF($C4="","",IFERROR(_xlfn.TEXTJOIN(" + ",TRUE(),IF(Répartition!$A$4:$A$103=$C4,Répartition!$B$4:$B$103&" ("&Répartition!$C$4:$C$103&"h)","")),""))} -> Interne (120h) | G4: =IF(COUNT(J4:AA4)=0,"",SUM(J4:AA4)) -> 120 | H4: =IFERROR(INDEX($J$3:$AA$3,MATCH(TRUE(),INDEX(J4:AA4>0,0),0)),"") -> 46266 | I4: =IF(SUMPRODUCT(MAX((J4:AA4>0)*COLUMN(J4:AA4)))=0,"",INDEX($J$3:$AA$3,SUMPRODUCT(MAX((J4:AA4>0)*COLUMN(J4:AA4)))-COLUMN($J$3)+1)) -> 46296 | J4: 80 | K4: 40 | AC4: Non commencé | AD4: =COUNTIF($E$4:$E$33,AC4) -> 4 | AE4: =SUMIF($E$4:$E$33,AC4,$G$4:$G$33) -> 1500
A5: Lot 5 | B5: Projet A | C5: Modélisation système | D5: Personne A | E5: Non commencé | F5: {=IF($C5="","",IFERROR(_xlfn.TEXTJOIN(" + ",TRUE(),IF(Répartition!$A$4:$A$103=$C5,Répartition!$B$4:$B$103&" ("&Répartition!$C$4:$C$103&"h)","")),""))} -> Interne (200h) | G5: =IF(COUNT(J5:AA5)=0,"",SUM(J5:AA5)) -> 200 | H5: =IFERROR(INDEX($J$3:$AA$3,MATCH(TRUE(),INDEX(J5:AA5>0,0),0)),"") -> 46296 | I5: =IF(SUMPRODUCT(MAX((J5:AA5>0)*COLUMN(J5:AA5)))=0,"",INDEX($J$3:$AA$3,SUMPRODUCT(MAX((J5:AA5>0)*COLUMN(J5:AA5)))-COLUMN($J$3)+1)) -> 46296 | K5: 200 | AC5: En cours | AD5: =COUNTIF($E$4:$E$33,AC5) -> 1 | AE5: =SUMIF($E$4:$E$33,AC5,$G$4:$G$33) -> 120
A6: Lot 2 | B6: Projet B | C6: Intégration technique | D6: Personne B | E6: Non commencé | F6: {=IF($C6="","",IFERROR(_xlfn.TEXTJOIN(" + ",TRUE(),IF(Répartition!$A$4:$A$103=$C6,Répartition!$B$4:$B$103&" ("&Répartition!$C$4:$C$103&"h)","")),""))} -> Client A (300h) + Subvention (180h) | G6: =IF(COUNT(J6:AA6)=0,"",SUM(J6:AA6)) -> 480 | H6: =IFERROR(INDEX($J$3:$AA$3,MATCH(TRUE(),INDEX(J6:AA6>0,0),0)),"") -> 46296 | I6: =IF(SUMPRODUCT(MAX((J6:AA6>0)*COLUMN(J6:AA6)))=0,"",INDEX($J$3:$AA$3,SUMPRODUCT(MAX((J6:AA6>0)*COLUMN(J6:AA6)))-COLUMN($J$3)+1)) -> 46357 | K6: 80 | L6: 320 | M6: 80 | AC6: Réalisé | AD6: =COUNTIF($E$4:$E$33,AC6) -> 0 | AE6: =SUMIF($E$4:$E$33,AC6,$G$4:$G$33) -> 0
A7: Lot 3 | B7: Projet B | C7: Configuration scénarios | D7: Personne B | E7: Non commencé | F7: {=IF($C7="","",IFERROR(_xlfn.TEXTJOIN(" + ",TRUE(),IF(Répartition!$A$4:$A$103=$C7,Répartition!$B$4:$B$103&" ("&Répartition!$C$4:$C$103&"h)","")),""))} -> Client A (500h) | G7: =IF(COUNT(J7:AA7)=0,"",SUM(J7:AA7)) -> 500 | H7: =IFERROR(INDEX($J$3:$AA$3,MATCH(TRUE(),INDEX(J7:AA7>0,0),0)),"") -> 46357 | I7: =IF(SUMPRODUCT(MAX((J7:AA7>0)*COLUMN(J7:AA7)))=0,"",INDEX($J$3:$AA$3,SUMPRODUCT(MAX((J7:AA7>0)*COLUMN(J7:AA7)))-COLUMN($J$3)+1)) -> 46388 | L7: 0 | M7: 240 | N7: 260 | AC7: % réalisé (h) | AE7: =IFERROR(AE6/SUM(AE4:AE6),0) -> 0
A8: Lot 4 | B8: Projet A | C8: Préparation livraison | D8: Personne A | E8: Non commencé | F8: {=IF($C8="","",IFERROR(_xlfn.TEXTJOIN(" + ",TRUE(),IF(Répartition!$A$4:$A$103=$C8,Répartition!$B$4:$B$103&" ("&Répartition!$C$4:$C$103&"h)","")),""))} -> Client A (220h) + Client B (100h) | G8: =IF(COUNT(J8:AA8)=0,"",SUM(J8:AA8)) -> 320 | H8: =IFERROR(INDEX($J$3:$AA$3,MATCH(TRUE(),INDEX(J8:AA8>0,0),0)),"") -> 46388 | I8: =IF(SUMPRODUCT(MAX((J8:AA8>0)*COLUMN(J8:AA8)))=0,"",INDEX($J$3:$AA$3,SUMPRODUCT(MAX((J8:AA8>0)*COLUMN(J8:AA8)))-COLUMN($J$3)+1)) -> 46419 | N8: 60 | O8: 260
F9: {=IF($C9="","",IFERROR(_xlfn.TEXTJOIN(" + ",TRUE(),IF(Répartition!$A$4:$A$103=$C9,Répartition!$B$4:$B$103&" ("&Répartition!$C$4:$C$103&"h)","")),""))} | G9: =IF(COUNT(J9:AA9)=0,"",SUM(J9:AA9)) | H9: =IFERROR(INDEX($J$3:$AA$3,MATCH(TRUE(),INDEX(J9:AA9>0,0),0)),"") | I9: =IF(SUMPRODUCT(MAX((J9:AA9>0)*COLUMN(J9:AA9)))=0,"",INDEX($J$3:$AA$3,SUMPRODUCT(MAX((J9:AA9>0)*COLUMN(J9:AA9)))-COLUMN($J$3)+1))
F10: {=IF($C10="","",IFERROR(_xlfn.TEXTJOIN(" + ",TRUE(),IF(Répartition!$A$4:$A$103=$C10,Répartition!$B$4:$B$103&" ("&Répartition!$C$4:$C$103&"h)","")),""))} | G10: =IF(COUNT(J10:AA10)=0,"",SUM(J10:AA10)) | H10: =IFERROR(INDEX($J$3:$AA$3,MATCH(TRUE(),INDEX(J10:AA10>0,0),0)),"") | I10: =IF(SUMPRODUCT(MAX((J10:AA10>0)*COLUMN(J10:AA10)))=0,"",INDEX($J$3:$AA$3,SUMPRODUCT(MAX((J10:AA10>0)*COLUMN(J10:AA10)))-COLUMN($J$3)+1))
F11: {=IF($C11="","",IFERROR(_xlfn.TEXTJOIN(" + ",TRUE(),IF(Répartition!$A$4:$A$103=$C11,Répartition!$B$4:$B$103&" ("&Répartition!$C$4:$C$103&"h)","")),""))} | G11: =IF(COUNT(J11:AA11)=0,"",SUM(J11:AA11)) | H11: =IFERROR(INDEX($J$3:$AA$3,MATCH(TRUE(),INDEX(J11:AA11>0,0),0)),"") | I11: =IF(SUMPRODUCT(MAX((J11:AA11>0)*COLUMN(J11:AA11)))=0,"",INDEX($J$3:$AA$3,SUMPRODUCT(MAX((J11:AA11>0)*COLUMN(J11:AA11)))-COLUMN($J$3)+1))
F12: {=IF($C12="","",IFERROR(_xlfn.TEXTJOIN(" + ",TRUE(),IF(Répartition!$A$4:$A$103=$C12,Répartition!$B$4:$B$103&" ("&Répartition!$C$4:$C$103&"h)","")),""))} | G12: =IF(COUNT(J12:AA12)=0,"",SUM(J12:AA12)) | H12: =IFERROR(INDEX($J$3:$AA$3,MATCH(TRUE(),INDEX(J12:AA12>0,0),0)),"") | I12: =IF(SUMPRODUCT(MAX((J12:AA12>0)*COLUMN(J12:AA12)))=0,"",INDEX($J$3:$AA$3,SUMPRODUCT(MAX((J12:AA12>0)*COLUMN(J12:AA12)))-COLUMN($J$3)+1))
F13: {=IF($C13="","",IFERROR(_xlfn.TEXTJOIN(" + ",TRUE(),IF(Répartition!$A$4:$A$103=$C13,Répartition!$B$4:$B$103&" ("&Répartition!$C$4:$C$103&"h)","")),""))} | G13: =IF(COUNT(J13:AA13)=0,"",SUM(J13:AA13)) | H13: =IFERROR(INDEX($J$3:$AA$3,MATCH(TRUE(),INDEX(J13:AA13>0,0),0)),"") | I13: =IF(SUMPRODUCT(MAX((J13:AA13>0)*COLUMN(J13:AA13)))=0,"",INDEX($J$3:$AA$3,SUMPRODUCT(MAX((J13:AA13>0)*COLUMN(J13:AA13)))-COLUMN($J$3)+1))
F14: {=IF($C14="","",IFERROR(_xlfn.TEXTJOIN(" + ",TRUE(),IF(Répartition!$A$4:$A$103=$C14,Répartition!$B$4:$B$103&" ("&Répartition!$C$4:$C$103&"h)","")),""))} | G14: =IF(COUNT(J14:AA14)=0,"",SUM(J14:AA14)) | H14: =IFERROR(INDEX($J$3:$AA$3,MATCH(TRUE(),INDEX(J14:AA14>0,0),0)),"") | I14: =IF(SUMPRODUCT(MAX((J14:AA14>0)*COLUMN(J14:AA14)))=0,"",INDEX($J$3:$AA$3,SUMPRODUCT(MAX((J14:AA14>0)*COLUMN(J14:AA14)))-COLUMN($J$3)+1))
F15: {=IF($C15="","",IFERROR(_xlfn.TEXTJOIN(" + ",TRUE(),IF(Répartition!$A$4:$A$103=$C15,Répartition!$B$4:$B$103&" ("&Répartition!$C$4:$C$103&"h)","")),""))} | G15: =IF(COUNT(J15:AA15)=0,"",SUM(J15:AA15)) | H15: =IFERROR(INDEX($J$3:$AA$3,MATCH(TRUE(),INDEX(J15:AA15>0,0),0)),"") | I15: =IF(SUMPRODUCT(MAX((J15:AA15>0)*COLUMN(J15:AA15)))=0,"",INDEX($J$3:$AA$3,SUMPRODUCT(MAX((J15:AA15>0)*COLUMN(J15:AA15)))-COLUMN($J$3)+1))
F16: {=IF($C16="","",IFERROR(_xlfn.TEXTJOIN(" + ",TRUE(),IF(Répartition!$A$4:$A$103=$C16,Répartition!$B$4:$B$103&" ("&Répartition!$C$4:$C$103&"h)","")),""))} | G16: =IF(COUNT(J16:AA16)=0,"",SUM(J16:AA16)) | H16: =IFERROR(INDEX($J$3:$AA$3,MATCH(TRUE(),INDEX(J16:AA16>0,0),0)),"") | I16: =IF(SUMPRODUCT(MAX((J16:AA16>0)*COLUMN(J16:AA16)))=0,"",INDEX($J$3:$AA$3,SUMPRODUCT(MAX((J16:AA16>0)*COLUMN(J16:AA16)))-COLUMN($J$3)+1))
F17: {=IF($C17="","",IFERROR(_xlfn.TEXTJOIN(" + ",TRUE(),IF(Répartition!$A$4:$A$103=$C17,Répartition!$B$4:$B$103&" ("&Répartition!$C$4:$C$103&"h)","")),""))} | G17: =IF(COUNT(J17:AA17)=0,"",SUM(J17:AA17)) | H17: =IFERROR(INDEX($J$3:$AA$3,MATCH(TRUE(),INDEX(J17:AA17>0,0),0)),"") | I17: =IF(SUMPRODUCT(MAX((J17:AA17>0)*COLUMN(J17:AA17)))=0,"",INDEX($J$3:$AA$3,SUMPRODUCT(MAX((J17:AA17>0)*COLUMN(J17:AA17)))-COLUMN($J$3)+1))
F18: {=IF($C18="","",IFERROR(_xlfn.TEXTJOIN(" + ",TRUE(),IF(Répartition!$A$4:$A$103=$C18,Répartition!$B$4:$B$103&" ("&Répartition!$C$4:$C$103&"h)","")),""))} | G18: =IF(COUNT(J18:AA18)=0,"",SUM(J18:AA18)) | H18: =IFERROR(INDEX($J$3:$AA$3,MATCH(TRUE(),INDEX(J18:AA18>0,0),0)),"") | I18: =IF(SUMPRODUCT(MAX((J18:AA18>0)*COLUMN(J18:AA18)))=0,"",INDEX($J$3:$AA$3,SUMPRODUCT(MAX((J18:AA18>0)*COLUMN(J18:AA18)))-COLUMN($J$3)+1))
F19: {=IF($C19="","",IFERROR(_xlfn.TEXTJOIN(" + ",TRUE(),IF(Répartition!$A$4:$A$103=$C19,Répartition!$B$4:$B$103&" ("&Répartition!$C$4:$C$103&"h)","")),""))} | G19: =IF(COUNT(J19:AA19)=0,"",SUM(J19:AA19)) | H19: =IFERROR(INDEX($J$3:$AA$3,MATCH(TRUE(),INDEX(J19:AA19>0,0),0)),"") | I19: =IF(SUMPRODUCT(MAX((J19:AA19>0)*COLUMN(J19:AA19)))=0,"",INDEX($J$3:$AA$3,SUMPRODUCT(MAX((J19:AA19>0)*COLUMN(J19:AA19)))-COLUMN($J$3)+1))
F20: {=IF($C20="","",IFERROR(_xlfn.TEXTJOIN(" + ",TRUE(),IF(Répartition!$A$4:$A$103=$C20,Répartition!$B$4:$B$103&" ("&Répartition!$C$4:$C$103&"h)","")),""))} | G20: =IF(COUNT(J20:AA20)=0,"",SUM(J20:AA20)) | H20: =IFERROR(INDEX($J$3:$AA$3,MATCH(TRUE(),INDEX(J20:AA20>0,0),0)),"") | I20: =IF(SUMPRODUCT(MAX((J20:AA20>0)*COLUMN(J20:AA20)))=0,"",INDEX($J$3:$AA$3,SUMPRODUCT(MAX((J20:AA20>0)*COLUMN(J20:AA20)))-COLUMN($J$3)+1))
... F33: {=IF($C33="","",IFERROR(_xlfn.TEXTJOIN(" + ",TRUE(),IF(Répartition!$A$4:$A$103=$C33,Répartition!$B$4:$B$103&" ("&Répartition!$C$4:$C$103&"h)","")),""))} | G33: =IF(COUNT(J33:AA33)=0,"",SUM(J33:AA33)) | H33: =IFERROR(INDEX($J$3:$AA$3,MATCH(TRUE(),INDEX(J33:AA33>0,0),0)),"") | I33: =IF(SUMPRODUCT(MAX((J33:AA33>0)*COLUMN(J33:AA33)))=0,"",INDEX($J$3:$AA$3,SUMPRODUCT(MAX((J33:AA33>0)*COLUMN(J33:AA33)))-COLUMN($J$3)+1))
A34: TOTAL | G34: =SUM(G4:G33) -> 1620 | J34: =SUM(J4:J33) -> 80 | K34: =SUM(K4:K33) -> 320 | L34: =SUM(L4:L33) -> 320 | M34: =SUM(M4:M33) -> 320 | N34: =SUM(N4:N33) -> 320 | O34: =SUM(O4:O33) -> 260 | P34: =SUM(P4:P33) -> 0 | Q34: =SUM(Q4:Q33) -> 0 | ... AA34: =SUM(AA4:AA33) -> 0
A36: Jalons & livrables
A37: Type | B37: Projet | C37: Intitulé | D37: Responsable | E37: Statut | F37: Financement | G37: Lot | H37: Échéance | I37: Commentaire | J37: 46266 | K37: 46296 | L37: 46327 | M37: 46357 | N37: 46388 | O37: 46419 | P37: 46447 | Q37: 46478 | R37: 46508 | S37: 46539 | T37: 46569 | U37: 46600 | V37: 46631 | W37: 46661 | X37: 46692 | Y37: 46722 | Z37: 46753 | AA37: 46784
A38: Jalon | B38: Projet A | C38: Revue de conception | D38: Personne A | E38: Non commencé | F38: Interne | G38: Lot 1 | H38: 46296 | J38: =IF($H38=J$37,IF($A38="Jalon","◆",IF($A38="Livrable","▲","●")),"") | K38: =IF($H38=K$37,IF($A38="Jalon","◆",IF($A38="Livrable","▲","●")),"") -> ◆ | L38: =IF($H38=L$37,IF($A38="Jalon","◆",IF($A38="Livrable","▲","●")),"") | M38: =IF($H38=M$37,IF($A38="Jalon","◆",IF($A38="Livrable","▲","●")),"") | N38: =IF($H38=N$37,IF($A38="Jalon","◆",IF($A38="Livrable","▲","●")),"") | O38: =IF($H38=O$37,IF($A38="Jalon","◆",IF($A38="Livrable","▲","●")),"") | P38: =IF($H38=P$37,IF($A38="Jalon","◆",IF($A38="Livrable","▲","●")),"") | Q38: =IF($H38=Q$37,IF($A38="Jalon","◆",IF($A38="Livrable","▲","●")),"") | ... AA38: =IF($H38=AA$37,IF($A38="Jalon","◆",IF($A38="Livrable","▲","●")),"")
A39: Livrable | B39: Projet A | C39: Dossier de livraison | D39: Personne B | E39: Non commencé | F39: Client A | G39: Lot 4 | H39: 46419 | J39: =IF($H39=J$37,IF($A39="Jalon","◆",IF($A39="Livrable","▲","●")),"") | K39: =IF($H39=K$37,IF($A39="Jalon","◆",IF($A39="Livrable","▲","●")),"") | L39: =IF($H39=L$37,IF($A39="Jalon","◆",IF($A39="Livrable","▲","●")),"") | M39: =IF($H39=M$37,IF($A39="Jalon","◆",IF($A39="Livrable","▲","●")),"") | N39: =IF($H39=N$37,IF($A39="Jalon","◆",IF($A39="Livrable","▲","●")),"") | O39: =IF($H39=O$37,IF($A39="Jalon","◆",IF($A39="Livrable","▲","●")),"") -> ▲ | P39: =IF($H39=P$37,IF($A39="Jalon","◆",IF($A39="Livrable","▲","●")),"") | Q39: =IF($H39=Q$37,IF($A39="Jalon","◆",IF($A39="Livrable","▲","●")),"") | ... AA39: =IF($H39=AA$37,IF($A39="Jalon","◆",IF($A39="Livrable","▲","●")),"")
J40: =IF($H40=J$37,IF($A40="Jalon","◆",IF($A40="Livrable","▲","●")),"") | K40: =IF($H40=K$37,IF($A40="Jalon","◆",IF($A40="Livrable","▲","●")),"") | L40: =IF($H40=L$37,IF($A40="Jalon","◆",IF($A40="Livrable","▲","●")),"") | M40: =IF($H40=M$37,IF($A40="Jalon","◆",IF($A40="Livrable","▲","●")),"") | N40: =IF($H40=N$37,IF($A40="Jalon","◆",IF($A40="Livrable","▲","●")),"") | O40: =IF($H40=O$37,IF($A40="Jalon","◆",IF($A40="Livrable","▲","●")),"") | P40: =IF($H40=P$37,IF($A40="Jalon","◆",IF($A40="Livrable","▲","●")),"") | Q40: =IF($H40=Q$37,IF($A40="Jalon","◆",IF($A40="Livrable","▲","●")),"") | ... AA40: =IF($H40=AA$37,IF($A40="Jalon","◆",IF($A40="Livrable","▲","●")),"")
J41: =IF($H41=J$37,IF($A41="Jalon","◆",IF($A41="Livrable","▲","●")),"") | K41: =IF($H41=K$37,IF($A41="Jalon","◆",IF($A41="Livrable","▲","●")),"") | L41: =IF($H41=L$37,IF($A41="Jalon","◆",IF($A41="Livrable","▲","●")),"") | M41: =IF($H41=M$37,IF($A41="Jalon","◆",IF($A41="Livrable","▲","●")),"") | N41: =IF($H41=N$37,IF($A41="Jalon","◆",IF($A41="Livrable","▲","●")),"") | O41: =IF($H41=O$37,IF($A41="Jalon","◆",IF($A41="Livrable","▲","●")),"") | P41: =IF($H41=P$37,IF($A41="Jalon","◆",IF($A41="Livrable","▲","●")),"") | Q41: =IF($H41=Q$37,IF($A41="Jalon","◆",IF($A41="Livrable","▲","●")),"") | ... AA41: =IF($H41=AA$37,IF($A41="Jalon","◆",IF($A41="Livrable","▲","●")),"")
J42: =IF($H42=J$37,IF($A42="Jalon","◆",IF($A42="Livrable","▲","●")),"") | K42: =IF($H42=K$37,IF($A42="Jalon","◆",IF($A42="Livrable","▲","●")),"") | L42: =IF($H42=L$37,IF($A42="Jalon","◆",IF($A42="Livrable","▲","●")),"") | M42: =IF($H42=M$37,IF($A42="Jalon","◆",IF($A42="Livrable","▲","●")),"") | N42: =IF($H42=N$37,IF($A42="Jalon","◆",IF($A42="Livrable","▲","●")),"") | O42: =IF($H42=O$37,IF($A42="Jalon","◆",IF($A42="Livrable","▲","●")),"") | P42: =IF($H42=P$37,IF($A42="Jalon","◆",IF($A42="Livrable","▲","●")),"") | Q42: =IF($H42=Q$37,IF($A42="Jalon","◆",IF($A42="Livrable","▲","●")),"") | ... AA42: =IF($H42=AA$37,IF($A42="Jalon","◆",IF($A42="Livrable","▲","●")),"")
J43: =IF($H43=J$37,IF($A43="Jalon","◆",IF($A43="Livrable","▲","●")),"") | K43: =IF($H43=K$37,IF($A43="Jalon","◆",IF($A43="Livrable","▲","●")),"") | L43: =IF($H43=L$37,IF($A43="Jalon","◆",IF($A43="Livrable","▲","●")),"") | M43: =IF($H43=M$37,IF($A43="Jalon","◆",IF($A43="Livrable","▲","●")),"") | N43: =IF($H43=N$37,IF($A43="Jalon","◆",IF($A43="Livrable","▲","●")),"") | O43: =IF($H43=O$37,IF($A43="Jalon","◆",IF($A43="Livrable","▲","●")),"") | P43: =IF($H43=P$37,IF($A43="Jalon","◆",IF($A43="Livrable","▲","●")),"") | Q43: =IF($H43=Q$37,IF($A43="Jalon","◆",IF($A43="Livrable","▲","●")),"") | ... AA43: =IF($H43=AA$37,IF($A43="Jalon","◆",IF($A43="Livrable","▲","●")),"")
J44: =IF($H44=J$37,IF($A44="Jalon","◆",IF($A44="Livrable","▲","●")),"") | K44: =IF($H44=K$37,IF($A44="Jalon","◆",IF($A44="Livrable","▲","●")),"") | L44: =IF($H44=L$37,IF($A44="Jalon","◆",IF($A44="Livrable","▲","●")),"") | M44: =IF($H44=M$37,IF($A44="Jalon","◆",IF($A44="Livrable","▲","●")),"") | N44: =IF($H44=N$37,IF($A44="Jalon","◆",IF($A44="Livrable","▲","●")),"") | O44: =IF($H44=O$37,IF($A44="Jalon","◆",IF($A44="Livrable","▲","●")),"") | P44: =IF($H44=P$37,IF($A44="Jalon","◆",IF($A44="Livrable","▲","●")),"") | Q44: =IF($H44=Q$37,IF($A44="Jalon","◆",IF($A44="Livrable","▲","●")),"") | ... AA44: =IF($H44=AA$37,IF($A44="Jalon","◆",IF($A44="Livrable","▲","●")),"")
J45: =IF($H45=J$37,IF($A45="Jalon","◆",IF($A45="Livrable","▲","●")),"") | K45: =IF($H45=K$37,IF($A45="Jalon","◆",IF($A45="Livrable","▲","●")),"") | L45: =IF($H45=L$37,IF($A45="Jalon","◆",IF($A45="Livrable","▲","●")),"") | M45: =IF($H45=M$37,IF($A45="Jalon","◆",IF($A45="Livrable","▲","●")),"") | N45: =IF($H45=N$37,IF($A45="Jalon","◆",IF($A45="Livrable","▲","●")),"") | O45: =IF($H45=O$37,IF($A45="Jalon","◆",IF($A45="Livrable","▲","●")),"") | P45: =IF($H45=P$37,IF($A45="Jalon","◆",IF($A45="Livrable","▲","●")),"") | Q45: =IF($H45=Q$37,IF($A45="Jalon","◆",IF($A45="Livrable","▲","●")),"") | ... AA45: =IF($H45=AA$37,IF($A45="Jalon","◆",IF($A45="Livrable","▲","●")),"")
J46: =IF($H46=J$37,IF($A46="Jalon","◆",IF($A46="Livrable","▲","●")),"") | K46: =IF($H46=K$37,IF($A46="Jalon","◆",IF($A46="Livrable","▲","●")),"") | L46: =IF($H46=L$37,IF($A46="Jalon","◆",IF($A46="Livrable","▲","●")),"") | M46: =IF($H46=M$37,IF($A46="Jalon","◆",IF($A46="Livrable","▲","●")),"") | N46: =IF($H46=N$37,IF($A46="Jalon","◆",IF($A46="Livrable","▲","●")),"") | O46: =IF($H46=O$37,IF($A46="Jalon","◆",IF($A46="Livrable","▲","●")),"") | P46: =IF($H46=P$37,IF($A46="Jalon","◆",IF($A46="Livrable","▲","●")),"") | Q46: =IF($H46=Q$37,IF($A46="Jalon","◆",IF($A46="Livrable","▲","●")),"") | ... AA46: =IF($H46=AA$37,IF($A46="Jalon","◆",IF($A46="Livrable","▲","●")),"")
J47: =IF($H47=J$37,IF($A47="Jalon","◆",IF($A47="Livrable","▲","●")),"") | K47: =IF($H47=K$37,IF($A47="Jalon","◆",IF($A47="Livrable","▲","●")),"") | L47: =IF($H47=L$37,IF($A47="Jalon","◆",IF($A47="Livrable","▲","●")),"") | M47: =IF($H47=M$37,IF($A47="Jalon","◆",IF($A47="Livrable","▲","●")),"") | N47: =IF($H47=N$37,IF($A47="Jalon","◆",IF($A47="Livrable","▲","●")),"") | O47: =IF($H47=O$37,IF($A47="Jalon","◆",IF($A47="Livrable","▲","●")),"") | P47: =IF($H47=P$37,IF($A47="Jalon","◆",IF($A47="Livrable","▲","●")),"") | Q47: =IF($H47=Q$37,IF($A47="Jalon","◆",IF($A47="Livrable","▲","●")),"") | ... AA47: =IF($H47=AA$37,IF($A47="Jalon","◆",IF($A47="Livrable","▲","●")),"")
J48: =IF($H48=J$37,IF($A48="Jalon","◆",IF($A48="Livrable","▲","●")),"") | K48: =IF($H48=K$37,IF($A48="Jalon","◆",IF($A48="Livrable","▲","●")),"") | L48: =IF($H48=L$37,IF($A48="Jalon","◆",IF($A48="Livrable","▲","●")),"") | M48: =IF($H48=M$37,IF($A48="Jalon","◆",IF($A48="Livrable","▲","●")),"") | N48: =IF($H48=N$37,IF($A48="Jalon","◆",IF($A48="Livrable","▲","●")),"") | O48: =IF($H48=O$37,IF($A48="Jalon","◆",IF($A48="Livrable","▲","●")),"") | P48: =IF($H48=P$37,IF($A48="Jalon","◆",IF($A48="Livrable","▲","●")),"") | Q48: =IF($H48=Q$37,IF($A48="Jalon","◆",IF($A48="Livrable","▲","●")),"") | ... AA48: =IF($H48=AA$37,IF($A48="Jalon","◆",IF($A48="Livrable","▲","●")),"")
J49: =IF($H49=J$37,IF($A49="Jalon","◆",IF($A49="Livrable","▲","●")),"") | K49: =IF($H49=K$37,IF($A49="Jalon","◆",IF($A49="Livrable","▲","●")),"") | L49: =IF($H49=L$37,IF($A49="Jalon","◆",IF($A49="Livrable","▲","●")),"") | M49: =IF($H49=M$37,IF($A49="Jalon","◆",IF($A49="Livrable","▲","●")),"") | N49: =IF($H49=N$37,IF($A49="Jalon","◆",IF($A49="Livrable","▲","●")),"") | O49: =IF($H49=O$37,IF($A49="Jalon","◆",IF($A49="Livrable","▲","●")),"") | P49: =IF($H49=P$37,IF($A49="Jalon","◆",IF($A49="Livrable","▲","●")),"") | Q49: =IF($H49=Q$37,IF($A49="Jalon","◆",IF($A49="Livrable","▲","●")),"") | ... AA49: =IF($H49=AA$37,IF($A49="Jalon","◆",IF($A49="Livrable","▲","●")),"")
J50: =IF($H50=J$37,IF($A50="Jalon","◆",IF($A50="Livrable","▲","●")),"") | K50: =IF($H50=K$37,IF($A50="Jalon","◆",IF($A50="Livrable","▲","●")),"") | L50: =IF($H50=L$37,IF($A50="Jalon","◆",IF($A50="Livrable","▲","●")),"") | M50: =IF($H50=M$37,IF($A50="Jalon","◆",IF($A50="Livrable","▲","●")),"") | N50: =IF($H50=N$37,IF($A50="Jalon","◆",IF($A50="Livrable","▲","●")),"") | O50: =IF($H50=O$37,IF($A50="Jalon","◆",IF($A50="Livrable","▲","●")),"") | P50: =IF($H50=P$37,IF($A50="Jalon","◆",IF($A50="Livrable","▲","●")),"") | Q50: =IF($H50=Q$37,IF($A50="Jalon","◆",IF($A50="Livrable","▲","●")),"") | ... AA50: =IF($H50=AA$37,IF($A50="Jalon","◆",IF($A50="Livrable","▲","●")),"")
J51: =IF($H51=J$37,IF($A51="Jalon","◆",IF($A51="Livrable","▲","●")),"") | K51: =IF($H51=K$37,IF($A51="Jalon","◆",IF($A51="Livrable","▲","●")),"") | L51: =IF($H51=L$37,IF($A51="Jalon","◆",IF($A51="Livrable","▲","●")),"") | M51: =IF($H51=M$37,IF($A51="Jalon","◆",IF($A51="Livrable","▲","●")),"") | N51: =IF($H51=N$37,IF($A51="Jalon","◆",IF($A51="Livrable","▲","●")),"") | O51: =IF($H51=O$37,IF($A51="Jalon","◆",IF($A51="Livrable","▲","●")),"") | P51: =IF($H51=P$37,IF($A51="Jalon","◆",IF($A51="Livrable","▲","●")),"") | Q51: =IF($H51=Q$37,IF($A51="Jalon","◆",IF($A51="Livrable","▲","●")),"") | ... AA51: =IF($H51=AA$37,IF($A51="Jalon","◆",IF($A51="Livrable","▲","●")),"")
... J57: =IF($H57=J$37,IF($A57="Jalon","◆",IF($A57="Livrable","▲","●")),"") | K57: =IF($H57=K$37,IF($A57="Jalon","◆",IF($A57="Livrable","▲","●")),"") | L57: =IF($H57=L$37,IF($A57="Jalon","◆",IF($A57="Livrable","▲","●")),"") | M57: =IF($H57=M$37,IF($A57="Jalon","◆",IF($A57="Livrable","▲","●")),"") | N57: =IF($H57=N$37,IF($A57="Jalon","◆",IF($A57="Livrable","▲","●")),"") | O57: =IF($H57=O$37,IF($A57="Jalon","◆",IF($A57="Livrable","▲","●")),"") | P57: =IF($H57=P$37,IF($A57="Jalon","◆",IF($A57="Livrable","▲","●")),"") | Q57: =IF($H57=Q$37,IF($A57="Jalon","◆",IF($A57="Livrable","▲","●")),"") | ... AA57: =IF($H57=AA$37,IF($A57="Jalon","◆",IF($A57="Livrable","▲","●")),"")
A59: Légende : ◆ jalon ▲ livrable ● revue — vert = réalisé. Case de tâche encadrée = jalon/livrable du même lot ce mois-là. Statuts : gris non commencé, orange en cours, vert réalisé.

Sheet Équipe
A1: Équipe — charge par personne (h)
A3: Personne | B3: Rôle | C3: Charge totale | D3: 46266 | E3: 46296 | F3: 46327 | G3: 46357 | H3: 46388 | I3: 46419 | J3: 46447 | K3: 46478 | L3: 46508 | M3: 46539 | N3: 46569 | O3: 46600 | P3: 46631 | Q3: 46661 | R3: 46692 | S3: 46722 | T3: 46753 | U3: 46784
A4: Personne A | B4: Architecte / modélisation | C4: =IF(A4="","",SUMIF(Gantt!$D$4:$D$33,A4,Gantt!$G$4:$G$33)) -> 640 | D4: =IF($A4="","",SUMIF(Gantt!$D$4:$D$33,$A4,Gantt!J$4:J$33)) -> 80 | E4: =IF($A4="","",SUMIF(Gantt!$D$4:$D$33,$A4,Gantt!K$4:K$33)) -> 240 | F4: =IF($A4="","",SUMIF(Gantt!$D$4:$D$33,$A4,Gantt!L$4:L$33)) -> 0 | G4: =IF($A4="","",SUMIF(Gantt!$D$4:$D$33,$A4,Gantt!M$4:M$33)) -> 0 | H4: =IF($A4="","",SUMIF(Gantt!$D$4:$D$33,$A4,Gantt!N$4:N$33)) -> 60 | I4: =IF($A4="","",SUMIF(Gantt!$D$4:$D$33,$A4,Gantt!O$4:O$33)) -> 260 | J4: =IF($A4="","",SUMIF(Gantt!$D$4:$D$33,$A4,Gantt!P$4:P$33)) -> 0 | K4: =IF($A4="","",SUMIF(Gantt!$D$4:$D$33,$A4,Gantt!Q$4:Q$33)) -> 0 | ... U4: =IF($A4="","",SUMIF(Gantt!$D$4:$D$33,$A4,Gantt!AA$4:AA$33)) -> 0
A5: Personne B | B5: Développeur intégration | C5: =IF(A5="","",SUMIF(Gantt!$D$4:$D$33,A5,Gantt!$G$4:$G$33)) -> 980 | D5: =IF($A5="","",SUMIF(Gantt!$D$4:$D$33,$A5,Gantt!J$4:J$33)) -> 0 | E5: =IF($A5="","",SUMIF(Gantt!$D$4:$D$33,$A5,Gantt!K$4:K$33)) -> 80 | F5: =IF($A5="","",SUMIF(Gantt!$D$4:$D$33,$A5,Gantt!L$4:L$33)) -> 320 | G5: =IF($A5="","",SUMIF(Gantt!$D$4:$D$33,$A5,Gantt!M$4:M$33)) -> 320 | H5: =IF($A5="","",SUMIF(Gantt!$D$4:$D$33,$A5,Gantt!N$4:N$33)) -> 260 | I5: =IF($A5="","",SUMIF(Gantt!$D$4:$D$33,$A5,Gantt!O$4:O$33)) -> 0 | J5: =IF($A5="","",SUMIF(Gantt!$D$4:$D$33,$A5,Gantt!P$4:P$33)) -> 0 | K5: =IF($A5="","",SUMIF(Gantt!$D$4:$D$33,$A5,Gantt!Q$4:Q$33)) -> 0 | ... U5: =IF($A5="","",SUMIF(Gantt!$D$4:$D$33,$A5,Gantt!AA$4:AA$33)) -> 0
C6: =IF(A6="","",SUMIF(Gantt!$D$4:$D$33,A6,Gantt!$G$4:$G$33)) | D6: =IF($A6="","",SUMIF(Gantt!$D$4:$D$33,$A6,Gantt!J$4:J$33)) | E6: =IF($A6="","",SUMIF(Gantt!$D$4:$D$33,$A6,Gantt!K$4:K$33)) | F6: =IF($A6="","",SUMIF(Gantt!$D$4:$D$33,$A6,Gantt!L$4:L$33)) | G6: =IF($A6="","",SUMIF(Gantt!$D$4:$D$33,$A6,Gantt!M$4:M$33)) | H6: =IF($A6="","",SUMIF(Gantt!$D$4:$D$33,$A6,Gantt!N$4:N$33)) | I6: =IF($A6="","",SUMIF(Gantt!$D$4:$D$33,$A6,Gantt!O$4:O$33)) | J6: =IF($A6="","",SUMIF(Gantt!$D$4:$D$33,$A6,Gantt!P$4:P$33)) | K6: =IF($A6="","",SUMIF(Gantt!$D$4:$D$33,$A6,Gantt!Q$4:Q$33)) | ... U6: =IF($A6="","",SUMIF(Gantt!$D$4:$D$33,$A6,Gantt!AA$4:AA$33))
C7: =IF(A7="","",SUMIF(Gantt!$D$4:$D$33,A7,Gantt!$G$4:$G$33)) | D7: =IF($A7="","",SUMIF(Gantt!$D$4:$D$33,$A7,Gantt!J$4:J$33)) | E7: =IF($A7="","",SUMIF(Gantt!$D$4:$D$33,$A7,Gantt!K$4:K$33)) | F7: =IF($A7="","",SUMIF(Gantt!$D$4:$D$33,$A7,Gantt!L$4:L$33)) | G7: =IF($A7="","",SUMIF(Gantt!$D$4:$D$33,$A7,Gantt!M$4:M$33)) | H7: =IF($A7="","",SUMIF(Gantt!$D$4:$D$33,$A7,Gantt!N$4:N$33)) | I7: =IF($A7="","",SUMIF(Gantt!$D$4:$D$33,$A7,Gantt!O$4:O$33)) | J7: =IF($A7="","",SUMIF(Gantt!$D$4:$D$33,$A7,Gantt!P$4:P$33)) | K7: =IF($A7="","",SUMIF(Gantt!$D$4:$D$33,$A7,Gantt!Q$4:Q$33)) | ... U7: =IF($A7="","",SUMIF(Gantt!$D$4:$D$33,$A7,Gantt!AA$4:AA$33))
C8: =IF(A8="","",SUMIF(Gantt!$D$4:$D$33,A8,Gantt!$G$4:$G$33)) | D8: =IF($A8="","",SUMIF(Gantt!$D$4:$D$33,$A8,Gantt!J$4:J$33)) | E8: =IF($A8="","",SUMIF(Gantt!$D$4:$D$33,$A8,Gantt!K$4:K$33)) | F8: =IF($A8="","",SUMIF(Gantt!$D$4:$D$33,$A8,Gantt!L$4:L$33)) | G8: =IF($A8="","",SUMIF(Gantt!$D$4:$D$33,$A8,Gantt!M$4:M$33)) | H8: =IF($A8="","",SUMIF(Gantt!$D$4:$D$33,$A8,Gantt!N$4:N$33)) | I8: =IF($A8="","",SUMIF(Gantt!$D$4:$D$33,$A8,Gantt!O$4:O$33)) | J8: =IF($A8="","",SUMIF(Gantt!$D$4:$D$33,$A8,Gantt!P$4:P$33)) | K8: =IF($A8="","",SUMIF(Gantt!$D$4:$D$33,$A8,Gantt!Q$4:Q$33)) | ... U8: =IF($A8="","",SUMIF(Gantt!$D$4:$D$33,$A8,Gantt!AA$4:AA$33))
C9: =IF(A9="","",SUMIF(Gantt!$D$4:$D$33,A9,Gantt!$G$4:$G$33)) | D9: =IF($A9="","",SUMIF(Gantt!$D$4:$D$33,$A9,Gantt!J$4:J$33)) | E9: =IF($A9="","",SUMIF(Gantt!$D$4:$D$33,$A9,Gantt!K$4:K$33)) | F9: =IF($A9="","",SUMIF(Gantt!$D$4:$D$33,$A9,Gantt!L$4:L$33)) | G9: =IF($A9="","",SUMIF(Gantt!$D$4:$D$33,$A9,Gantt!M$4:M$33)) | H9: =IF($A9="","",SUMIF(Gantt!$D$4:$D$33,$A9,Gantt!N$4:N$33)) | I9: =IF($A9="","",SUMIF(Gantt!$D$4:$D$33,$A9,Gantt!O$4:O$33)) | J9: =IF($A9="","",SUMIF(Gantt!$D$4:$D$33,$A9,Gantt!P$4:P$33)) | K9: =IF($A9="","",SUMIF(Gantt!$D$4:$D$33,$A9,Gantt!Q$4:Q$33)) | ... U9: =IF($A9="","",SUMIF(Gantt!$D$4:$D$33,$A9,Gantt!AA$4:AA$33))
C10: =IF(A10="","",SUMIF(Gantt!$D$4:$D$33,A10,Gantt!$G$4:$G$33)) | D10: =IF($A10="","",SUMIF(Gantt!$D$4:$D$33,$A10,Gantt!J$4:J$33)) | E10: =IF($A10="","",SUMIF(Gantt!$D$4:$D$33,$A10,Gantt!K$4:K$33)) | F10: =IF($A10="","",SUMIF(Gantt!$D$4:$D$33,$A10,Gantt!L$4:L$33)) | G10: =IF($A10="","",SUMIF(Gantt!$D$4:$D$33,$A10,Gantt!M$4:M$33)) | H10: =IF($A10="","",SUMIF(Gantt!$D$4:$D$33,$A10,Gantt!N$4:N$33)) | I10: =IF($A10="","",SUMIF(Gantt!$D$4:$D$33,$A10,Gantt!O$4:O$33)) | J10: =IF($A10="","",SUMIF(Gantt!$D$4:$D$33,$A10,Gantt!P$4:P$33)) | K10: =IF($A10="","",SUMIF(Gantt!$D$4:$D$33,$A10,Gantt!Q$4:Q$33)) | ... U10: =IF($A10="","",SUMIF(Gantt!$D$4:$D$33,$A10,Gantt!AA$4:AA$33))
C11: =IF(A11="","",SUMIF(Gantt!$D$4:$D$33,A11,Gantt!$G$4:$G$33)) | D11: =IF($A11="","",SUMIF(Gantt!$D$4:$D$33,$A11,Gantt!J$4:J$33)) | E11: =IF($A11="","",SUMIF(Gantt!$D$4:$D$33,$A11,Gantt!K$4:K$33)) | F11: =IF($A11="","",SUMIF(Gantt!$D$4:$D$33,$A11,Gantt!L$4:L$33)) | G11: =IF($A11="","",SUMIF(Gantt!$D$4:$D$33,$A11,Gantt!M$4:M$33)) | H11: =IF($A11="","",SUMIF(Gantt!$D$4:$D$33,$A11,Gantt!N$4:N$33)) | I11: =IF($A11="","",SUMIF(Gantt!$D$4:$D$33,$A11,Gantt!O$4:O$33)) | J11: =IF($A11="","",SUMIF(Gantt!$D$4:$D$33,$A11,Gantt!P$4:P$33)) | K11: =IF($A11="","",SUMIF(Gantt!$D$4:$D$33,$A11,Gantt!Q$4:Q$33)) | ... U11: =IF($A11="","",SUMIF(Gantt!$D$4:$D$33,$A11,Gantt!AA$4:AA$33))
C12: =IF(A12="","",SUMIF(Gantt!$D$4:$D$33,A12,Gantt!$G$4:$G$33)) | D12: =IF($A12="","",SUMIF(Gantt!$D$4:$D$33,$A12,Gantt!J$4:J$33)) | E12: =IF($A12="","",SUMIF(Gantt!$D$4:$D$33,$A12,Gantt!K$4:K$33)) | F12: =IF($A12="","",SUMIF(Gantt!$D$4:$D$33,$A12,Gantt!L$4:L$33)) | G12: =IF($A12="","",SUMIF(Gantt!$D$4:$D$33,$A12,Gantt!M$4:M$33)) | H12: =IF($A12="","",SUMIF(Gantt!$D$4:$D$33,$A12,Gantt!N$4:N$33)) | I12: =IF($A12="","",SUMIF(Gantt!$D$4:$D$33,$A12,Gantt!O$4:O$33)) | J12: =IF($A12="","",SUMIF(Gantt!$D$4:$D$33,$A12,Gantt!P$4:P$33)) | K12: =IF($A12="","",SUMIF(Gantt!$D$4:$D$33,$A12,Gantt!Q$4:Q$33)) | ... U12: =IF($A12="","",SUMIF(Gantt!$D$4:$D$33,$A12,Gantt!AA$4:AA$33))
C13: =IF(A13="","",SUMIF(Gantt!$D$4:$D$33,A13,Gantt!$G$4:$G$33)) | D13: =IF($A13="","",SUMIF(Gantt!$D$4:$D$33,$A13,Gantt!J$4:J$33)) | E13: =IF($A13="","",SUMIF(Gantt!$D$4:$D$33,$A13,Gantt!K$4:K$33)) | F13: =IF($A13="","",SUMIF(Gantt!$D$4:$D$33,$A13,Gantt!L$4:L$33)) | G13: =IF($A13="","",SUMIF(Gantt!$D$4:$D$33,$A13,Gantt!M$4:M$33)) | H13: =IF($A13="","",SUMIF(Gantt!$D$4:$D$33,$A13,Gantt!N$4:N$33)) | I13: =IF($A13="","",SUMIF(Gantt!$D$4:$D$33,$A13,Gantt!O$4:O$33)) | J13: =IF($A13="","",SUMIF(Gantt!$D$4:$D$33,$A13,Gantt!P$4:P$33)) | K13: =IF($A13="","",SUMIF(Gantt!$D$4:$D$33,$A13,Gantt!Q$4:Q$33)) | ... U13: =IF($A13="","",SUMIF(Gantt!$D$4:$D$33,$A13,Gantt!AA$4:AA$33))
C14: =IF(A14="","",SUMIF(Gantt!$D$4:$D$33,A14,Gantt!$G$4:$G$33)) | D14: =IF($A14="","",SUMIF(Gantt!$D$4:$D$33,$A14,Gantt!J$4:J$33)) | E14: =IF($A14="","",SUMIF(Gantt!$D$4:$D$33,$A14,Gantt!K$4:K$33)) | F14: =IF($A14="","",SUMIF(Gantt!$D$4:$D$33,$A14,Gantt!L$4:L$33)) | G14: =IF($A14="","",SUMIF(Gantt!$D$4:$D$33,$A14,Gantt!M$4:M$33)) | H14: =IF($A14="","",SUMIF(Gantt!$D$4:$D$33,$A14,Gantt!N$4:N$33)) | I14: =IF($A14="","",SUMIF(Gantt!$D$4:$D$33,$A14,Gantt!O$4:O$33)) | J14: =IF($A14="","",SUMIF(Gantt!$D$4:$D$33,$A14,Gantt!P$4:P$33)) | K14: =IF($A14="","",SUMIF(Gantt!$D$4:$D$33,$A14,Gantt!Q$4:Q$33)) | ... U14: =IF($A14="","",SUMIF(Gantt!$D$4:$D$33,$A14,Gantt!AA$4:AA$33))
C15: =IF(A15="","",SUMIF(Gantt!$D$4:$D$33,A15,Gantt!$G$4:$G$33)) | D15: =IF($A15="","",SUMIF(Gantt!$D$4:$D$33,$A15,Gantt!J$4:J$33)) | E15: =IF($A15="","",SUMIF(Gantt!$D$4:$D$33,$A15,Gantt!K$4:K$33)) | F15: =IF($A15="","",SUMIF(Gantt!$D$4:$D$33,$A15,Gantt!L$4:L$33)) | G15: =IF($A15="","",SUMIF(Gantt!$D$4:$D$33,$A15,Gantt!M$4:M$33)) | H15: =IF($A15="","",SUMIF(Gantt!$D$4:$D$33,$A15,Gantt!N$4:N$33)) | I15: =IF($A15="","",SUMIF(Gantt!$D$4:$D$33,$A15,Gantt!O$4:O$33)) | J15: =IF($A15="","",SUMIF(Gantt!$D$4:$D$33,$A15,Gantt!P$4:P$33)) | K15: =IF($A15="","",SUMIF(Gantt!$D$4:$D$33,$A15,Gantt!Q$4:Q$33)) | ... U15: =IF($A15="","",SUMIF(Gantt!$D$4:$D$33,$A15,Gantt!AA$4:AA$33))
C16: =IF(A16="","",SUMIF(Gantt!$D$4:$D$33,A16,Gantt!$G$4:$G$33)) | D16: =IF($A16="","",SUMIF(Gantt!$D$4:$D$33,$A16,Gantt!J$4:J$33)) | E16: =IF($A16="","",SUMIF(Gantt!$D$4:$D$33,$A16,Gantt!K$4:K$33)) | F16: =IF($A16="","",SUMIF(Gantt!$D$4:$D$33,$A16,Gantt!L$4:L$33)) | G16: =IF($A16="","",SUMIF(Gantt!$D$4:$D$33,$A16,Gantt!M$4:M$33)) | H16: =IF($A16="","",SUMIF(Gantt!$D$4:$D$33,$A16,Gantt!N$4:N$33)) | I16: =IF($A16="","",SUMIF(Gantt!$D$4:$D$33,$A16,Gantt!O$4:O$33)) | J16: =IF($A16="","",SUMIF(Gantt!$D$4:$D$33,$A16,Gantt!P$4:P$33)) | K16: =IF($A16="","",SUMIF(Gantt!$D$4:$D$33,$A16,Gantt!Q$4:Q$33)) | ... U16: =IF($A16="","",SUMIF(Gantt!$D$4:$D$33,$A16,Gantt!AA$4:AA$33))
C17: =IF(A17="","",SUMIF(Gantt!$D$4:$D$33,A17,Gantt!$G$4:$G$33)) | D17: =IF($A17="","",SUMIF(Gantt!$D$4:$D$33,$A17,Gantt!J$4:J$33)) | E17: =IF($A17="","",SUMIF(Gantt!$D$4:$D$33,$A17,Gantt!K$4:K$33)) | F17: =IF($A17="","",SUMIF(Gantt!$D$4:$D$33,$A17,Gantt!L$4:L$33)) | G17: =IF($A17="","",SUMIF(Gantt!$D$4:$D$33,$A17,Gantt!M$4:M$33)) | H17: =IF($A17="","",SUMIF(Gantt!$D$4:$D$33,$A17,Gantt!N$4:N$33)) | I17: =IF($A17="","",SUMIF(Gantt!$D$4:$D$33,$A17,Gantt!O$4:O$33)) | J17: =IF($A17="","",SUMIF(Gantt!$D$4:$D$33,$A17,Gantt!P$4:P$33)) | K17: =IF($A17="","",SUMIF(Gantt!$D$4:$D$33,$A17,Gantt!Q$4:Q$33)) | ... U17: =IF($A17="","",SUMIF(Gantt!$D$4:$D$33,$A17,Gantt!AA$4:AA$33))
... C23: =IF(A23="","",SUMIF(Gantt!$D$4:$D$33,A23,Gantt!$G$4:$G$33)) | D23: =IF($A23="","",SUMIF(Gantt!$D$4:$D$33,$A23,Gantt!J$4:J$33)) | E23: =IF($A23="","",SUMIF(Gantt!$D$4:$D$33,$A23,Gantt!K$4:K$33)) | F23: =IF($A23="","",SUMIF(Gantt!$D$4:$D$33,$A23,Gantt!L$4:L$33)) | G23: =IF($A23="","",SUMIF(Gantt!$D$4:$D$33,$A23,Gantt!M$4:M$33)) | H23: =IF($A23="","",SUMIF(Gantt!$D$4:$D$33,$A23,Gantt!N$4:N$33)) | I23: =IF($A23="","",SUMIF(Gantt!$D$4:$D$33,$A23,Gantt!O$4:O$33)) | J23: =IF($A23="","",SUMIF(Gantt!$D$4:$D$33,$A23,Gantt!P$4:P$33)) | K23: =IF($A23="","",SUMIF(Gantt!$D$4:$D$33,$A23,Gantt!Q$4:Q$33)) | ... U23: =IF($A23="","",SUMIF(Gantt!$D$4:$D$33,$A23,Gantt!AA$4:AA$33))
A24: TOTAL affecté | C24: =SUM(C4:C23) -> 1620 | D24: =SUM(D4:D23) -> 80 | E24: =SUM(E4:E23) -> 320 | F24: =SUM(F4:F23) -> 320 | G24: =SUM(G4:G23) -> 320 | H24: =SUM(H4:H23) -> 320 | I24: =SUM(I4:I23) -> 260 | J24: =SUM(J4:J23) -> 0 | ... U24: =SUM(U4:U23) -> 0
A25: Non affecté | C25: =SUMIF(Gantt!$D$4:$D$33,"",Gantt!$G$4:$G$33) -> 0
A27: Ajouter une personne = écrire son nom sur une ligne libre (colonne A) ; elle apparaît aussitôt dans les listes « Responsable ». Rouge = plus de 160 h dans le mois.

Sheet Projets
A1: Projets
A3: Projet | B3: Client / maîtrise d'ouvrage | C3: Statut | D3: Tâches | E3: Charge (h) | F3: Réalisé (h) | G3: % réalisé
A4: Projet A | B4: Interne R&D | C4: En cours | D4: =IF($A4="","",COUNTIF(Gantt!$B$4:$B$33,$A4)) -> 3 | E4: =IF($A4="","",SUMIF(Gantt!$B$4:$B$33,$A4,Gantt!$G$4:$G$33)) -> 640 | F4: =IF($A4="","",SUMIFS(Gantt!$G$4:$G$33,Gantt!$B$4:$B$33,$A4,Gantt!$E$4:$E$33,"Réalisé")) -> 0 | G4: =IF(OR($A4="",N(E4)=0),"",F4/E4) -> 0
A5: Projet B | B5: Client A | C5: En cours | D5: =IF($A5="","",COUNTIF(Gantt!$B$4:$B$33,$A5)) -> 2 | E5: =IF($A5="","",SUMIF(Gantt!$B$4:$B$33,$A5,Gantt!$G$4:$G$33)) -> 980 | F5: =IF($A5="","",SUMIFS(Gantt!$G$4:$G$33,Gantt!$B$4:$B$33,$A5,Gantt!$E$4:$E$33,"Réalisé")) -> 0 | G5: =IF(OR($A5="",N(E5)=0),"",F5/E5) -> 0
D6: =IF($A6="","",COUNTIF(Gantt!$B$4:$B$33,$A6)) | E6: =IF($A6="","",SUMIF(Gantt!$B$4:$B$33,$A6,Gantt!$G$4:$G$33)) | F6: =IF($A6="","",SUMIFS(Gantt!$G$4:$G$33,Gantt!$B$4:$B$33,$A6,Gantt!$E$4:$E$33,"Réalisé")) | G6: =IF(OR($A6="",N(E6)=0),"",F6/E6)
D7: =IF($A7="","",COUNTIF(Gantt!$B$4:$B$33,$A7)) | E7: =IF($A7="","",SUMIF(Gantt!$B$4:$B$33,$A7,Gantt!$G$4:$G$33)) | F7: =IF($A7="","",SUMIFS(Gantt!$G$4:$G$33,Gantt!$B$4:$B$33,$A7,Gantt!$E$4:$E$33,"Réalisé")) | G7: =IF(OR($A7="",N(E7)=0),"",F7/E7)
D8: =IF($A8="","",COUNTIF(Gantt!$B$4:$B$33,$A8)) | E8: =IF($A8="","",SUMIF(Gantt!$B$4:$B$33,$A8,Gantt!$G$4:$G$33)) | F8: =IF($A8="","",SUMIFS(Gantt!$G$4:$G$33,Gantt!$B$4:$B$33,$A8,Gantt!$E$4:$E$33,"Réalisé")) | G8: =IF(OR($A8="",N(E8)=0),"",F8/E8)
D9: =IF($A9="","",COUNTIF(Gantt!$B$4:$B$33,$A9)) | E9: =IF($A9="","",SUMIF(Gantt!$B$4:$B$33,$A9,Gantt!$G$4:$G$33)) | F9: =IF($A9="","",SUMIFS(Gantt!$G$4:$G$33,Gantt!$B$4:$B$33,$A9,Gantt!$E$4:$E$33,"Réalisé")) | G9: =IF(OR($A9="",N(E9)=0),"",F9/E9)
D10: =IF($A10="","",COUNTIF(Gantt!$B$4:$B$33,$A10)) | E10: =IF($A10="","",SUMIF(Gantt!$B$4:$B$33,$A10,Gantt!$G$4:$G$33)) | F10: =IF($A10="","",SUMIFS(Gantt!$G$4:$G$33,Gantt!$B$4:$B$33,$A10,Gantt!$E$4:$E$33,"Réalisé")) | G10: =IF(OR($A10="",N(E10)=0),"",F10/E10)
D11: =IF($A11="","",COUNTIF(Gantt!$B$4:$B$33,$A11)) | E11: =IF($A11="","",SUMIF(Gantt!$B$4:$B$33,$A11,Gantt!$G$4:$G$33)) | F11: =IF($A11="","",SUMIFS(Gantt!$G$4:$G$33,Gantt!$B$4:$B$33,$A11,Gantt!$E$4:$E$33,"Réalisé")) | G11: =IF(OR($A11="",N(E11)=0),"",F11/E11)
D12: =IF($A12="","",COUNTIF(Gantt!$B$4:$B$33,$A12)) | E12: =IF($A12="","",SUMIF(Gantt!$B$4:$B$33,$A12,Gantt!$G$4:$G$33)) | F12: =IF($A12="","",SUMIFS(Gantt!$G$4:$G$33,Gantt!$B$4:$B$33,$A12,Gantt!$E$4:$E$33,"Réalisé")) | G12: =IF(OR($A12="",N(E12)=0),"",F12/E12)
D13: =IF($A13="","",COUNTIF(Gantt!$B$4:$B$33,$A13)) | E13: =IF($A13="","",SUMIF(Gantt!$B$4:$B$33,$A13,Gantt!$G$4:$G$33)) | F13: =IF($A13="","",SUMIFS(Gantt!$G$4:$G$33,Gantt!$B$4:$B$33,$A13,Gantt!$E$4:$E$33,"Réalisé")) | G13: =IF(OR($A13="",N(E13)=0),"",F13/E13)
D14: =IF($A14="","",COUNTIF(Gantt!$B$4:$B$33,$A14)) | E14: =IF($A14="","",SUMIF(Gantt!$B$4:$B$33,$A14,Gantt!$G$4:$G$33)) | F14: =IF($A14="","",SUMIFS(Gantt!$G$4:$G$33,Gantt!$B$4:$B$33,$A14,Gantt!$E$4:$E$33,"Réalisé")) | G14: =IF(OR($A14="",N(E14)=0),"",F14/E14)
D15: =IF($A15="","",COUNTIF(Gantt!$B$4:$B$33,$A15)) | E15: =IF($A15="","",SUMIF(Gantt!$B$4:$B$33,$A15,Gantt!$G$4:$G$33)) | F15: =IF($A15="","",SUMIFS(Gantt!$G$4:$G$33,Gantt!$B$4:$B$33,$A15,Gantt!$E$4:$E$33,"Réalisé")) | G15: =IF(OR($A15="",N(E15)=0),"",F15/E15)
D16: =IF($A16="","",COUNTIF(Gantt!$B$4:$B$33,$A16)) | E16: =IF($A16="","",SUMIF(Gantt!$B$4:$B$33,$A16,Gantt!$G$4:$G$33)) | F16: =IF($A16="","",SUMIFS(Gantt!$G$4:$G$33,Gantt!$B$4:$B$33,$A16,Gantt!$E$4:$E$33,"Réalisé")) | G16: =IF(OR($A16="",N(E16)=0),"",F16/E16)
D17: =IF($A17="","",COUNTIF(Gantt!$B$4:$B$33,$A17)) | E17: =IF($A17="","",SUMIF(Gantt!$B$4:$B$33,$A17,Gantt!$G$4:$G$33)) | F17: =IF($A17="","",SUMIFS(Gantt!$G$4:$G$33,Gantt!$B$4:$B$33,$A17,Gantt!$E$4:$E$33,"Réalisé")) | G17: =IF(OR($A17="",N(E17)=0),"",F17/E17)
D18: =IF($A18="","",COUNTIF(Gantt!$B$4:$B$33,$A18)) | E18: =IF($A18="","",SUMIF(Gantt!$B$4:$B$33,$A18,Gantt!$G$4:$G$33)) | F18: =IF($A18="","",SUMIFS(Gantt!$G$4:$G$33,Gantt!$B$4:$B$33,$A18,Gantt!$E$4:$E$33,"Réalisé")) | G18: =IF(OR($A18="",N(E18)=0),"",F18/E18)
A19: TOTAL | D19: =SUM(D4:D18) -> 5 | E19: =SUM(E4:E18) -> 1620 | F19: =SUM(F4:F18) -> 0
A20: Sans projet | E20: =SUMIF(Gantt!$B$4:$B$33,"",Gantt!$G$4:$G$33) -> 0
A22: Saisir les projets en colonne A (cellules jaunes) : ils alimentent la liste « Projet » du planning. Le reste est calculé.

Sheet Financement
A1: Sources de financement
A3: Source | B3: Certitude | C3: Description | D3: Budget (h) | E3: Affecté (h) | F3: Écart | G3: % consommé
A4: Interne | B4: Confirmé | C4: Budget R&D interne | D4: 600 | E4: =IF($A4="","",SUMIF(Répartition!$B$4:$B$103,$A4,Répartition!$C$4:$C$103)) -> 320 | F4: =IF($A4="","",D4-E4) -> 280 | G4: =IF(OR($A4="",N(D4)=0),"",E4/D4) -> 0.53333333
A5: Client A | B5: Confirmé | C5: Tranche ferme contrat | D5: 900 | E5: =IF($A5="","",SUMIF(Répartition!$B$4:$B$103,$A5,Répartition!$C$4:$C$103)) -> 1020 | F5: =IF($A5="","",D5-E5) -> -120 | G5: =IF(OR($A5="",N(D5)=0),"",E5/D5) -> 1.1333333
A6: Subvention | B6: Pressenti | C6: Aide à l'innovation | D6: 300 | E6: =IF($A6="","",SUMIF(Répartition!$B$4:$B$103,$A6,Répartition!$C$4:$C$103)) -> 180 | F6: =IF($A6="","",D6-E6) -> 120 | G6: =IF(OR($A6="",N(D6)=0),"",E6/D6) -> 0.6
A7: Client B | B7: Option | C7: Tranche conditionnelle | D7: 400 | E7: =IF($A7="","",SUMIF(Répartition!$B$4:$B$103,$A7,Répartition!$C$4:$C$103)) -> 100 | F7: =IF($A7="","",D7-E7) -> 300 | G7: =IF(OR($A7="",N(D7)=0),"",E7/D7) -> 0.25
E8: =IF($A8="","",SUMIF(Répartition!$B$4:$B$103,$A8,Répartition!$C$4:$C$103)) | F8: =IF($A8="","",D8-E8) | G8: =IF(OR($A8="",N(D8)=0),"",E8/D8)
E9: =IF($A9="","",SUMIF(Répartition!$B$4:$B$103,$A9,Répartition!$C$4:$C$103)) | F9: =IF($A9="","",D9-E9) | G9: =IF(OR($A9="",N(D9)=0),"",E9/D9)
E10: =IF($A10="","",SUMIF(Répartition!$B$4:$B$103,$A10,Répartition!$C$4:$C$103)) | F10: =IF($A10="","",D10-E10) | G10: =IF(OR($A10="",N(D10)=0),"",E10/D10)
E11: =IF($A11="","",SUMIF(Répartition!$B$4:$B$103,$A11,Répartition!$C$4:$C$103)) | F11: =IF($A11="","",D11-E11) | G11: =IF(OR($A11="",N(D11)=0),"",E11/D11)
E12: =IF($A12="","",SUMIF(Répartition!$B$4:$B$103,$A12,Répartition!$C$4:$C$103)) | F12: =IF($A12="","",D12-E12) | G12: =IF(OR($A12="",N(D12)=0),"",E12/D12)
E13: =IF($A13="","",SUMIF(Répartition!$B$4:$B$103,$A13,Répartition!$C$4:$C$103)) | F13: =IF($A13="","",D13-E13) | G13: =IF(OR($A13="",N(D13)=0),"",E13/D13)
E14: =IF($A14="","",SUMIF(Répartition!$B$4:$B$103,$A14,Répartition!$C$4:$C$103)) | F14: =IF($A14="","",D14-E14) | G14: =IF(OR($A14="",N(D14)=0),"",E14/D14)
E15: =IF($A15="","",SUMIF(Répartition!$B$4:$B$103,$A15,Répartition!$C$4:$C$103)) | F15: =IF($A15="","",D15-E15) | G15: =IF(OR($A15="",N(D15)=0),"",E15/D15)
E16: =IF($A16="","",SUMIF(Répartition!$B$4:$B$103,$A16,Répartition!$C$4:$C$103)) | F16: =IF($A16="","",D16-E16) | G16: =IF(OR($A16="",N(D16)=0),"",E16/D16)
E17: =IF($A17="","",SUMIF(Répartition!$B$4:$B$103,$A17,Répartition!$C$4:$C$103)) | F17: =IF($A17="","",D17-E17) | G17: =IF(OR($A17="",N(D17)=0),"",E17/D17)
E18: =IF($A18="","",SUMIF(Répartition!$B$4:$B$103,$A18,Répartition!$C$4:$C$103)) | F18: =IF($A18="","",D18-E18) | G18: =IF(OR($A18="",N(D18)=0),"",E18/D18)
A19: TOTAL | D19: =SUM(D4:D18) -> 2200 | E19: =SUM(E4:E18) -> 1620 | F19: =SUM(F4:F18) -> 580
A20: Dont confirmé | D20: =SUMIF($B$4:$B$18,"Confirmé",$D$4:$D$18) -> 1500 | E20: =SUMIF($B$4:$B$18,"Confirmé",$E$4:$E$18) -> 1340
A21: Dont pressenti / option | D21: =SUMIF($B$4:$B$18,"<>Confirmé",$D$4:$D$18) -> 700 | E21: =SUMIF($B$4:$B$18,"<>Confirmé",$E$4:$E$18) -> 280
A22: Charge non couverte | E22: =SUM(Gantt!$G$4:$G$33)-E19 -> 0
A24: Saisir les sources en colonne A et leur budget en D : elles alimentent la liste « Source » de l'onglet Répartition. Affecté = heures qui leur sont attribuées dans cet onglet.

Sheet Répartition
A1: Répartition du financement (heures par tâche et par source)
A3: Tâche | B3: Source | C3: Heures | D3: Certitude | E3: Projet | F3: Charge tâche | G3: Reste à financer
A4: Conception d'actifs 3D | B4: Interne | C4: 120 | D4: =IF($B4="","",IFERROR(VLOOKUP($B4,Financement!$A$4:$B$18,2,FALSE()),"")) -> Confirmé | E4: =IF($A4="","",IFERROR(INDEX(Gantt!$B$4:$B$33,MATCH($A4,Gantt!$C$4:$C$33,0)),"")) -> Projet A | F4: =IF($A4="","",IFERROR(INDEX(Gantt!$G$4:$G$33,MATCH($A4,Gantt!$C$4:$C$33,0)),"")) -> 120 | G4: =IF($A4="","",F4-SUMIF($A$4:$A$103,$A4,$C$4:$C$103)) -> 0
A5: Modélisation système | B5: Interne | C5: 200 | D5: =IF($B5="","",IFERROR(VLOOKUP($B5,Financement!$A$4:$B$18,2,FALSE()),"")) -> Confirmé | E5: =IF($A5="","",IFERROR(INDEX(Gantt!$B$4:$B$33,MATCH($A5,Gantt!$C$4:$C$33,0)),"")) -> Projet A | F5: =IF($A5="","",IFERROR(INDEX(Gantt!$G$4:$G$33,MATCH($A5,Gantt!$C$4:$C$33,0)),"")) -> 200 | G5: =IF($A5="","",F5-SUMIF($A$4:$A$103,$A5,$C$4:$C$103)) -> 0
A6: Intégration technique | B6: Client A | C6: 300 | D6: =IF($B6="","",IFERROR(VLOOKUP($B6,Financement!$A$4:$B$18,2,FALSE()),"")) -> Confirmé | E6: =IF($A6="","",IFERROR(INDEX(Gantt!$B$4:$B$33,MATCH($A6,Gantt!$C$4:$C$33,0)),"")) -> Projet B | F6: =IF($A6="","",IFERROR(INDEX(Gantt!$G$4:$G$33,MATCH($A6,Gantt!$C$4:$C$33,0)),"")) -> 480 | G6: =IF($A6="","",F6-SUMIF($A$4:$A$103,$A6,$C$4:$C$103)) -> 0
A7: Intégration technique | B7: Subvention | C7: 180 | D7: =IF($B7="","",IFERROR(VLOOKUP($B7,Financement!$A$4:$B$18,2,FALSE()),"")) -> Pressenti | E7: =IF($A7="","",IFERROR(INDEX(Gantt!$B$4:$B$33,MATCH($A7,Gantt!$C$4:$C$33,0)),"")) -> Projet B | F7: =IF($A7="","",IFERROR(INDEX(Gantt!$G$4:$G$33,MATCH($A7,Gantt!$C$4:$C$33,0)),"")) -> 480 | G7: =IF($A7="","",F7-SUMIF($A$4:$A$103,$A7,$C$4:$C$103)) -> 0
A8: Configuration scénarios | B8: Client A | C8: 500 | D8: =IF($B8="","",IFERROR(VLOOKUP($B8,Financement!$A$4:$B$18,2,FALSE()),"")) -> Confirmé | E8: =IF($A8="","",IFERROR(INDEX(Gantt!$B$4:$B$33,MATCH($A8,Gantt!$C$4:$C$33,0)),"")) -> Projet B | F8: =IF($A8="","",IFERROR(INDEX(Gantt!$G$4:$G$33,MATCH($A8,Gantt!$C$4:$C$33,0)),"")) -> 500 | G8: =IF($A8="","",F8-SUMIF($A$4:$A$103,$A8,$C$4:$C$103)) -> 0
A9: Préparation livraison | B9: Client A | C9: 220 | D9: =IF($B9="","",IFERROR(VLOOKUP($B9,Financement!$A$4:$B$18,2,FALSE()),"")) -> Confirmé | E9: =IF($A9="","",IFERROR(INDEX(Gantt!$B$4:$B$33,MATCH($A9,Gantt!$C$4:$C$33,0)),"")) -> Projet A | F9: =IF($A9="","",IFERROR(INDEX(Gantt!$G$4:$G$33,MATCH($A9,Gantt!$C$4:$C$33,0)),"")) -> 320 | G9: =IF($A9="","",F9-SUMIF($A$4:$A$103,$A9,$C$4:$C$103)) -> 0
A10: Préparation livraison | B10: Client B | C10: 100 | D10: =IF($B10="","",IFERROR(VLOOKUP($B10,Financement!$A$4:$B$18,2,FALSE()),"")) -> Option | E10: =IF($A10="","",IFERROR(INDEX(Gantt!$B$4:$B$33,MATCH($A10,Gantt!$C$4:$C$33,0)),"")) -> Projet A | F10: =IF($A10="","",IFERROR(INDEX(Gantt!$G$4:$G$33,MATCH($A10,Gantt!$C$4:$C$33,0)),"")) -> 320 | G10: =IF($A10="","",F10-SUMIF($A$4:$A$103,$A10,$C$4:$C$103)) -> 0
D11: =IF($B11="","",IFERROR(VLOOKUP($B11,Financement!$A$4:$B$18,2,FALSE()),"")) | E11: =IF($A11="","",IFERROR(INDEX(Gantt!$B$4:$B$33,MATCH($A11,Gantt!$C$4:$C$33,0)),"")) | F11: =IF($A11="","",IFERROR(INDEX(Gantt!$G$4:$G$33,MATCH($A11,Gantt!$C$4:$C$33,0)),"")) | G11: =IF($A11="","",F11-SUMIF($A$4:$A$103,$A11,$C$4:$C$103))
D12: =IF($B12="","",IFERROR(VLOOKUP($B12,Financement!$A$4:$B$18,2,FALSE()),"")) | E12: =IF($A12="","",IFERROR(INDEX(Gantt!$B$4:$B$33,MATCH($A12,Gantt!$C$4:$C$33,0)),"")) | F12: =IF($A12="","",IFERROR(INDEX(Gantt!$G$4:$G$33,MATCH($A12,Gantt!$C$4:$C$33,0)),"")) | G12: =IF($A12="","",F12-SUMIF($A$4:$A$103,$A12,$C$4:$C$103))
D13: =IF($B13="","",IFERROR(VLOOKUP($B13,Financement!$A$4:$B$18,2,FALSE()),"")) | E13: =IF($A13="","",IFERROR(INDEX(Gantt!$B$4:$B$33,MATCH($A13,Gantt!$C$4:$C$33,0)),"")) | F13: =IF($A13="","",IFERROR(INDEX(Gantt!$G$4:$G$33,MATCH($A13,Gantt!$C$4:$C$33,0)),"")) | G13: =IF($A13="","",F13-SUMIF($A$4:$A$103,$A13,$C$4:$C$103))
D14: =IF($B14="","",IFERROR(VLOOKUP($B14,Financement!$A$4:$B$18,2,FALSE()),"")) | E14: =IF($A14="","",IFERROR(INDEX(Gantt!$B$4:$B$33,MATCH($A14,Gantt!$C$4:$C$33,0)),"")) | F14: =IF($A14="","",IFERROR(INDEX(Gantt!$G$4:$G$33,MATCH($A14,Gantt!$C$4:$C$33,0)),"")) | G14: =IF($A14="","",F14-SUMIF($A$4:$A$103,$A14,$C$4:$C$103))
D15: =IF($B15="","",IFERROR(VLOOKUP($B15,Financement!$A$4:$B$18,2,FALSE()),"")) | E15: =IF($A15="","",IFERROR(INDEX(Gantt!$B$4:$B$33,MATCH($A15,Gantt!$C$4:$C$33,0)),"")) | F15: =IF($A15="","",IFERROR(INDEX(Gantt!$G$4:$G$33,MATCH($A15,Gantt!$C$4:$C$33,0)),"")) | G15: =IF($A15="","",F15-SUMIF($A$4:$A$103,$A15,$C$4:$C$103))
D16: =IF($B16="","",IFERROR(VLOOKUP($B16,Financement!$A$4:$B$18,2,FALSE()),"")) | E16: =IF($A16="","",IFERROR(INDEX(Gantt!$B$4:$B$33,MATCH($A16,Gantt!$C$4:$C$33,0)),"")) | F16: =IF($A16="","",IFERROR(INDEX(Gantt!$G$4:$G$33,MATCH($A16,Gantt!$C$4:$C$33,0)),"")) | G16: =IF($A16="","",F16-SUMIF($A$4:$A$103,$A16,$C$4:$C$103))
D17: =IF($B17="","",IFERROR(VLOOKUP($B17,Financement!$A$4:$B$18,2,FALSE()),"")) | E17: =IF($A17="","",IFERROR(INDEX(Gantt!$B$4:$B$33,MATCH($A17,Gantt!$C$4:$C$33,0)),"")) | F17: =IF($A17="","",IFERROR(INDEX(Gantt!$G$4:$G$33,MATCH($A17,Gantt!$C$4:$C$33,0)),"")) | G17: =IF($A17="","",F17-SUMIF($A$4:$A$103,$A17,$C$4:$C$103))
D18: =IF($B18="","",IFERROR(VLOOKUP($B18,Financement!$A$4:$B$18,2,FALSE()),"")) | E18: =IF($A18="","",IFERROR(INDEX(Gantt!$B$4:$B$33,MATCH($A18,Gantt!$C$4:$C$33,0)),"")) | F18: =IF($A18="","",IFERROR(INDEX(Gantt!$G$4:$G$33,MATCH($A18,Gantt!$C$4:$C$33,0)),"")) | G18: =IF($A18="","",F18-SUMIF($A$4:$A$103,$A18,$C$4:$C$103))
D19: =IF($B19="","",IFERROR(VLOOKUP($B19,Financement!$A$4:$B$18,2,FALSE()),"")) | E19: =IF($A19="","",IFERROR(INDEX(Gantt!$B$4:$B$33,MATCH($A19,Gantt!$C$4:$C$33,0)),"")) | F19: =IF($A19="","",IFERROR(INDEX(Gantt!$G$4:$G$33,MATCH($A19,Gantt!$C$4:$C$33,0)),"")) | G19: =IF($A19="","",F19-SUMIF($A$4:$A$103,$A19,$C$4:$C$103))
D20: =IF($B20="","",IFERROR(VLOOKUP($B20,Financement!$A$4:$B$18,2,FALSE()),"")) | E20: =IF($A20="","",IFERROR(INDEX(Gantt!$B$4:$B$33,MATCH($A20,Gantt!$C$4:$C$33,0)),"")) | F20: =IF($A20="","",IFERROR(INDEX(Gantt!$G$4:$G$33,MATCH($A20,Gantt!$C$4:$C$33,0)),"")) | G20: =IF($A20="","",F20-SUMIF($A$4:$A$103,$A20,$C$4:$C$103))
D21: =IF($B21="","",IFERROR(VLOOKUP($B21,Financement!$A$4:$B$18,2,FALSE()),"")) | E21: =IF($A21="","",IFERROR(INDEX(Gantt!$B$4:$B$33,MATCH($A21,Gantt!$C$4:$C$33,0)),"")) | F21: =IF($A21="","",IFERROR(INDEX(Gantt!$G$4:$G$33,MATCH($A21,Gantt!$C$4:$C$33,0)),"")) | G21: =IF($A21="","",F21-SUMIF($A$4:$A$103,$A21,$C$4:$C$103))
D22: =IF($B22="","",IFERROR(VLOOKUP($B22,Financement!$A$4:$B$18,2,FALSE()),"")) | E22: =IF($A22="","",IFERROR(INDEX(Gantt!$B$4:$B$33,MATCH($A22,Gantt!$C$4:$C$33,0)),"")) | F22: =IF($A22="","",IFERROR(INDEX(Gantt!$G$4:$G$33,MATCH($A22,Gantt!$C$4:$C$33,0)),"")) | G22: =IF($A22="","",F22-SUMIF($A$4:$A$103,$A22,$C$4:$C$103))
... D103: =IF($B103="","",IFERROR(VLOOKUP($B103,Financement!$A$4:$B$18,2,FALSE()),"")) | E103: =IF($A103="","",IFERROR(INDEX(Gantt!$B$4:$B$33,MATCH($A103,Gantt!$C$4:$C$33,0)),"")) | F103: =IF($A103="","",IFERROR(INDEX(Gantt!$G$4:$G$33,MATCH($A103,Gantt!$C$4:$C$33,0)),"")) | G103: =IF($A103="","",F103-SUMIF($A$4:$A$103,$A103,$C$4:$C$103))
A104: TOTAL | C104: =SUM(C4:C103) -> 1620
A106: Une ligne = une part de financement. Répéter la même tâche sur plusieurs lignes pour la partager entre sources. Reste à financer : vert = couverte, orange = incomplète, rouge = sur-financée.

Sheet Pointage
A1: Pointage des heures consommées
A2: Une ligne = un pointage. Saisir la date, la personne, la tâche, la source de financement et les heures réalisées. Projet et mois sont déduits. Les synthèses à droite comparent budget, prévu et pointé.
A3: Date | B3: Personne | C3: Tâche | D3: Projet | E3: Source | F3: Heures | G3: Mois | H3: Commentaire | J3: Source | K3: Budget (h) | L3: Prévu (h) | M3: Pointé (h) | N3: Reste budget | O3: % consommé | Q3: Tâche | R3: Projet | S3: Charge prévue | T3: Pointé (h) | U3: Écart | V3: % avancement réel
A4: 46280 | B4: Personne A | C4: Conception d'actifs 3D | D4: =IF($C4="","",IFERROR(INDEX(Gantt!$B$4:$B$33,MATCH($C4,Gantt!$C$4:$C$33,0)),"")) -> Projet A | E4: Interne | F4: 45 | G4: =IF($A4="","",DATE(YEAR($A4),MONTH($A4),1)) -> 46266 | H4: Blocking des assets | J4: =IF(Financement!$A4="","",Financement!$A4) -> Interne | K4: =IF($J4="","",Financement!$D4) -> 600 | L4: =IF($J4="","",Financement!$E4) -> 320 | M4: =IF($J4="","",SUMIF($E$4:$E$303,$J4,$F$4:$F$303)) -> 83 | N4: =IF($J4="","",K4-M4) -> 517 | O4: =IF(OR($J4="",N(K4)=0),"",M4/K4) -> 0.13833333 | Q4: =IF(Gantt!$C4="","",Gantt!$C4) -> Conception d'actifs 3D | R4: =IF($Q4="","",Gantt!$B4) -> Projet A | S4: =IF($Q4="","",Gantt!$G4) -> 120 | T4: =IF($Q4="","",SUMIF($C$4:$C$303,$Q4,$F$4:$F$303)) -> 83 | U4: =IF($Q4="","",S4-T4) -> 37 | V4: =IF(OR($Q4="",N(S4)=0),"",T4/S4) -> 0.69166667
A5: 46294 | B5: Personne A | C5: Conception d'actifs 3D | D5: =IF($C5="","",IFERROR(INDEX(Gantt!$B$4:$B$33,MATCH($C5,Gantt!$C$4:$C$33,0)),"")) -> Projet A | E5: Interne | F5: 38 | G5: =IF($A5="","",DATE(YEAR($A5),MONTH($A5),1)) -> 46266 | H5: Textures | J5: =IF(Financement!$A5="","",Financement!$A5) -> Client A | K5: =IF($J5="","",Financement!$D5) -> 900 | L5: =IF($J5="","",Financement!$E5) -> 1020 | M5: =IF($J5="","",SUMIF($E$4:$E$303,$J5,$F$4:$F$303)) -> 60 | N5: =IF($J5="","",K5-M5) -> 840 | O5: =IF(OR($J5="",N(K5)=0),"",M5/K5) -> 0.066666667 | Q5: =IF(Gantt!$C5="","",Gantt!$C5) -> Modélisation système | R5: =IF($Q5="","",Gantt!$B5) -> Projet A | S5: =IF($Q5="","",Gantt!$G5) -> 200 | T5: =IF($Q5="","",SUMIF($C$4:$C$303,$Q5,$F$4:$F$303)) -> 0 | U5: =IF($Q5="","",S5-T5) -> 200 | V5: =IF(OR($Q5="",N(S5)=0),"",T5/S5) -> 0
A6: 46308 | B6: Personne B | C6: Intégration technique | D6: =IF($C6="","",IFERROR(INDEX(Gantt!$B$4:$B$33,MATCH($C6,Gantt!$C$4:$C$33,0)),"")) -> Projet B | E6: Client A | F6: 60 | G6: =IF($A6="","",DATE(YEAR($A6),MONTH($A6),1)) -> 46296 | H6: Bus de données | J6: =IF(Financement!$A6="","",Financement!$A6) -> Subvention | K6: =IF($J6="","",Financement!$D6) -> 300 | L6: =IF($J6="","",Financement!$E6) -> 180 | M6: =IF($J6="","",SUMIF($E$4:$E$303,$J6,$F$4:$F$303)) -> 0 | N6: =IF($J6="","",K6-M6) -> 300 | O6: =IF(OR($J6="",N(K6)=0),"",M6/K6) -> 0 | Q6: =IF(Gantt!$C6="","",Gantt!$C6) -> Intégration technique | R6: =IF($Q6="","",Gantt!$B6) -> Projet B | S6: =IF($Q6="","",Gantt!$G6) -> 480 | T6: =IF($Q6="","",SUMIF($C$4:$C$303,$Q6,$F$4:$F$303)) -> 60 | U6: =IF($Q6="","",S6-T6) -> 420 | V6: =IF(OR($Q6="",N(S6)=0),"",T6/S6) -> 0.125
D7: =IF($C7="","",IFERROR(INDEX(Gantt!$B$4:$B$33,MATCH($C7,Gantt!$C$4:$C$33,0)),"")) | G7: =IF($A7="","",DATE(YEAR($A7),MONTH($A7),1)) | J7: =IF(Financement!$A7="","",Financement!$A7) -> Client B | K7: =IF($J7="","",Financement!$D7) -> 400 | L7: =IF($J7="","",Financement!$E7) -> 100 | M7: =IF($J7="","",SUMIF($E$4:$E$303,$J7,$F$4:$F$303)) -> 0 | N7: =IF($J7="","",K7-M7) -> 400 | O7: =IF(OR($J7="",N(K7)=0),"",M7/K7) -> 0 | Q7: =IF(Gantt!$C7="","",Gantt!$C7) -> Configuration scénarios | R7: =IF($Q7="","",Gantt!$B7) -> Projet B | S7: =IF($Q7="","",Gantt!$G7) -> 500 | T7: =IF($Q7="","",SUMIF($C$4:$C$303,$Q7,$F$4:$F$303)) -> 0 | U7: =IF($Q7="","",S7-T7) -> 500 | V7: =IF(OR($Q7="",N(S7)=0),"",T7/S7) -> 0
D8: =IF($C8="","",IFERROR(INDEX(Gantt!$B$4:$B$33,MATCH($C8,Gantt!$C$4:$C$33,0)),"")) | G8: =IF($A8="","",DATE(YEAR($A8),MONTH($A8),1)) | J8: =IF(Financement!$A8="","",Financement!$A8) | K8: =IF($J8="","",Financement!$D8) | L8: =IF($J8="","",Financement!$E8) | M8: =IF($J8="","",SUMIF($E$4:$E$303,$J8,$F$4:$F$303)) | N8: =IF($J8="","",K8-M8) | O8: =IF(OR($J8="",N(K8)=0),"",M8/K8) | Q8: =IF(Gantt!$C8="","",Gantt!$C8) -> Préparation livraison | R8: =IF($Q8="","",Gantt!$B8) -> Projet A | S8: =IF($Q8="","",Gantt!$G8) -> 320 | T8: =IF($Q8="","",SUMIF($C$4:$C$303,$Q8,$F$4:$F$303)) -> 0 | U8: =IF($Q8="","",S8-T8) -> 320 | V8: =IF(OR($Q8="",N(S8)=0),"",T8/S8) -> 0
D9: =IF($C9="","",IFERROR(INDEX(Gantt!$B$4:$B$33,MATCH($C9,Gantt!$C$4:$C$33,0)),"")) | G9: =IF($A9="","",DATE(YEAR($A9),MONTH($A9),1)) | J9: =IF(Financement!$A9="","",Financement!$A9) | K9: =IF($J9="","",Financement!$D9) | L9: =IF($J9="","",Financement!$E9) | M9: =IF($J9="","",SUMIF($E$4:$E$303,$J9,$F$4:$F$303)) | N9: =IF($J9="","",K9-M9) | O9: =IF(OR($J9="",N(K9)=0),"",M9/K9) | Q9: =IF(Gantt!$C9="","",Gantt!$C9) | R9: =IF($Q9="","",Gantt!$B9) | S9: =IF($Q9="","",Gantt!$G9) | T9: =IF($Q9="","",SUMIF($C$4:$C$303,$Q9,$F$4:$F$303)) | U9: =IF($Q9="","",S9-T9) | V9: =IF(OR($Q9="",N(S9)=0),"",T9/S9)
D10: =IF($C10="","",IFERROR(INDEX(Gantt!$B$4:$B$33,MATCH($C10,Gantt!$C$4:$C$33,0)),"")) | G10: =IF($A10="","",DATE(YEAR($A10),MONTH($A10),1)) | J10: =IF(Financement!$A10="","",Financement!$A10) | K10: =IF($J10="","",Financement!$D10) | L10: =IF($J10="","",Financement!$E10) | M10: =IF($J10="","",SUMIF($E$4:$E$303,$J10,$F$4:$F$303)) | N10: =IF($J10="","",K10-M10) | O10: =IF(OR($J10="",N(K10)=0),"",M10/K10) | Q10: =IF(Gantt!$C10="","",Gantt!$C10) | R10: =IF($Q10="","",Gantt!$B10) | S10: =IF($Q10="","",Gantt!$G10) | T10: =IF($Q10="","",SUMIF($C$4:$C$303,$Q10,$F$4:$F$303)) | U10: =IF($Q10="","",S10-T10) | V10: =IF(OR($Q10="",N(S10)=0),"",T10/S10)
D11: =IF($C11="","",IFERROR(INDEX(Gantt!$B$4:$B$33,MATCH($C11,Gantt!$C$4:$C$33,0)),"")) | G11: =IF($A11="","",DATE(YEAR($A11),MONTH($A11),1)) | J11: =IF(Financement!$A11="","",Financement!$A11) | K11: =IF($J11="","",Financement!$D11) | L11: =IF($J11="","",Financement!$E11) | M11: =IF($J11="","",SUMIF($E$4:$E$303,$J11,$F$4:$F$303)) | N11: =IF($J11="","",K11-M11) | O11: =IF(OR($J11="",N(K11)=0),"",M11/K11) | Q11: =IF(Gantt!$C11="","",Gantt!$C11) | R11: =IF($Q11="","",Gantt!$B11) | S11: =IF($Q11="","",Gantt!$G11) | T11: =IF($Q11="","",SUMIF($C$4:$C$303,$Q11,$F$4:$F$303)) | U11: =IF($Q11="","",S11-T11) | V11: =IF(OR($Q11="",N(S11)=0),"",T11/S11)
D12: =IF($C12="","",IFERROR(INDEX(Gantt!$B$4:$B$33,MATCH($C12,Gantt!$C$4:$C$33,0)),"")) | G12: =IF($A12="","",DATE(YEAR($A12),MONTH($A12),1)) | J12: =IF(Financement!$A12="","",Financement!$A12) | K12: =IF($J12="","",Financement!$D12) | L12: =IF($J12="","",Financement!$E12) | M12: =IF($J12="","",SUMIF($E$4:$E$303,$J12,$F$4:$F$303)) | N12: =IF($J12="","",K12-M12) | O12: =IF(OR($J12="",N(K12)=0),"",M12/K12) | Q12: =IF(Gantt!$C12="","",Gantt!$C12) | R12: =IF($Q12="","",Gantt!$B12) | S12: =IF($Q12="","",Gantt!$G12) | T12: =IF($Q12="","",SUMIF($C$4:$C$303,$Q12,$F$4:$F$303)) | U12: =IF($Q12="","",S12-T12) | V12: =IF(OR($Q12="",N(S12)=0),"",T12/S12)
D13: =IF($C13="","",IFERROR(INDEX(Gantt!$B$4:$B$33,MATCH($C13,Gantt!$C$4:$C$33,0)),"")) | G13: =IF($A13="","",DATE(YEAR($A13),MONTH($A13),1)) | J13: =IF(Financement!$A13="","",Financement!$A13) | K13: =IF($J13="","",Financement!$D13) | L13: =IF($J13="","",Financement!$E13) | M13: =IF($J13="","",SUMIF($E$4:$E$303,$J13,$F$4:$F$303)) | N13: =IF($J13="","",K13-M13) | O13: =IF(OR($J13="",N(K13)=0),"",M13/K13) | Q13: =IF(Gantt!$C13="","",Gantt!$C13) | R13: =IF($Q13="","",Gantt!$B13) | S13: =IF($Q13="","",Gantt!$G13) | T13: =IF($Q13="","",SUMIF($C$4:$C$303,$Q13,$F$4:$F$303)) | U13: =IF($Q13="","",S13-T13) | V13: =IF(OR($Q13="",N(S13)=0),"",T13/S13)
D14: =IF($C14="","",IFERROR(INDEX(Gantt!$B$4:$B$33,MATCH($C14,Gantt!$C$4:$C$33,0)),"")) | G14: =IF($A14="","",DATE(YEAR($A14),MONTH($A14),1)) | J14: =IF(Financement!$A14="","",Financement!$A14) | K14: =IF($J14="","",Financement!$D14) | L14: =IF($J14="","",Financement!$E14) | M14: =IF($J14="","",SUMIF($E$4:$E$303,$J14,$F$4:$F$303)) | N14: =IF($J14="","",K14-M14) | O14: =IF(OR($J14="",N(K14)=0),"",M14/K14) | Q14: =IF(Gantt!$C14="","",Gantt!$C14) | R14: =IF($Q14="","",Gantt!$B14) | S14: =IF($Q14="","",Gantt!$G14) | T14: =IF($Q14="","",SUMIF($C$4:$C$303,$Q14,$F$4:$F$303)) | U14: =IF($Q14="","",S14-T14) | V14: =IF(OR($Q14="",N(S14)=0),"",T14/S14)
D15: =IF($C15="","",IFERROR(INDEX(Gantt!$B$4:$B$33,MATCH($C15,Gantt!$C$4:$C$33,0)),"")) | G15: =IF($A15="","",DATE(YEAR($A15),MONTH($A15),1)) | J15: =IF(Financement!$A15="","",Financement!$A15) | K15: =IF($J15="","",Financement!$D15) | L15: =IF($J15="","",Financement!$E15) | M15: =IF($J15="","",SUMIF($E$4:$E$303,$J15,$F$4:$F$303)) | N15: =IF($J15="","",K15-M15) | O15: =IF(OR($J15="",N(K15)=0),"",M15/K15) | Q15: =IF(Gantt!$C15="","",Gantt!$C15) | R15: =IF($Q15="","",Gantt!$B15) | S15: =IF($Q15="","",Gantt!$G15) | T15: =IF($Q15="","",SUMIF($C$4:$C$303,$Q15,$F$4:$F$303)) | U15: =IF($Q15="","",S15-T15) | V15: =IF(OR($Q15="",N(S15)=0),"",T15/S15)
D16: =IF($C16="","",IFERROR(INDEX(Gantt!$B$4:$B$33,MATCH($C16,Gantt!$C$4:$C$33,0)),"")) | G16: =IF($A16="","",DATE(YEAR($A16),MONTH($A16),1)) | J16: =IF(Financement!$A16="","",Financement!$A16) | K16: =IF($J16="","",Financement!$D16) | L16: =IF($J16="","",Financement!$E16) | M16: =IF($J16="","",SUMIF($E$4:$E$303,$J16,$F$4:$F$303)) | N16: =IF($J16="","",K16-M16) | O16: =IF(OR($J16="",N(K16)=0),"",M16/K16) | Q16: =IF(Gantt!$C16="","",Gantt!$C16) | R16: =IF($Q16="","",Gantt!$B16) | S16: =IF($Q16="","",Gantt!$G16) | T16: =IF($Q16="","",SUMIF($C$4:$C$303,$Q16,$F$4:$F$303)) | U16: =IF($Q16="","",S16-T16) | V16: =IF(OR($Q16="",N(S16)=0),"",T16/S16)
D17: =IF($C17="","",IFERROR(INDEX(Gantt!$B$4:$B$33,MATCH($C17,Gantt!$C$4:$C$33,0)),"")) | G17: =IF($A17="","",DATE(YEAR($A17),MONTH($A17),1)) | J17: =IF(Financement!$A17="","",Financement!$A17) | K17: =IF($J17="","",Financement!$D17) | L17: =IF($J17="","",Financement!$E17) | M17: =IF($J17="","",SUMIF($E$4:$E$303,$J17,$F$4:$F$303)) | N17: =IF($J17="","",K17-M17) | O17: =IF(OR($J17="",N(K17)=0),"",M17/K17) | Q17: =IF(Gantt!$C17="","",Gantt!$C17) | R17: =IF($Q17="","",Gantt!$B17) | S17: =IF($Q17="","",Gantt!$G17) | T17: =IF($Q17="","",SUMIF($C$4:$C$303,$Q17,$F$4:$F$303)) | U17: =IF($Q17="","",S17-T17) | V17: =IF(OR($Q17="",N(S17)=0),"",T17/S17)
D18: =IF($C18="","",IFERROR(INDEX(Gantt!$B$4:$B$33,MATCH($C18,Gantt!$C$4:$C$33,0)),"")) | G18: =IF($A18="","",DATE(YEAR($A18),MONTH($A18),1)) | J18: =IF(Financement!$A18="","",Financement!$A18) | K18: =IF($J18="","",Financement!$D18) | L18: =IF($J18="","",Financement!$E18) | M18: =IF($J18="","",SUMIF($E$4:$E$303,$J18,$F$4:$F$303)) | N18: =IF($J18="","",K18-M18) | O18: =IF(OR($J18="",N(K18)=0),"",M18/K18) | Q18: =IF(Gantt!$C18="","",Gantt!$C18) | R18: =IF($Q18="","",Gantt!$B18) | S18: =IF($Q18="","",Gantt!$G18) | T18: =IF($Q18="","",SUMIF($C$4:$C$303,$Q18,$F$4:$F$303)) | U18: =IF($Q18="","",S18-T18) | V18: =IF(OR($Q18="",N(S18)=0),"",T18/S18)
D19: =IF($C19="","",IFERROR(INDEX(Gantt!$B$4:$B$33,MATCH($C19,Gantt!$C$4:$C$33,0)),"")) | G19: =IF($A19="","",DATE(YEAR($A19),MONTH($A19),1)) | J19: TOTAL | K19: =SUM(K4:K18) -> 2200 | L19: =SUM(L4:L18) -> 1620 | M19: =SUM(M4:M18) -> 143 | N19: =SUM(N4:N18) -> 2057 | Q19: =IF(Gantt!$C19="","",Gantt!$C19) | R19: =IF($Q19="","",Gantt!$B19) | S19: =IF($Q19="","",Gantt!$G19) | T19: =IF($Q19="","",SUMIF($C$4:$C$303,$Q19,$F$4:$F$303)) | U19: =IF($Q19="","",S19-T19) | V19: =IF(OR($Q19="",N(S19)=0),"",T19/S19)
D20: =IF($C20="","",IFERROR(INDEX(Gantt!$B$4:$B$33,MATCH($C20,Gantt!$C$4:$C$33,0)),"")) | G20: =IF($A20="","",DATE(YEAR($A20),MONTH($A20),1)) | J20: Pointé hors source | M20: =SUMIF($E$4:$E$303,"",$F$4:$F$303) -> 0 | Q20: =IF(Gantt!$C20="","",Gantt!$C20) | R20: =IF($Q20="","",Gantt!$B20) | S20: =IF($Q20="","",Gantt!$G20) | T20: =IF($Q20="","",SUMIF($C$4:$C$303,$Q20,$F$4:$F$303)) | U20: =IF($Q20="","",S20-T20) | V20: =IF(OR($Q20="",N(S20)=0),"",T20/S20)
D21: =IF($C21="","",IFERROR(INDEX(Gantt!$B$4:$B$33,MATCH($C21,Gantt!$C$4:$C$33,0)),"")) | G21: =IF($A21="","",DATE(YEAR($A21),MONTH($A21),1)) | J21: Pointé par personne | Q21: =IF(Gantt!$C21="","",Gantt!$C21) | R21: =IF($Q21="","",Gantt!$B21) | S21: =IF($Q21="","",Gantt!$G21) | T21: =IF($Q21="","",SUMIF($C$4:$C$303,$Q21,$F$4:$F$303)) | U21: =IF($Q21="","",S21-T21) | V21: =IF(OR($Q21="",N(S21)=0),"",T21/S21)
D22: =IF($C22="","",IFERROR(INDEX(Gantt!$B$4:$B$33,MATCH($C22,Gantt!$C$4:$C$33,0)),"")) | G22: =IF($A22="","",DATE(YEAR($A22),MONTH($A22),1)) | J22: Personne | K22: Prévu (h) | L22: Pointé (h) | M22: Écart | Q22: =IF(Gantt!$C22="","",Gantt!$C22) | R22: =IF($Q22="","",Gantt!$B22) | S22: =IF($Q22="","",Gantt!$G22) | T22: =IF($Q22="","",SUMIF($C$4:$C$303,$Q22,$F$4:$F$303)) | U22: =IF($Q22="","",S22-T22) | V22: =IF(OR($Q22="",N(S22)=0),"",T22/S22)
