Workbook
Name Liste_Personnes: 'Paramètres'!$A$4:$A$33
Name Liste_Projets: 'Paramètres'!$B$4:$B$33
Name Liste_Taches: 'Paramètres'!$C$4:$C$33
Name Annee: 'Paramètres'!$F$3

Sheet Saisie
A1: Date | B1: Personne | C1: Projet | D1: Tâche | E1: Heures | F1: Commentaire | G1: Mois
A2: 46029 | B2: Personne C | C2: Interne | D2: Réunion | E2: 2 | F2: Exemple fictif | G2: =IF(A2="","",MONTH(A2))
A3: 46032 | B3: Personne A | C3: Projet Alpha | D3: Gestion | E3: 7 | F3: Exemple fictif | G3: =IF(A3="","",MONTH(A3))
A4: 46035 | B4: Personne B | C4: Projet Beta | D4: Analyse | E4: 1 | F4: Exemple fictif | G4: =IF(A4="","",MONTH(A4))
A5: 46069 | B5: Personne C | C5: Interne | D5: Développement | E5: 3.5 | F5: Exemple fictif | G5: =IF(A5="","",MONTH(A5))
A6: 46072 | B6: Personne A | C6: Projet Alpha | D6: Réunion | E6: 1 | F6: Exemple fictif | G6: =IF(A6="","",MONTH(A6))
A7: 46075 | B7: Personne B | C7: Projet Beta | D7: Gestion | E7: 4 | F7: Exemple fictif | G7: =IF(A7="","",MONTH(A7))
A8: 46106 | B8: Personne C | C8: Interne | D8: Analyse | E8: 4 | F8: Exemple fictif | G8: =IF(A8="","",MONTH(A8))
A9: 46082 | B9: Personne A | C9: Projet Alpha | D9: Développement | E9: 4 | F9: Exemple fictif | G9: =IF(A9="","",MONTH(A9))
A10: 46085 | B10: Personne B | C10: Projet Beta | D10: Réunion | E10: 4 | F10: Exemple fictif | G10: =IF(A10="","",MONTH(A10))
A11: 46119 | B11: Personne C | C11: Interne | D11: Gestion | E11: 2 | F11: Exemple fictif | G11: =IF(A11="","",MONTH(A11))
A12: 46122 | B12: Personne A | C12: Projet Alpha | D12: Analyse | E12: 1 | F12: Exemple fictif | G12: =IF(A12="","",MONTH(A12))
A13: 46125 | B13: Personne B | C13: Projet Beta | D13: Développement | E13: 4 | F13: Exemple fictif | G13: =IF(A13="","",MONTH(A13))
... A31: 46308 | B31: Personne B | C31: Projet Beta | D31: Gestion | E31: 2 | F31: Exemple fictif | G31: =IF(A31="","",MONTH(A31))
G32: =IF(A32="","",MONTH(A32))
G33: =IF(A33="","",MONTH(A33))
G34: =IF(A34="","",MONTH(A34))
G35: =IF(A35="","",MONTH(A35))
G36: =IF(A36="","",MONTH(A36))
G37: =IF(A37="","",MONTH(A37))
G38: =IF(A38="","",MONTH(A38))
G39: =IF(A39="","",MONTH(A39))
G40: =IF(A40="","",MONTH(A40))
G41: =IF(A41="","",MONTH(A41))
G42: =IF(A42="","",MONTH(A42))
G43: =IF(A43="","",MONTH(A43))
... G501: =IF(A501="","",MONTH(A501))

Sheet Synthèse
A1: ="Synthèse des heures — "&Annee
A3: Heures par projet × mois
A4: Projet | B4: Janv. | C4: Févr. | D4: Mars | E4: Avr. | F4: Mai | G4: Juin | H4: Juil. | I4: Août | J4: Sept. | K4: Oct. | L4: Nov. | M4: Déc. | N4: Total
A5: =IF(INDEX(Liste_Projets,1)="","",INDEX(Liste_Projets,1)) | B5: =IF($A5="","",SUMIFS(Saisie!$E$2:$E$501,Saisie!$C$2:$C$501,$A5,Saisie!$A$2:$A$501,">="&DATE(Annee,1,1),Saisie!$A$2:$A$501,"<"&DATE(Annee,2,1))) | C5: =IF($A5="","",SUMIFS(Saisie!$E$2:$E$501,Saisie!$C$2:$C$501,$A5,Saisie!$A$2:$A$501,">="&DATE(Annee,2,1),Saisie!$A$2:$A$501,"<"&DATE(Annee,3,1))) | D5: =IF($A5="","",SUMIFS(Saisie!$E$2:$E$501,Saisie!$C$2:$C$501,$A5,Saisie!$A$2:$A$501,">="&DATE(Annee,3,1),Saisie!$A$2:$A$501,"<"&DATE(Annee,4,1))) | E5: =IF($A5="","",SUMIFS(Saisie!$E$2:$E$501,Saisie!$C$2:$C$501,$A5,Saisie!$A$2:$A$501,">="&DATE(Annee,4,1),Saisie!$A$2:$A$501,"<"&DATE(Annee,5,1))) | F5: =IF($A5="","",SUMIFS(Saisie!$E$2:$E$501,Saisie!$C$2:$C$501,$A5,Saisie!$A$2:$A$501,">="&DATE(Annee,5,1),Saisie!$A$2:$A$501,"<"&DATE(Annee,6,1))) | G5: =IF($A5="","",SUMIFS(Saisie!$E$2:$E$501,Saisie!$C$2:$C$501,$A5,Saisie!$A$2:$A$501,">="&DATE(Annee,6,1),Saisie!$A$2:$A$501,"<"&DATE(Annee,7,1))) | H5: =IF($A5="","",SUMIFS(Saisie!$E$2:$E$501,Saisie!$C$2:$C$501,$A5,Saisie!$A$2:$A$501,">="&DATE(Annee,7,1),Saisie!$A$2:$A$501,"<"&DATE(Annee,8,1))) | I5: =IF($A5="","",SUMIFS(Saisie!$E$2:$E$501,Saisie!$C$2:$C$501,$A5,Saisie!$A$2:$A$501,">="&DATE(Annee,8,1),Saisie!$A$2:$A$501,"<"&DATE(Annee,9,1))) | J5: =IF($A5="","",SUMIFS(Saisie!$E$2:$E$501,Saisie!$C$2:$C$501,$A5,Saisie!$A$2:$A$501,">="&DATE(Annee,9,1),Saisie!$A$2:$A$501,"<"&DATE(Annee,10,1))) | K5: =IF($A5="","",SUMIFS(Saisie!$E$2:$E$501,Saisie!$C$2:$C$501,$A5,Saisie!$A$2:$A$501,">="&DATE(Annee,10,1),Saisie!$A$2:$A$501,"<"&DATE(Annee,11,1))) | L5: =IF($A5="","",SUMIFS(Saisie!$E$2:$E$501,Saisie!$C$2:$C$501,$A5,Saisie!$A$2:$A$501,">="&DATE(Annee,11,1),Saisie!$A$2:$A$501,"<"&DATE(Annee,12,1))) | M5: =IF($A5="","",SUMIFS(Saisie!$E$2:$E$501,Saisie!$C$2:$C$501,$A5,Saisie!$A$2:$A$501,">="&DATE(Annee,12,1),Saisie!$A$2:$A$501,"<"&DATE(Annee,13,1))) | N5: =IF($A5="","",SUM(B5:M5))
A6: =IF(INDEX(Liste_Projets,2)="","",INDEX(Liste_Projets,2)) | B6: =IF($A6="","",SUMIFS(Saisie!$E$2:$E$501,Saisie!$C$2:$C$501,$A6,Saisie!$A$2:$A$501,">="&DATE(Annee,1,1),Saisie!$A$2:$A$501,"<"&DATE(Annee,2,1))) | C6: =IF($A6="","",SUMIFS(Saisie!$E$2:$E$501,Saisie!$C$2:$C$501,$A6,Saisie!$A$2:$A$501,">="&DATE(Annee,2,1),Saisie!$A$2:$A$501,"<"&DATE(Annee,3,1))) | D6: =IF($A6="","",SUMIFS(Saisie!$E$2:$E$501,Saisie!$C$2:$C$501,$A6,Saisie!$A$2:$A$501,">="&DATE(Annee,3,1),Saisie!$A$2:$A$501,"<"&DATE(Annee,4,1))) | E6: =IF($A6="","",SUMIFS(Saisie!$E$2:$E$501,Saisie!$C$2:$C$501,$A6,Saisie!$A$2:$A$501,">="&DATE(Annee,4,1),Saisie!$A$2:$A$501,"<"&DATE(Annee,5,1))) | F6: =IF($A6="","",SUMIFS(Saisie!$E$2:$E$501,Saisie!$C$2:$C$501,$A6,Saisie!$A$2:$A$501,">="&DATE(Annee,5,1),Saisie!$A$2:$A$501,"<"&DATE(Annee,6,1))) | G6: =IF($A6="","",SUMIFS(Saisie!$E$2:$E$501,Saisie!$C$2:$C$501,$A6,Saisie!$A$2:$A$501,">="&DATE(Annee,6,1),Saisie!$A$2:$A$501,"<"&DATE(Annee,7,1))) | H6: =IF($A6="","",SUMIFS(Saisie!$E$2:$E$501,Saisie!$C$2:$C$501,$A6,Saisie!$A$2:$A$501,">="&DATE(Annee,7,1),Saisie!$A$2:$A$501,"<"&DATE(Annee,8,1))) | I6: =IF($A6="","",SUMIFS(Saisie!$E$2:$E$501,Saisie!$C$2:$C$501,$A6,Saisie!$A$2:$A$501,">="&DATE(Annee,8,1),Saisie!$A$2:$A$501,"<"&DATE(Annee,9,1))) | J6: =IF($A6="","",SUMIFS(Saisie!$E$2:$E$501,Saisie!$C$2:$C$501,$A6,Saisie!$A$2:$A$501,">="&DATE(Annee,9,1),Saisie!$A$2:$A$501,"<"&DATE(Annee,10,1))) | K6: =IF($A6="","",SUMIFS(Saisie!$E$2:$E$501,Saisie!$C$2:$C$501,$A6,Saisie!$A$2:$A$501,">="&DATE(Annee,10,1),Saisie!$A$2:$A$501,"<"&DATE(Annee,11,1))) | L6: =IF($A6="","",SUMIFS(Saisie!$E$2:$E$501,Saisie!$C$2:$C$501,$A6,Saisie!$A$2:$A$501,">="&DATE(Annee,11,1),Saisie!$A$2:$A$501,"<"&DATE(Annee,12,1))) | M6: =IF($A6="","",SUMIFS(Saisie!$E$2:$E$501,Saisie!$C$2:$C$501,$A6,Saisie!$A$2:$A$501,">="&DATE(Annee,12,1),Saisie!$A$2:$A$501,"<"&DATE(Annee,13,1))) | N6: =IF($A6="","",SUM(B6:M6))
A7: =IF(INDEX(Liste_Projets,3)="","",INDEX(Liste_Projets,3)) | B7: =IF($A7="","",SUMIFS(Saisie!$E$2:$E$501,Saisie!$C$2:$C$501,$A7,Saisie!$A$2:$A$501,">="&DATE(Annee,1,1),Saisie!$A$2:$A$501,"<"&DATE(Annee,2,1))) | C7: =IF($A7="","",SUMIFS(Saisie!$E$2:$E$501,Saisie!$C$2:$C$501,$A7,Saisie!$A$2:$A$501,">="&DATE(Annee,2,1),Saisie!$A$2:$A$501,"<"&DATE(Annee,3,1))) | D7: =IF($A7="","",SUMIFS(Saisie!$E$2:$E$501,Saisie!$C$2:$C$501,$A7,Saisie!$A$2:$A$501,">="&DATE(Annee,3,1),Saisie!$A$2:$A$501,"<"&DATE(Annee,4,1))) | E7: =IF($A7="","",SUMIFS(Saisie!$E$2:$E$501,Saisie!$C$2:$C$501,$A7,Saisie!$A$2:$A$501,">="&DATE(Annee,4,1),Saisie!$A$2:$A$501,"<"&DATE(Annee,5,1))) | F7: =IF($A7="","",SUMIFS(Saisie!$E$2:$E$501,Saisie!$C$2:$C$501,$A7,Saisie!$A$2:$A$501,">="&DATE(Annee,5,1),Saisie!$A$2:$A$501,"<"&DATE(Annee,6,1))) | G7: =IF($A7="","",SUMIFS(Saisie!$E$2:$E$501,Saisie!$C$2:$C$501,$A7,Saisie!$A$2:$A$501,">="&DATE(Annee,6,1),Saisie!$A$2:$A$501,"<"&DATE(Annee,7,1))) | H7: =IF($A7="","",SUMIFS(Saisie!$E$2:$E$501,Saisie!$C$2:$C$501,$A7,Saisie!$A$2:$A$501,">="&DATE(Annee,7,1),Saisie!$A$2:$A$501,"<"&DATE(Annee,8,1))) | I7: =IF($A7="","",SUMIFS(Saisie!$E$2:$E$501,Saisie!$C$2:$C$501,$A7,Saisie!$A$2:$A$501,">="&DATE(Annee,8,1),Saisie!$A$2:$A$501,"<"&DATE(Annee,9,1))) | J7: =IF($A7="","",SUMIFS(Saisie!$E$2:$E$501,Saisie!$C$2:$C$501,$A7,Saisie!$A$2:$A$501,">="&DATE(Annee,9,1),Saisie!$A$2:$A$501,"<"&DATE(Annee,10,1))) | K7: =IF($A7="","",SUMIFS(Saisie!$E$2:$E$501,Saisie!$C$2:$C$501,$A7,Saisie!$A$2:$A$501,">="&DATE(Annee,10,1),Saisie!$A$2:$A$501,"<"&DATE(Annee,11,1))) | L7: =IF($A7="","",SUMIFS(Saisie!$E$2:$E$501,Saisie!$C$2:$C$501,$A7,Saisie!$A$2:$A$501,">="&DATE(Annee,11,1),Saisie!$A$2:$A$501,"<"&DATE(Annee,12,1))) | M7: =IF($A7="","",SUMIFS(Saisie!$E$2:$E$501,Saisie!$C$2:$C$501,$A7,Saisie!$A$2:$A$501,">="&DATE(Annee,12,1),Saisie!$A$2:$A$501,"<"&DATE(Annee,13,1))) | N7: =IF($A7="","",SUM(B7:M7))
A8: =IF(INDEX(Liste_Projets,4)="","",INDEX(Liste_Projets,4)) | B8: =IF($A8="","",SUMIFS(Saisie!$E$2:$E$501,Saisie!$C$2:$C$501,$A8,Saisie!$A$2:$A$501,">="&DATE(Annee,1,1),Saisie!$A$2:$A$501,"<"&DATE(Annee,2,1))) | C8: =IF($A8="","",SUMIFS(Saisie!$E$2:$E$501,Saisie!$C$2:$C$501,$A8,Saisie!$A$2:$A$501,">="&DATE(Annee,2,1),Saisie!$A$2:$A$501,"<"&DATE(Annee,3,1))) | D8: =IF($A8="","",SUMIFS(Saisie!$E$2:$E$501,Saisie!$C$2:$C$501,$A8,Saisie!$A$2:$A$501,">="&DATE(Annee,3,1),Saisie!$A$2:$A$501,"<"&DATE(Annee,4,1))) | E8: =IF($A8="","",SUMIFS(Saisie!$E$2:$E$501,Saisie!$C$2:$C$501,$A8,Saisie!$A$2:$A$501,">="&DATE(Annee,4,1),Saisie!$A$2:$A$501,"<"&DATE(Annee,5,1))) | F8: =IF($A8="","",SUMIFS(Saisie!$E$2:$E$501,Saisie!$C$2:$C$501,$A8,Saisie!$A$2:$A$501,">="&DATE(Annee,5,1),Saisie!$A$2:$A$501,"<"&DATE(Annee,6,1))) | G8: =IF($A8="","",SUMIFS(Saisie!$E$2:$E$501,Saisie!$C$2:$C$501,$A8,Saisie!$A$2:$A$501,">="&DATE(Annee,6,1),Saisie!$A$2:$A$501,"<"&DATE(Annee,7,1))) | H8: =IF($A8="","",SUMIFS(Saisie!$E$2:$E$501,Saisie!$C$2:$C$501,$A8,Saisie!$A$2:$A$501,">="&DATE(Annee,7,1),Saisie!$A$2:$A$501,"<"&DATE(Annee,8,1))) | I8: =IF($A8="","",SUMIFS(Saisie!$E$2:$E$501,Saisie!$C$2:$C$501,$A8,Saisie!$A$2:$A$501,">="&DATE(Annee,8,1),Saisie!$A$2:$A$501,"<"&DATE(Annee,9,1))) | J8: =IF($A8="","",SUMIFS(Saisie!$E$2:$E$501,Saisie!$C$2:$C$501,$A8,Saisie!$A$2:$A$501,">="&DATE(Annee,9,1),Saisie!$A$2:$A$501,"<"&DATE(Annee,10,1))) | K8: =IF($A8="","",SUMIFS(Saisie!$E$2:$E$501,Saisie!$C$2:$C$501,$A8,Saisie!$A$2:$A$501,">="&DATE(Annee,10,1),Saisie!$A$2:$A$501,"<"&DATE(Annee,11,1))) | L8: =IF($A8="","",SUMIFS(Saisie!$E$2:$E$501,Saisie!$C$2:$C$501,$A8,Saisie!$A$2:$A$501,">="&DATE(Annee,11,1),Saisie!$A$2:$A$501,"<"&DATE(Annee,12,1))) | M8: =IF($A8="","",SUMIFS(Saisie!$E$2:$E$501,Saisie!$C$2:$C$501,$A8,Saisie!$A$2:$A$501,">="&DATE(Annee,12,1),Saisie!$A$2:$A$501,"<"&DATE(Annee,13,1))) | N8: =IF($A8="","",SUM(B8:M8))
A9: =IF(INDEX(Liste_Projets,5)="","",INDEX(Liste_Projets,5)) | B9: =IF($A9="","",SUMIFS(Saisie!$E$2:$E$501,Saisie!$C$2:$C$501,$A9,Saisie!$A$2:$A$501,">="&DATE(Annee,1,1),Saisie!$A$2:$A$501,"<"&DATE(Annee,2,1))) | C9: =IF($A9="","",SUMIFS(Saisie!$E$2:$E$501,Saisie!$C$2:$C$501,$A9,Saisie!$A$2:$A$501,">="&DATE(Annee,2,1),Saisie!$A$2:$A$501,"<"&DATE(Annee,3,1))) | D9: =IF($A9="","",SUMIFS(Saisie!$E$2:$E$501,Saisie!$C$2:$C$501,$A9,Saisie!$A$2:$A$501,">="&DATE(Annee,3,1),Saisie!$A$2:$A$501,"<"&DATE(Annee,4,1))) | E9: =IF($A9="","",SUMIFS(Saisie!$E$2:$E$501,Saisie!$C$2:$C$501,$A9,Saisie!$A$2:$A$501,">="&DATE(Annee,4,1),Saisie!$A$2:$A$501,"<"&DATE(Annee,5,1))) | F9: =IF($A9="","",SUMIFS(Saisie!$E$2:$E$501,Saisie!$C$2:$C$501,$A9,Saisie!$A$2:$A$501,">="&DATE(Annee,5,1),Saisie!$A$2:$A$501,"<"&DATE(Annee,6,1))) | G9: =IF($A9="","",SUMIFS(Saisie!$E$2:$E$501,Saisie!$C$2:$C$501,$A9,Saisie!$A$2:$A$501,">="&DATE(Annee,6,1),Saisie!$A$2:$A$501,"<"&DATE(Annee,7,1))) | H9: =IF($A9="","",SUMIFS(Saisie!$E$2:$E$501,Saisie!$C$2:$C$501,$A9,Saisie!$A$2:$A$501,">="&DATE(Annee,7,1),Saisie!$A$2:$A$501,"<"&DATE(Annee,8,1))) | I9: =IF($A9="","",SUMIFS(Saisie!$E$2:$E$501,Saisie!$C$2:$C$501,$A9,Saisie!$A$2:$A$501,">="&DATE(Annee,8,1),Saisie!$A$2:$A$501,"<"&DATE(Annee,9,1))) | J9: =IF($A9="","",SUMIFS(Saisie!$E$2:$E$501,Saisie!$C$2:$C$501,$A9,Saisie!$A$2:$A$501,">="&DATE(Annee,9,1),Saisie!$A$2:$A$501,"<"&DATE(Annee,10,1))) | K9: =IF($A9="","",SUMIFS(Saisie!$E$2:$E$501,Saisie!$C$2:$C$501,$A9,Saisie!$A$2:$A$501,">="&DATE(Annee,10,1),Saisie!$A$2:$A$501,"<"&DATE(Annee,11,1))) | L9: =IF($A9="","",SUMIFS(Saisie!$E$2:$E$501,Saisie!$C$2:$C$501,$A9,Saisie!$A$2:$A$501,">="&DATE(Annee,11,1),Saisie!$A$2:$A$501,"<"&DATE(Annee,12,1))) | M9: =IF($A9="","",SUMIFS(Saisie!$E$2:$E$501,Saisie!$C$2:$C$501,$A9,Saisie!$A$2:$A$501,">="&DATE(Annee,12,1),Saisie!$A$2:$A$501,"<"&DATE(Annee,13,1))) | N9: =IF($A9="","",SUM(B9:M9))
A10: =IF(INDEX(Liste_Projets,6)="","",INDEX(Liste_Projets,6)) | B10: =IF($A10="","",SUMIFS(Saisie!$E$2:$E$501,Saisie!$C$2:$C$501,$A10,Saisie!$A$2:$A$501,">="&DATE(Annee,1,1),Saisie!$A$2:$A$501,"<"&DATE(Annee,2,1))) | C10: =IF($A10="","",SUMIFS(Saisie!$E$2:$E$501,Saisie!$C$2:$C$501,$A10,Saisie!$A$2:$A$501,">="&DATE(Annee,2,1),Saisie!$A$2:$A$501,"<"&DATE(Annee,3,1))) | D10: =IF($A10="","",SUMIFS(Saisie!$E$2:$E$501,Saisie!$C$2:$C$501,$A10,Saisie!$A$2:$A$501,">="&DATE(Annee,3,1),Saisie!$A$2:$A$501,"<"&DATE(Annee,4,1))) | E10: =IF($A10="","",SUMIFS(Saisie!$E$2:$E$501,Saisie!$C$2:$C$501,$A10,Saisie!$A$2:$A$501,">="&DATE(Annee,4,1),Saisie!$A$2:$A$501,"<"&DATE(Annee,5,1))) | F10: =IF($A10="","",SUMIFS(Saisie!$E$2:$E$501,Saisie!$C$2:$C$501,$A10,Saisie!$A$2:$A$501,">="&DATE(Annee,5,1),Saisie!$A$2:$A$501,"<"&DATE(Annee,6,1))) | G10: =IF($A10="","",SUMIFS(Saisie!$E$2:$E$501,Saisie!$C$2:$C$501,$A10,Saisie!$A$2:$A$501,">="&DATE(Annee,6,1),Saisie!$A$2:$A$501,"<"&DATE(Annee,7,1))) | H10: =IF($A10="","",SUMIFS(Saisie!$E$2:$E$501,Saisie!$C$2:$C$501,$A10,Saisie!$A$2:$A$501,">="&DATE(Annee,7,1),Saisie!$A$2:$A$501,"<"&DATE(Annee,8,1))) | I10: =IF($A10="","",SUMIFS(Saisie!$E$2:$E$501,Saisie!$C$2:$C$501,$A10,Saisie!$A$2:$A$501,">="&DATE(Annee,8,1),Saisie!$A$2:$A$501,"<"&DATE(Annee,9,1))) | J10: =IF($A10="","",SUMIFS(Saisie!$E$2:$E$501,Saisie!$C$2:$C$501,$A10,Saisie!$A$2:$A$501,">="&DATE(Annee,9,1),Saisie!$A$2:$A$501,"<"&DATE(Annee,10,1))) | K10: =IF($A10="","",SUMIFS(Saisie!$E$2:$E$501,Saisie!$C$2:$C$501,$A10,Saisie!$A$2:$A$501,">="&DATE(Annee,10,1),Saisie!$A$2:$A$501,"<"&DATE(Annee,11,1))) | L10: =IF($A10="","",SUMIFS(Saisie!$E$2:$E$501,Saisie!$C$2:$C$501,$A10,Saisie!$A$2:$A$501,">="&DATE(Annee,11,1),Saisie!$A$2:$A$501,"<"&DATE(Annee,12,1))) | M10: =IF($A10="","",SUMIFS(Saisie!$E$2:$E$501,Saisie!$C$2:$C$501,$A10,Saisie!$A$2:$A$501,">="&DATE(Annee,12,1),Saisie!$A$2:$A$501,"<"&DATE(Annee,13,1))) | N10: =IF($A10="","",SUM(B10:M10))
A11: =IF(INDEX(Liste_Projets,7)="","",INDEX(Liste_Projets,7)) | B11: =IF($A11="","",SUMIFS(Saisie!$E$2:$E$501,Saisie!$C$2:$C$501,$A11,Saisie!$A$2:$A$501,">="&DATE(Annee,1,1),Saisie!$A$2:$A$501,"<"&DATE(Annee,2,1))) | C11: =IF($A11="","",SUMIFS(Saisie!$E$2:$E$501,Saisie!$C$2:$C$501,$A11,Saisie!$A$2:$A$501,">="&DATE(Annee,2,1),Saisie!$A$2:$A$501,"<"&DATE(Annee,3,1))) | D11: =IF($A11="","",SUMIFS(Saisie!$E$2:$E$501,Saisie!$C$2:$C$501,$A11,Saisie!$A$2:$A$501,">="&DATE(Annee,3,1),Saisie!$A$2:$A$501,"<"&DATE(Annee,4,1))) | E11: =IF($A11="","",SUMIFS(Saisie!$E$2:$E$501,Saisie!$C$2:$C$501,$A11,Saisie!$A$2:$A$501,">="&DATE(Annee,4,1),Saisie!$A$2:$A$501,"<"&DATE(Annee,5,1))) | F11: =IF($A11="","",SUMIFS(Saisie!$E$2:$E$501,Saisie!$C$2:$C$501,$A11,Saisie!$A$2:$A$501,">="&DATE(Annee,5,1),Saisie!$A$2:$A$501,"<"&DATE(Annee,6,1))) | G11: =IF($A11="","",SUMIFS(Saisie!$E$2:$E$501,Saisie!$C$2:$C$501,$A11,Saisie!$A$2:$A$501,">="&DATE(Annee,6,1),Saisie!$A$2:$A$501,"<"&DATE(Annee,7,1))) | H11: =IF($A11="","",SUMIFS(Saisie!$E$2:$E$501,Saisie!$C$2:$C$501,$A11,Saisie!$A$2:$A$501,">="&DATE(Annee,7,1),Saisie!$A$2:$A$501,"<"&DATE(Annee,8,1))) | I11: =IF($A11="","",SUMIFS(Saisie!$E$2:$E$501,Saisie!$C$2:$C$501,$A11,Saisie!$A$2:$A$501,">="&DATE(Annee,8,1),Saisie!$A$2:$A$501,"<"&DATE(Annee,9,1))) | J11: =IF($A11="","",SUMIFS(Saisie!$E$2:$E$501,Saisie!$C$2:$C$501,$A11,Saisie!$A$2:$A$501,">="&DATE(Annee,9,1),Saisie!$A$2:$A$501,"<"&DATE(Annee,10,1))) | K11: =IF($A11="","",SUMIFS(Saisie!$E$2:$E$501,Saisie!$C$2:$C$501,$A11,Saisie!$A$2:$A$501,">="&DATE(Annee,10,1),Saisie!$A$2:$A$501,"<"&DATE(Annee,11,1))) | L11: =IF($A11="","",SUMIFS(Saisie!$E$2:$E$501,Saisie!$C$2:$C$501,$A11,Saisie!$A$2:$A$501,">="&DATE(Annee,11,1),Saisie!$A$2:$A$501,"<"&DATE(Annee,12,1))) | M11: =IF($A11="","",SUMIFS(Saisie!$E$2:$E$501,Saisie!$C$2:$C$501,$A11,Saisie!$A$2:$A$501,">="&DATE(Annee,12,1),Saisie!$A$2:$A$501,"<"&DATE(Annee,13,1))) | N11: =IF($A11="","",SUM(B11:M11))
A12: =IF(INDEX(Liste_Projets,8)="","",INDEX(Liste_Projets,8)) | B12: =IF($A12="","",SUMIFS(Saisie!$E$2:$E$501,Saisie!$C$2:$C$501,$A12,Saisie!$A$2:$A$501,">="&DATE(Annee,1,1),Saisie!$A$2:$A$501,"<"&DATE(Annee,2,1))) | C12: =IF($A12="","",SUMIFS(Saisie!$E$2:$E$501,Saisie!$C$2:$C$501,$A12,Saisie!$A$2:$A$501,">="&DATE(Annee,2,1),Saisie!$A$2:$A$501,"<"&DATE(Annee,3,1))) | D12: =IF($A12="","",SUMIFS(Saisie!$E$2:$E$501,Saisie!$C$2:$C$501,$A12,Saisie!$A$2:$A$501,">="&DATE(Annee,3,1),Saisie!$A$2:$A$501,"<"&DATE(Annee,4,1))) | E12: =IF($A12="","",SUMIFS(Saisie!$E$2:$E$501,Saisie!$C$2:$C$501,$A12,Saisie!$A$2:$A$501,">="&DATE(Annee,4,1),Saisie!$A$2:$A$501,"<"&DATE(Annee,5,1))) | F12: =IF($A12="","",SUMIFS(Saisie!$E$2:$E$501,Saisie!$C$2:$C$501,$A12,Saisie!$A$2:$A$501,">="&DATE(Annee,5,1),Saisie!$A$2:$A$501,"<"&DATE(Annee,6,1))) | G12: =IF($A12="","",SUMIFS(Saisie!$E$2:$E$501,Saisie!$C$2:$C$501,$A12,Saisie!$A$2:$A$501,">="&DATE(Annee,6,1),Saisie!$A$2:$A$501,"<"&DATE(Annee,7,1))) | H12: =IF($A12="","",SUMIFS(Saisie!$E$2:$E$501,Saisie!$C$2:$C$501,$A12,Saisie!$A$2:$A$501,">="&DATE(Annee,7,1),Saisie!$A$2:$A$501,"<"&DATE(Annee,8,1))) | I12: =IF($A12="","",SUMIFS(Saisie!$E$2:$E$501,Saisie!$C$2:$C$501,$A12,Saisie!$A$2:$A$501,">="&DATE(Annee,8,1),Saisie!$A$2:$A$501,"<"&DATE(Annee,9,1))) | J12: =IF($A12="","",SUMIFS(Saisie!$E$2:$E$501,Saisie!$C$2:$C$501,$A12,Saisie!$A$2:$A$501,">="&DATE(Annee,9,1),Saisie!$A$2:$A$501,"<"&DATE(Annee,10,1))) | K12: =IF($A12="","",SUMIFS(Saisie!$E$2:$E$501,Saisie!$C$2:$C$501,$A12,Saisie!$A$2:$A$501,">="&DATE(Annee,10,1),Saisie!$A$2:$A$501,"<"&DATE(Annee,11,1))) | L12: =IF($A12="","",SUMIFS(Saisie!$E$2:$E$501,Saisie!$C$2:$C$501,$A12,Saisie!$A$2:$A$501,">="&DATE(Annee,11,1),Saisie!$A$2:$A$501,"<"&DATE(Annee,12,1))) | M12: =IF($A12="","",SUMIFS(Saisie!$E$2:$E$501,Saisie!$C$2:$C$501,$A12,Saisie!$A$2:$A$501,">="&DATE(Annee,12,1),Saisie!$A$2:$A$501,"<"&DATE(Annee,13,1))) | N12: =IF($A12="","",SUM(B12:M12))
A13: =IF(INDEX(Liste_Projets,9)="","",INDEX(Liste_Projets,9)) | B13: =IF($A13="","",SUMIFS(Saisie!$E$2:$E$501,Saisie!$C$2:$C$501,$A13,Saisie!$A$2:$A$501,">="&DATE(Annee,1,1),Saisie!$A$2:$A$501,"<"&DATE(Annee,2,1))) | C13: =IF($A13="","",SUMIFS(Saisie!$E$2:$E$501,Saisie!$C$2:$C$501,$A13,Saisie!$A$2:$A$501,">="&DATE(Annee,2,1),Saisie!$A$2:$A$501,"<"&DATE(Annee,3,1))) | D13: =IF($A13="","",SUMIFS(Saisie!$E$2:$E$501,Saisie!$C$2:$C$501,$A13,Saisie!$A$2:$A$501,">="&DATE(Annee,3,1),Saisie!$A$2:$A$501,"<"&DATE(Annee,4,1))) | E13: =IF($A13="","",SUMIFS(Saisie!$E$2:$E$501,Saisie!$C$2:$C$501,$A13,Saisie!$A$2:$A$501,">="&DATE(Annee,4,1),Saisie!$A$2:$A$501,"<"&DATE(Annee,5,1))) | F13: =IF($A13="","",SUMIFS(Saisie!$E$2:$E$501,Saisie!$C$2:$C$501,$A13,Saisie!$A$2:$A$501,">="&DATE(Annee,5,1),Saisie!$A$2:$A$501,"<"&DATE(Annee,6,1))) | G13: =IF($A13="","",SUMIFS(Saisie!$E$2:$E$501,Saisie!$C$2:$C$501,$A13,Saisie!$A$2:$A$501,">="&DATE(Annee,6,1),Saisie!$A$2:$A$501,"<"&DATE(Annee,7,1))) | H13: =IF($A13="","",SUMIFS(Saisie!$E$2:$E$501,Saisie!$C$2:$C$501,$A13,Saisie!$A$2:$A$501,">="&DATE(Annee,7,1),Saisie!$A$2:$A$501,"<"&DATE(Annee,8,1))) | I13: =IF($A13="","",SUMIFS(Saisie!$E$2:$E$501,Saisie!$C$2:$C$501,$A13,Saisie!$A$2:$A$501,">="&DATE(Annee,8,1),Saisie!$A$2:$A$501,"<"&DATE(Annee,9,1))) | J13: =IF($A13="","",SUMIFS(Saisie!$E$2:$E$501,Saisie!$C$2:$C$501,$A13,Saisie!$A$2:$A$501,">="&DATE(Annee,9,1),Saisie!$A$2:$A$501,"<"&DATE(Annee,10,1))) | K13: =IF($A13="","",SUMIFS(Saisie!$E$2:$E$501,Saisie!$C$2:$C$501,$A13,Saisie!$A$2:$A$501,">="&DATE(Annee,10,1),Saisie!$A$2:$A$501,"<"&DATE(Annee,11,1))) | L13: =IF($A13="","",SUMIFS(Saisie!$E$2:$E$501,Saisie!$C$2:$C$501,$A13,Saisie!$A$2:$A$501,">="&DATE(Annee,11,1),Saisie!$A$2:$A$501,"<"&DATE(Annee,12,1))) | M13: =IF($A13="","",SUMIFS(Saisie!$E$2:$E$501,Saisie!$C$2:$C$501,$A13,Saisie!$A$2:$A$501,">="&DATE(Annee,12,1),Saisie!$A$2:$A$501,"<"&DATE(Annee,13,1))) | N13: =IF($A13="","",SUM(B13:M13))
A14: =IF(INDEX(Liste_Projets,10)="","",INDEX(Liste_Projets,10)) | B14: =IF($A14="","",SUMIFS(Saisie!$E$2:$E$501,Saisie!$C$2:$C$501,$A14,Saisie!$A$2:$A$501,">="&DATE(Annee,1,1),Saisie!$A$2:$A$501,"<"&DATE(Annee,2,1))) | C14: =IF($A14="","",SUMIFS(Saisie!$E$2:$E$501,Saisie!$C$2:$C$501,$A14,Saisie!$A$2:$A$501,">="&DATE(Annee,2,1),Saisie!$A$2:$A$501,"<"&DATE(Annee,3,1))) | D14: =IF($A14="","",SUMIFS(Saisie!$E$2:$E$501,Saisie!$C$2:$C$501,$A14,Saisie!$A$2:$A$501,">="&DATE(Annee,3,1),Saisie!$A$2:$A$501,"<"&DATE(Annee,4,1))) | E14: =IF($A14="","",SUMIFS(Saisie!$E$2:$E$501,Saisie!$C$2:$C$501,$A14,Saisie!$A$2:$A$501,">="&DATE(Annee,4,1),Saisie!$A$2:$A$501,"<"&DATE(Annee,5,1))) | F14: =IF($A14="","",SUMIFS(Saisie!$E$2:$E$501,Saisie!$C$2:$C$501,$A14,Saisie!$A$2:$A$501,">="&DATE(Annee,5,1),Saisie!$A$2:$A$501,"<"&DATE(Annee,6,1))) | G14: =IF($A14="","",SUMIFS(Saisie!$E$2:$E$501,Saisie!$C$2:$C$501,$A14,Saisie!$A$2:$A$501,">="&DATE(Annee,6,1),Saisie!$A$2:$A$501,"<"&DATE(Annee,7,1))) | H14: =IF($A14="","",SUMIFS(Saisie!$E$2:$E$501,Saisie!$C$2:$C$501,$A14,Saisie!$A$2:$A$501,">="&DATE(Annee,7,1),Saisie!$A$2:$A$501,"<"&DATE(Annee,8,1))) | I14: =IF($A14="","",SUMIFS(Saisie!$E$2:$E$501,Saisie!$C$2:$C$501,$A14,Saisie!$A$2:$A$501,">="&DATE(Annee,8,1),Saisie!$A$2:$A$501,"<"&DATE(Annee,9,1))) | J14: =IF($A14="","",SUMIFS(Saisie!$E$2:$E$501,Saisie!$C$2:$C$501,$A14,Saisie!$A$2:$A$501,">="&DATE(Annee,9,1),Saisie!$A$2:$A$501,"<"&DATE(Annee,10,1))) | K14: =IF($A14="","",SUMIFS(Saisie!$E$2:$E$501,Saisie!$C$2:$C$501,$A14,Saisie!$A$2:$A$501,">="&DATE(Annee,10,1),Saisie!$A$2:$A$501,"<"&DATE(Annee,11,1))) | L14: =IF($A14="","",SUMIFS(Saisie!$E$2:$E$501,Saisie!$C$2:$C$501,$A14,Saisie!$A$2:$A$501,">="&DATE(Annee,11,1),Saisie!$A$2:$A$501,"<"&DATE(Annee,12,1))) | M14: =IF($A14="","",SUMIFS(Saisie!$E$2:$E$501,Saisie!$C$2:$C$501,$A14,Saisie!$A$2:$A$501,">="&DATE(Annee,12,1),Saisie!$A$2:$A$501,"<"&DATE(Annee,13,1))) | N14: =IF($A14="","",SUM(B14:M14))
A15: =IF(INDEX(Liste_Projets,11)="","",INDEX(Liste_Projets,11)) | B15: =IF($A15="","",SUMIFS(Saisie!$E$2:$E$501,Saisie!$C$2:$C$501,$A15,Saisie!$A$2:$A$501,">="&DATE(Annee,1,1),Saisie!$A$2:$A$501,"<"&DATE(Annee,2,1))) | C15: =IF($A15="","",SUMIFS(Saisie!$E$2:$E$501,Saisie!$C$2:$C$501,$A15,Saisie!$A$2:$A$501,">="&DATE(Annee,2,1),Saisie!$A$2:$A$501,"<"&DATE(Annee,3,1))) | D15: =IF($A15="","",SUMIFS(Saisie!$E$2:$E$501,Saisie!$C$2:$C$501,$A15,Saisie!$A$2:$A$501,">="&DATE(Annee,3,1),Saisie!$A$2:$A$501,"<"&DATE(Annee,4,1))) | E15: =IF($A15="","",SUMIFS(Saisie!$E$2:$E$501,Saisie!$C$2:$C$501,$A15,Saisie!$A$2:$A$501,">="&DATE(Annee,4,1),Saisie!$A$2:$A$501,"<"&DATE(Annee,5,1))) | F15: =IF($A15="","",SUMIFS(Saisie!$E$2:$E$501,Saisie!$C$2:$C$501,$A15,Saisie!$A$2:$A$501,">="&DATE(Annee,5,1),Saisie!$A$2:$A$501,"<"&DATE(Annee,6,1))) | G15: =IF($A15="","",SUMIFS(Saisie!$E$2:$E$501,Saisie!$C$2:$C$501,$A15,Saisie!$A$2:$A$501,">="&DATE(Annee,6,1),Saisie!$A$2:$A$501,"<"&DATE(Annee,7,1))) | H15: =IF($A15="","",SUMIFS(Saisie!$E$2:$E$501,Saisie!$C$2:$C$501,$A15,Saisie!$A$2:$A$501,">="&DATE(Annee,7,1),Saisie!$A$2:$A$501,"<"&DATE(Annee,8,1))) | I15: =IF($A15="","",SUMIFS(Saisie!$E$2:$E$501,Saisie!$C$2:$C$501,$A15,Saisie!$A$2:$A$501,">="&DATE(Annee,8,1),Saisie!$A$2:$A$501,"<"&DATE(Annee,9,1))) | J15: =IF($A15="","",SUMIFS(Saisie!$E$2:$E$501,Saisie!$C$2:$C$501,$A15,Saisie!$A$2:$A$501,">="&DATE(Annee,9,1),Saisie!$A$2:$A$501,"<"&DATE(Annee,10,1))) | K15: =IF($A15="","",SUMIFS(Saisie!$E$2:$E$501,Saisie!$C$2:$C$501,$A15,Saisie!$A$2:$A$501,">="&DATE(Annee,10,1),Saisie!$A$2:$A$501,"<"&DATE(Annee,11,1))) | L15: =IF($A15="","",SUMIFS(Saisie!$E$2:$E$501,Saisie!$C$2:$C$501,$A15,Saisie!$A$2:$A$501,">="&DATE(Annee,11,1),Saisie!$A$2:$A$501,"<"&DATE(Annee,12,1))) | M15: =IF($A15="","",SUMIFS(Saisie!$E$2:$E$501,Saisie!$C$2:$C$501,$A15,Saisie!$A$2:$A$501,">="&DATE(Annee,12,1),Saisie!$A$2:$A$501,"<"&DATE(Annee,13,1))) | N15: =IF($A15="","",SUM(B15:M15))
A16: =IF(INDEX(Liste_Projets,12)="","",INDEX(Liste_Projets,12)) | B16: =IF($A16="","",SUMIFS(Saisie!$E$2:$E$501,Saisie!$C$2:$C$501,$A16,Saisie!$A$2:$A$501,">="&DATE(Annee,1,1),Saisie!$A$2:$A$501,"<"&DATE(Annee,2,1))) | C16: =IF($A16="","",SUMIFS(Saisie!$E$2:$E$501,Saisie!$C$2:$C$501,$A16,Saisie!$A$2:$A$501,">="&DATE(Annee,2,1),Saisie!$A$2:$A$501,"<"&DATE(Annee,3,1))) | D16: =IF($A16="","",SUMIFS(Saisie!$E$2:$E$501,Saisie!$C$2:$C$501,$A16,Saisie!$A$2:$A$501,">="&DATE(Annee,3,1),Saisie!$A$2:$A$501,"<"&DATE(Annee,4,1))) | E16: =IF($A16="","",SUMIFS(Saisie!$E$2:$E$501,Saisie!$C$2:$C$501,$A16,Saisie!$A$2:$A$501,">="&DATE(Annee,4,1),Saisie!$A$2:$A$501,"<"&DATE(Annee,5,1))) | F16: =IF($A16="","",SUMIFS(Saisie!$E$2:$E$501,Saisie!$C$2:$C$501,$A16,Saisie!$A$2:$A$501,">="&DATE(Annee,5,1),Saisie!$A$2:$A$501,"<"&DATE(Annee,6,1))) | G16: =IF($A16="","",SUMIFS(Saisie!$E$2:$E$501,Saisie!$C$2:$C$501,$A16,Saisie!$A$2:$A$501,">="&DATE(Annee,6,1),Saisie!$A$2:$A$501,"<"&DATE(Annee,7,1))) | H16: =IF($A16="","",SUMIFS(Saisie!$E$2:$E$501,Saisie!$C$2:$C$501,$A16,Saisie!$A$2:$A$501,">="&DATE(Annee,7,1),Saisie!$A$2:$A$501,"<"&DATE(Annee,8,1))) | I16: =IF($A16="","",SUMIFS(Saisie!$E$2:$E$501,Saisie!$C$2:$C$501,$A16,Saisie!$A$2:$A$501,">="&DATE(Annee,8,1),Saisie!$A$2:$A$501,"<"&DATE(Annee,9,1))) | J16: =IF($A16="","",SUMIFS(Saisie!$E$2:$E$501,Saisie!$C$2:$C$501,$A16,Saisie!$A$2:$A$501,">="&DATE(Annee,9,1),Saisie!$A$2:$A$501,"<"&DATE(Annee,10,1))) | K16: =IF($A16="","",SUMIFS(Saisie!$E$2:$E$501,Saisie!$C$2:$C$501,$A16,Saisie!$A$2:$A$501,">="&DATE(Annee,10,1),Saisie!$A$2:$A$501,"<"&DATE(Annee,11,1))) | L16: =IF($A16="","",SUMIFS(Saisie!$E$2:$E$501,Saisie!$C$2:$C$501,$A16,Saisie!$A$2:$A$501,">="&DATE(Annee,11,1),Saisie!$A$2:$A$501,"<"&DATE(Annee,12,1))) | M16: =IF($A16="","",SUMIFS(Saisie!$E$2:$E$501,Saisie!$C$2:$C$501,$A16,Saisie!$A$2:$A$501,">="&DATE(Annee,12,1),Saisie!$A$2:$A$501,"<"&DATE(Annee,13,1))) | N16: =IF($A16="","",SUM(B16:M16))
A17: =IF(INDEX(Liste_Projets,13)="","",INDEX(Liste_Projets,13)) | B17: =IF($A17="","",SUMIFS(Saisie!$E$2:$E$501,Saisie!$C$2:$C$501,$A17,Saisie!$A$2:$A$501,">="&DATE(Annee,1,1),Saisie!$A$2:$A$501,"<"&DATE(Annee,2,1))) | C17: =IF($A17="","",SUMIFS(Saisie!$E$2:$E$501,Saisie!$C$2:$C$501,$A17,Saisie!$A$2:$A$501,">="&DATE(Annee,2,1),Saisie!$A$2:$A$501,"<"&DATE(Annee,3,1))) | D17: =IF($A17="","",SUMIFS(Saisie!$E$2:$E$501,Saisie!$C$2:$C$501,$A17,Saisie!$A$2:$A$501,">="&DATE(Annee,3,1),Saisie!$A$2:$A$501,"<"&DATE(Annee,4,1))) | E17: =IF($A17="","",SUMIFS(Saisie!$E$2:$E$501,Saisie!$C$2:$C$501,$A17,Saisie!$A$2:$A$501,">="&DATE(Annee,4,1),Saisie!$A$2:$A$501,"<"&DATE(Annee,5,1))) | F17: =IF($A17="","",SUMIFS(Saisie!$E$2:$E$501,Saisie!$C$2:$C$501,$A17,Saisie!$A$2:$A$501,">="&DATE(Annee,5,1),Saisie!$A$2:$A$501,"<"&DATE(Annee,6,1))) | G17: =IF($A17="","",SUMIFS(Saisie!$E$2:$E$501,Saisie!$C$2:$C$501,$A17,Saisie!$A$2:$A$501,">="&DATE(Annee,6,1),Saisie!$A$2:$A$501,"<"&DATE(Annee,7,1))) | H17: =IF($A17="","",SUMIFS(Saisie!$E$2:$E$501,Saisie!$C$2:$C$501,$A17,Saisie!$A$2:$A$501,">="&DATE(Annee,7,1),Saisie!$A$2:$A$501,"<"&DATE(Annee,8,1))) | I17: =IF($A17="","",SUMIFS(Saisie!$E$2:$E$501,Saisie!$C$2:$C$501,$A17,Saisie!$A$2:$A$501,">="&DATE(Annee,8,1),Saisie!$A$2:$A$501,"<"&DATE(Annee,9,1))) | J17: =IF($A17="","",SUMIFS(Saisie!$E$2:$E$501,Saisie!$C$2:$C$501,$A17,Saisie!$A$2:$A$501,">="&DATE(Annee,9,1),Saisie!$A$2:$A$501,"<"&DATE(Annee,10,1))) | K17: =IF($A17="","",SUMIFS(Saisie!$E$2:$E$501,Saisie!$C$2:$C$501,$A17,Saisie!$A$2:$A$501,">="&DATE(Annee,10,1),Saisie!$A$2:$A$501,"<"&DATE(Annee,11,1))) | L17: =IF($A17="","",SUMIFS(Saisie!$E$2:$E$501,Saisie!$C$2:$C$501,$A17,Saisie!$A$2:$A$501,">="&DATE(Annee,11,1),Saisie!$A$2:$A$501,"<"&DATE(Annee,12,1))) | M17: =IF($A17="","",SUMIFS(Saisie!$E$2:$E$501,Saisie!$C$2:$C$501,$A17,Saisie!$A$2:$A$501,">="&DATE(Annee,12,1),Saisie!$A$2:$A$501,"<"&DATE(Annee,13,1))) | N17: =IF($A17="","",SUM(B17:M17))
A18: =IF(INDEX(Liste_Projets,14)="","",INDEX(Liste_Projets,14)) | B18: =IF($A18="","",SUMIFS(Saisie!$E$2:$E$501,Saisie!$C$2:$C$501,$A18,Saisie!$A$2:$A$501,">="&DATE(Annee,1,1),Saisie!$A$2:$A$501,"<"&DATE(Annee,2,1))) | C18: =IF($A18="","",SUMIFS(Saisie!$E$2:$E$501,Saisie!$C$2:$C$501,$A18,Saisie!$A$2:$A$501,">="&DATE(Annee,2,1),Saisie!$A$2:$A$501,"<"&DATE(Annee,3,1))) | D18: =IF($A18="","",SUMIFS(Saisie!$E$2:$E$501,Saisie!$C$2:$C$501,$A18,Saisie!$A$2:$A$501,">="&DATE(Annee,3,1),Saisie!$A$2:$A$501,"<"&DATE(Annee,4,1))) | E18: =IF($A18="","",SUMIFS(Saisie!$E$2:$E$501,Saisie!$C$2:$C$501,$A18,Saisie!$A$2:$A$501,">="&DATE(Annee,4,1),Saisie!$A$2:$A$501,"<"&DATE(Annee,5,1))) | F18: =IF($A18="","",SUMIFS(Saisie!$E$2:$E$501,Saisie!$C$2:$C$501,$A18,Saisie!$A$2:$A$501,">="&DATE(Annee,5,1),Saisie!$A$2:$A$501,"<"&DATE(Annee,6,1))) | G18: =IF($A18="","",SUMIFS(Saisie!$E$2:$E$501,Saisie!$C$2:$C$501,$A18,Saisie!$A$2:$A$501,">="&DATE(Annee,6,1),Saisie!$A$2:$A$501,"<"&DATE(Annee,7,1))) | H18: =IF($A18="","",SUMIFS(Saisie!$E$2:$E$501,Saisie!$C$2:$C$501,$A18,Saisie!$A$2:$A$501,">="&DATE(Annee,7,1),Saisie!$A$2:$A$501,"<"&DATE(Annee,8,1))) | I18: =IF($A18="","",SUMIFS(Saisie!$E$2:$E$501,Saisie!$C$2:$C$501,$A18,Saisie!$A$2:$A$501,">="&DATE(Annee,8,1),Saisie!$A$2:$A$501,"<"&DATE(Annee,9,1))) | J18: =IF($A18="","",SUMIFS(Saisie!$E$2:$E$501,Saisie!$C$2:$C$501,$A18,Saisie!$A$2:$A$501,">="&DATE(Annee,9,1),Saisie!$A$2:$A$501,"<"&DATE(Annee,10,1))) | K18: =IF($A18="","",SUMIFS(Saisie!$E$2:$E$501,Saisie!$C$2:$C$501,$A18,Saisie!$A$2:$A$501,">="&DATE(Annee,10,1),Saisie!$A$2:$A$501,"<"&DATE(Annee,11,1))) | L18: =IF($A18="","",SUMIFS(Saisie!$E$2:$E$501,Saisie!$C$2:$C$501,$A18,Saisie!$A$2:$A$501,">="&DATE(Annee,11,1),Saisie!$A$2:$A$501,"<"&DATE(Annee,12,1))) | M18: =IF($A18="","",SUMIFS(Saisie!$E$2:$E$501,Saisie!$C$2:$C$501,$A18,Saisie!$A$2:$A$501,">="&DATE(Annee,12,1),Saisie!$A$2:$A$501,"<"&DATE(Annee,13,1))) | N18: =IF($A18="","",SUM(B18:M18))
A19: =IF(INDEX(Liste_Projets,15)="","",INDEX(Liste_Projets,15)) | B19: =IF($A19="","",SUMIFS(Saisie!$E$2:$E$501,Saisie!$C$2:$C$501,$A19,Saisie!$A$2:$A$501,">="&DATE(Annee,1,1),Saisie!$A$2:$A$501,"<"&DATE(Annee,2,1))) | C19: =IF($A19="","",SUMIFS(Saisie!$E$2:$E$501,Saisie!$C$2:$C$501,$A19,Saisie!$A$2:$A$501,">="&DATE(Annee,2,1),Saisie!$A$2:$A$501,"<"&DATE(Annee,3,1))) | D19: =IF($A19="","",SUMIFS(Saisie!$E$2:$E$501,Saisie!$C$2:$C$501,$A19,Saisie!$A$2:$A$501,">="&DATE(Annee,3,1),Saisie!$A$2:$A$501,"<"&DATE(Annee,4,1))) | E19: =IF($A19="","",SUMIFS(Saisie!$E$2:$E$501,Saisie!$C$2:$C$501,$A19,Saisie!$A$2:$A$501,">="&DATE(Annee,4,1),Saisie!$A$2:$A$501,"<"&DATE(Annee,5,1))) | F19: =IF($A19="","",SUMIFS(Saisie!$E$2:$E$501,Saisie!$C$2:$C$501,$A19,Saisie!$A$2:$A$501,">="&DATE(Annee,5,1),Saisie!$A$2:$A$501,"<"&DATE(Annee,6,1))) | G19: =IF($A19="","",SUMIFS(Saisie!$E$2:$E$501,Saisie!$C$2:$C$501,$A19,Saisie!$A$2:$A$501,">="&DATE(Annee,6,1),Saisie!$A$2:$A$501,"<"&DATE(Annee,7,1))) | H19: =IF($A19="","",SUMIFS(Saisie!$E$2:$E$501,Saisie!$C$2:$C$501,$A19,Saisie!$A$2:$A$501,">="&DATE(Annee,7,1),Saisie!$A$2:$A$501,"<"&DATE(Annee,8,1))) | I19: =IF($A19="","",SUMIFS(Saisie!$E$2:$E$501,Saisie!$C$2:$C$501,$A19,Saisie!$A$2:$A$501,">="&DATE(Annee,8,1),Saisie!$A$2:$A$501,"<"&DATE(Annee,9,1))) | J19: =IF($A19="","",SUMIFS(Saisie!$E$2:$E$501,Saisie!$C$2:$C$501,$A19,Saisie!$A$2:$A$501,">="&DATE(Annee,9,1),Saisie!$A$2:$A$501,"<"&DATE(Annee,10,1))) | K19: =IF($A19="","",SUMIFS(Saisie!$E$2:$E$501,Saisie!$C$2:$C$501,$A19,Saisie!$A$2:$A$501,">="&DATE(Annee,10,1),Saisie!$A$2:$A$501,"<"&DATE(Annee,11,1))) | L19: =IF($A19="","",SUMIFS(Saisie!$E$2:$E$501,Saisie!$C$2:$C$501,$A19,Saisie!$A$2:$A$501,">="&DATE(Annee,11,1),Saisie!$A$2:$A$501,"<"&DATE(Annee,12,1))) | M19: =IF($A19="","",SUMIFS(Saisie!$E$2:$E$501,Saisie!$C$2:$C$501,$A19,Saisie!$A$2:$A$501,">="&DATE(Annee,12,1),Saisie!$A$2:$A$501,"<"&DATE(Annee,13,1))) | N19: =IF($A19="","",SUM(B19:M19))
A20: =IF(INDEX(Liste_Projets,16)="","",INDEX(Liste_Projets,16)) | B20: =IF($A20="","",SUMIFS(Saisie!$E$2:$E$501,Saisie!$C$2:$C$501,$A20,Saisie!$A$2:$A$501,">="&DATE(Annee,1,1),Saisie!$A$2:$A$501,"<"&DATE(Annee,2,1))) | C20: =IF($A20="","",SUMIFS(Saisie!$E$2:$E$501,Saisie!$C$2:$C$501,$A20,Saisie!$A$2:$A$501,">="&DATE(Annee,2,1),Saisie!$A$2:$A$501,"<"&DATE(Annee,3,1))) | D20: =IF($A20="","",SUMIFS(Saisie!$E$2:$E$501,Saisie!$C$2:$C$501,$A20,Saisie!$A$2:$A$501,">="&DATE(Annee,3,1),Saisie!$A$2:$A$501,"<"&DATE(Annee,4,1))) | E20: =IF($A20="","",SUMIFS(Saisie!$E$2:$E$501,Saisie!$C$2:$C$501,$A20,Saisie!$A$2:$A$501,">="&DATE(Annee,4,1),Saisie!$A$2:$A$501,"<"&DATE(Annee,5,1))) | F20: =IF($A20="","",SUMIFS(Saisie!$E$2:$E$501,Saisie!$C$2:$C$501,$A20,Saisie!$A$2:$A$501,">="&DATE(Annee,5,1),Saisie!$A$2:$A$501,"<"&DATE(Annee,6,1))) | G20: =IF($A20="","",SUMIFS(Saisie!$E$2:$E$501,Saisie!$C$2:$C$501,$A20,Saisie!$A$2:$A$501,">="&DATE(Annee,6,1),Saisie!$A$2:$A$501,"<"&DATE(Annee,7,1))) | H20: =IF($A20="","",SUMIFS(Saisie!$E$2:$E$501,Saisie!$C$2:$C$501,$A20,Saisie!$A$2:$A$501,">="&DATE(Annee,7,1),Saisie!$A$2:$A$501,"<"&DATE(Annee,8,1))) | I20: =IF($A20="","",SUMIFS(Saisie!$E$2:$E$501,Saisie!$C$2:$C$501,$A20,Saisie!$A$2:$A$501,">="&DATE(Annee,8,1),Saisie!$A$2:$A$501,"<"&DATE(Annee,9,1))) | J20: =IF($A20="","",SUMIFS(Saisie!$E$2:$E$501,Saisie!$C$2:$C$501,$A20,Saisie!$A$2:$A$501,">="&DATE(Annee,9,1),Saisie!$A$2:$A$501,"<"&DATE(Annee,10,1))) | K20: =IF($A20="","",SUMIFS(Saisie!$E$2:$E$501,Saisie!$C$2:$C$501,$A20,Saisie!$A$2:$A$501,">="&DATE(Annee,10,1),Saisie!$A$2:$A$501,"<"&DATE(Annee,11,1))) | L20: =IF($A20="","",SUMIFS(Saisie!$E$2:$E$501,Saisie!$C$2:$C$501,$A20,Saisie!$A$2:$A$501,">="&DATE(Annee,11,1),Saisie!$A$2:$A$501,"<"&DATE(Annee,12,1))) | M20: =IF($A20="","",SUMIFS(Saisie!$E$2:$E$501,Saisie!$C$2:$C$501,$A20,Saisie!$A$2:$A$501,">="&DATE(Annee,12,1),Saisie!$A$2:$A$501,"<"&DATE(Annee,13,1))) | N20: =IF($A20="","",SUM(B20:M20))
A21: =IF(INDEX(Liste_Projets,17)="","",INDEX(Liste_Projets,17)) | B21: =IF($A21="","",SUMIFS(Saisie!$E$2:$E$501,Saisie!$C$2:$C$501,$A21,Saisie!$A$2:$A$501,">="&DATE(Annee,1,1),Saisie!$A$2:$A$501,"<"&DATE(Annee,2,1))) | C21: =IF($A21="","",SUMIFS(Saisie!$E$2:$E$501,Saisie!$C$2:$C$501,$A21,Saisie!$A$2:$A$501,">="&DATE(Annee,2,1),Saisie!$A$2:$A$501,"<"&DATE(Annee,3,1))) | D21: =IF($A21="","",SUMIFS(Saisie!$E$2:$E$501,Saisie!$C$2:$C$501,$A21,Saisie!$A$2:$A$501,">="&DATE(Annee,3,1),Saisie!$A$2:$A$501,"<"&DATE(Annee,4,1))) | E21: =IF($A21="","",SUMIFS(Saisie!$E$2:$E$501,Saisie!$C$2:$C$501,$A21,Saisie!$A$2:$A$501,">="&DATE(Annee,4,1),Saisie!$A$2:$A$501,"<"&DATE(Annee,5,1))) | F21: =IF($A21="","",SUMIFS(Saisie!$E$2:$E$501,Saisie!$C$2:$C$501,$A21,Saisie!$A$2:$A$501,">="&DATE(Annee,5,1),Saisie!$A$2:$A$501,"<"&DATE(Annee,6,1))) | G21: =IF($A21="","",SUMIFS(Saisie!$E$2:$E$501,Saisie!$C$2:$C$501,$A21,Saisie!$A$2:$A$501,">="&DATE(Annee,6,1),Saisie!$A$2:$A$501,"<"&DATE(Annee,7,1))) | H21: =IF($A21="","",SUMIFS(Saisie!$E$2:$E$501,Saisie!$C$2:$C$501,$A21,Saisie!$A$2:$A$501,">="&DATE(Annee,7,1),Saisie!$A$2:$A$501,"<"&DATE(Annee,8,1))) | I21: =IF($A21="","",SUMIFS(Saisie!$E$2:$E$501,Saisie!$C$2:$C$501,$A21,Saisie!$A$2:$A$501,">="&DATE(Annee,8,1),Saisie!$A$2:$A$501,"<"&DATE(Annee,9,1))) | J21: =IF($A21="","",SUMIFS(Saisie!$E$2:$E$501,Saisie!$C$2:$C$501,$A21,Saisie!$A$2:$A$501,">="&DATE(Annee,9,1),Saisie!$A$2:$A$501,"<"&DATE(Annee,10,1))) | K21: =IF($A21="","",SUMIFS(Saisie!$E$2:$E$501,Saisie!$C$2:$C$501,$A21,Saisie!$A$2:$A$501,">="&DATE(Annee,10,1),Saisie!$A$2:$A$501,"<"&DATE(Annee,11,1))) | L21: =IF($A21="","",SUMIFS(Saisie!$E$2:$E$501,Saisie!$C$2:$C$501,$A21,Saisie!$A$2:$A$501,">="&DATE(Annee,11,1),Saisie!$A$2:$A$501,"<"&DATE(Annee,12,1))) | M21: =IF($A21="","",SUMIFS(Saisie!$E$2:$E$501,Saisie!$C$2:$C$501,$A21,Saisie!$A$2:$A$501,">="&DATE(Annee,12,1),Saisie!$A$2:$A$501,"<"&DATE(Annee,13,1))) | N21: =IF($A21="","",SUM(B21:M21))
A22: =IF(INDEX(Liste_Projets,18)="","",INDEX(Liste_Projets,18)) | B22: =IF($A22="","",SUMIFS(Saisie!$E$2:$E$501,Saisie!$C$2:$C$501,$A22,Saisie!$A$2:$A$501,">="&DATE(Annee,1,1),Saisie!$A$2:$A$501,"<"&DATE(Annee,2,1))) | C22: =IF($A22="","",SUMIFS(Saisie!$E$2:$E$501,Saisie!$C$2:$C$501,$A22,Saisie!$A$2:$A$501,">="&DATE(Annee,2,1),Saisie!$A$2:$A$501,"<"&DATE(Annee,3,1))) | D22: =IF($A22="","",SUMIFS(Saisie!$E$2:$E$501,Saisie!$C$2:$C$501,$A22,Saisie!$A$2:$A$501,">="&DATE(Annee,3,1),Saisie!$A$2:$A$501,"<"&DATE(Annee,4,1))) | E22: =IF($A22="","",SUMIFS(Saisie!$E$2:$E$501,Saisie!$C$2:$C$501,$A22,Saisie!$A$2:$A$501,">="&DATE(Annee,4,1),Saisie!$A$2:$A$501,"<"&DATE(Annee,5,1))) | F22: =IF($A22="","",SUMIFS(Saisie!$E$2:$E$501,Saisie!$C$2:$C$501,$A22,Saisie!$A$2:$A$501,">="&DATE(Annee,5,1),Saisie!$A$2:$A$501,"<"&DATE(Annee,6,1))) | G22: =IF($A22="","",SUMIFS(Saisie!$E$2:$E$501,Saisie!$C$2:$C$501,$A22,Saisie!$A$2:$A$501,">="&DATE(Annee,6,1),Saisie!$A$2:$A$501,"<"&DATE(Annee,7,1))) | H22: =IF($A22="","",SUMIFS(Saisie!$E$2:$E$501,Saisie!$C$2:$C$501,$A22,Saisie!$A$2:$A$501,">="&DATE(Annee,7,1),Saisie!$A$2:$A$501,"<"&DATE(Annee,8,1))) | I22: =IF($A22="","",SUMIFS(Saisie!$E$2:$E$501,Saisie!$C$2:$C$501,$A22,Saisie!$A$2:$A$501,">="&DATE(Annee,8,1),Saisie!$A$2:$A$501,"<"&DATE(Annee,9,1))) | J22: =IF($A22="","",SUMIFS(Saisie!$E$2:$E$501,Saisie!$C$2:$C$501,$A22,Saisie!$A$2:$A$501,">="&DATE(Annee,9,1),Saisie!$A$2:$A$501,"<"&DATE(Annee,10,1))) | K22: =IF($A22="","",SUMIFS(Saisie!$E$2:$E$501,Saisie!$C$2:$C$501,$A22,Saisie!$A$2:$A$501,">="&DATE(Annee,10,1),Saisie!$A$2:$A$501,"<"&DATE(Annee,11,1))) | L22: =IF($A22="","",SUMIFS(Saisie!$E$2:$E$501,Saisie!$C$2:$C$501,$A22,Saisie!$A$2:$A$501,">="&DATE(Annee,11,1),Saisie!$A$2:$A$501,"<"&DATE(Annee,12,1))) | M22: =IF($A22="","",SUMIFS(Saisie!$E$2:$E$501,Saisie!$C$2:$C$501,$A22,Saisie!$A$2:$A$501,">="&DATE(Annee,12,1),Saisie!$A$2:$A$501,"<"&DATE(Annee,13,1))) | N22: =IF($A22="","",SUM(B22:M22))
A23: =IF(INDEX(Liste_Projets,19)="","",INDEX(Liste_Projets,19)) | B23: =IF($A23="","",SUMIFS(Saisie!$E$2:$E$501,Saisie!$C$2:$C$501,$A23,Saisie!$A$2:$A$501,">="&DATE(Annee,1,1),Saisie!$A$2:$A$501,"<"&DATE(Annee,2,1))) | C23: =IF($A23="","",SUMIFS(Saisie!$E$2:$E$501,Saisie!$C$2:$C$501,$A23,Saisie!$A$2:$A$501,">="&DATE(Annee,2,1),Saisie!$A$2:$A$501,"<"&DATE(Annee,3,1))) | D23: =IF($A23="","",SUMIFS(Saisie!$E$2:$E$501,Saisie!$C$2:$C$501,$A23,Saisie!$A$2:$A$501,">="&DATE(Annee,3,1),Saisie!$A$2:$A$501,"<"&DATE(Annee,4,1))) | E23: =IF($A23="","",SUMIFS(Saisie!$E$2:$E$501,Saisie!$C$2:$C$501,$A23,Saisie!$A$2:$A$501,">="&DATE(Annee,4,1),Saisie!$A$2:$A$501,"<"&DATE(Annee,5,1))) | F23: =IF($A23="","",SUMIFS(Saisie!$E$2:$E$501,Saisie!$C$2:$C$501,$A23,Saisie!$A$2:$A$501,">="&DATE(Annee,5,1),Saisie!$A$2:$A$501,"<"&DATE(Annee,6,1))) | G23: =IF($A23="","",SUMIFS(Saisie!$E$2:$E$501,Saisie!$C$2:$C$501,$A23,Saisie!$A$2:$A$501,">="&DATE(Annee,6,1),Saisie!$A$2:$A$501,"<"&DATE(Annee,7,1))) | H23: =IF($A23="","",SUMIFS(Saisie!$E$2:$E$501,Saisie!$C$2:$C$501,$A23,Saisie!$A$2:$A$501,">="&DATE(Annee,7,1),Saisie!$A$2:$A$501,"<"&DATE(Annee,8,1))) | I23: =IF($A23="","",SUMIFS(Saisie!$E$2:$E$501,Saisie!$C$2:$C$501,$A23,Saisie!$A$2:$A$501,">="&DATE(Annee,8,1),Saisie!$A$2:$A$501,"<"&DATE(Annee,9,1))) | J23: =IF($A23="","",SUMIFS(Saisie!$E$2:$E$501,Saisie!$C$2:$C$501,$A23,Saisie!$A$2:$A$501,">="&DATE(Annee,9,1),Saisie!$A$2:$A$501,"<"&DATE(Annee,10,1))) | K23: =IF($A23="","",SUMIFS(Saisie!$E$2:$E$501,Saisie!$C$2:$C$501,$A23,Saisie!$A$2:$A$501,">="&DATE(Annee,10,1),Saisie!$A$2:$A$501,"<"&DATE(Annee,11,1))) | L23: =IF($A23="","",SUMIFS(Saisie!$E$2:$E$501,Saisie!$C$2:$C$501,$A23,Saisie!$A$2:$A$501,">="&DATE(Annee,11,1),Saisie!$A$2:$A$501,"<"&DATE(Annee,12,1))) | M23: =IF($A23="","",SUMIFS(Saisie!$E$2:$E$501,Saisie!$C$2:$C$501,$A23,Saisie!$A$2:$A$501,">="&DATE(Annee,12,1),Saisie!$A$2:$A$501,"<"&DATE(Annee,13,1))) | N23: =IF($A23="","",SUM(B23:M23))
A24: =IF(INDEX(Liste_Projets,20)="","",INDEX(Liste_Projets,20)) | B24: =IF($A24="","",SUMIFS(Saisie!$E$2:$E$501,Saisie!$C$2:$C$501,$A24,Saisie!$A$2:$A$501,">="&DATE(Annee,1,1),Saisie!$A$2:$A$501,"<"&DATE(Annee,2,1))) | C24: =IF($A24="","",SUMIFS(Saisie!$E$2:$E$501,Saisie!$C$2:$C$501,$A24,Saisie!$A$2:$A$501,">="&DATE(Annee,2,1),Saisie!$A$2:$A$501,"<"&DATE(Annee,3,1))) | D24: =IF($A24="","",SUMIFS(Saisie!$E$2:$E$501,Saisie!$C$2:$C$501,$A24,Saisie!$A$2:$A$501,">="&DATE(Annee,3,1),Saisie!$A$2:$A$501,"<"&DATE(Annee,4,1))) | E24: =IF($A24="","",SUMIFS(Saisie!$E$2:$E$501,Saisie!$C$2:$C$501,$A24,Saisie!$A$2:$A$501,">="&DATE(Annee,4,1),Saisie!$A$2:$A$501,"<"&DATE(Annee,5,1))) | F24: =IF($A24="","",SUMIFS(Saisie!$E$2:$E$501,Saisie!$C$2:$C$501,$A24,Saisie!$A$2:$A$501,">="&DATE(Annee,5,1),Saisie!$A$2:$A$501,"<"&DATE(Annee,6,1))) | G24: =IF($A24="","",SUMIFS(Saisie!$E$2:$E$501,Saisie!$C$2:$C$501,$A24,Saisie!$A$2:$A$501,">="&DATE(Annee,6,1),Saisie!$A$2:$A$501,"<"&DATE(Annee,7,1))) | H24: =IF($A24="","",SUMIFS(Saisie!$E$2:$E$501,Saisie!$C$2:$C$501,$A24,Saisie!$A$2:$A$501,">="&DATE(Annee,7,1),Saisie!$A$2:$A$501,"<"&DATE(Annee,8,1))) | I24: =IF($A24="","",SUMIFS(Saisie!$E$2:$E$501,Saisie!$C$2:$C$501,$A24,Saisie!$A$2:$A$501,">="&DATE(Annee,8,1),Saisie!$A$2:$A$501,"<"&DATE(Annee,9,1))) | J24: =IF($A24="","",SUMIFS(Saisie!$E$2:$E$501,Saisie!$C$2:$C$501,$A24,Saisie!$A$2:$A$501,">="&DATE(Annee,9,1),Saisie!$A$2:$A$501,"<"&DATE(Annee,10,1))) | K24: =IF($A24="","",SUMIFS(Saisie!$E$2:$E$501,Saisie!$C$2:$C$501,$A24,Saisie!$A$2:$A$501,">="&DATE(Annee,10,1),Saisie!$A$2:$A$501,"<"&DATE(Annee,11,1))) | L24: =IF($A24="","",SUMIFS(Saisie!$E$2:$E$501,Saisie!$C$2:$C$501,$A24,Saisie!$A$2:$A$501,">="&DATE(Annee,11,1),Saisie!$A$2:$A$501,"<"&DATE(Annee,12,1))) | M24: =IF($A24="","",SUMIFS(Saisie!$E$2:$E$501,Saisie!$C$2:$C$501,$A24,Saisie!$A$2:$A$501,">="&DATE(Annee,12,1),Saisie!$A$2:$A$501,"<"&DATE(Annee,13,1))) | N24: =IF($A24="","",SUM(B24:M24))
A25: =IF(INDEX(Liste_Projets,21)="","",INDEX(Liste_Projets,21)) | B25: =IF($A25="","",SUMIFS(Saisie!$E$2:$E$501,Saisie!$C$2:$C$501,$A25,Saisie!$A$2:$A$501,">="&DATE(Annee,1,1),Saisie!$A$2:$A$501,"<"&DATE(Annee,2,1))) | C25: =IF($A25="","",SUMIFS(Saisie!$E$2:$E$501,Saisie!$C$2:$C$501,$A25,Saisie!$A$2:$A$501,">="&DATE(Annee,2,1),Saisie!$A$2:$A$501,"<"&DATE(Annee,3,1))) | D25: =IF($A25="","",SUMIFS(Saisie!$E$2:$E$501,Saisie!$C$2:$C$501,$A25,Saisie!$A$2:$A$501,">="&DATE(Annee,3,1),Saisie!$A$2:$A$501,"<"&DATE(Annee,4,1))) | E25: =IF($A25="","",SUMIFS(Saisie!$E$2:$E$501,Saisie!$C$2:$C$501,$A25,Saisie!$A$2:$A$501,">="&DATE(Annee,4,1),Saisie!$A$2:$A$501,"<"&DATE(Annee,5,1))) | F25: =IF($A25="","",SUMIFS(Saisie!$E$2:$E$501,Saisie!$C$2:$C$501,$A25,Saisie!$A$2:$A$501,">="&DATE(Annee,5,1),Saisie!$A$2:$A$501,"<"&DATE(Annee,6,1))) | G25: =IF($A25="","",SUMIFS(Saisie!$E$2:$E$501,Saisie!$C$2:$C$501,$A25,Saisie!$A$2:$A$501,">="&DATE(Annee,6,1),Saisie!$A$2:$A$501,"<"&DATE(Annee,7,1))) | H25: =IF($A25="","",SUMIFS(Saisie!$E$2:$E$501,Saisie!$C$2:$C$501,$A25,Saisie!$A$2:$A$501,">="&DATE(Annee,7,1),Saisie!$A$2:$A$501,"<"&DATE(Annee,8,1))) | I25: =IF($A25="","",SUMIFS(Saisie!$E$2:$E$501,Saisie!$C$2:$C$501,$A25,Saisie!$A$2:$A$501,">="&DATE(Annee,8,1),Saisie!$A$2:$A$501,"<"&DATE(Annee,9,1))) | J25: =IF($A25="","",SUMIFS(Saisie!$E$2:$E$501,Saisie!$C$2:$C$501,$A25,Saisie!$A$2:$A$501,">="&DATE(Annee,9,1),Saisie!$A$2:$A$501,"<"&DATE(Annee,10,1))) | K25: =IF($A25="","",SUMIFS(Saisie!$E$2:$E$501,Saisie!$C$2:$C$501,$A25,Saisie!$A$2:$A$501,">="&DATE(Annee,10,1),Saisie!$A$2:$A$501,"<"&DATE(Annee,11,1))) | L25: =IF($A25="","",SUMIFS(Saisie!$E$2:$E$501,Saisie!$C$2:$C$501,$A25,Saisie!$A$2:$A$501,">="&DATE(Annee,11,1),Saisie!$A$2:$A$501,"<"&DATE(Annee,12,1))) | M25: =IF($A25="","",SUMIFS(Saisie!$E$2:$E$501,Saisie!$C$2:$C$501,$A25,Saisie!$A$2:$A$501,">="&DATE(Annee,12,1),Saisie!$A$2:$A$501,"<"&DATE(Annee,13,1))) | N25: =IF($A25="","",SUM(B25:M25))
A26: =IF(INDEX(Liste_Projets,22)="","",INDEX(Liste_Projets,22)) | B26: =IF($A26="","",SUMIFS(Saisie!$E$2:$E$501,Saisie!$C$2:$C$501,$A26,Saisie!$A$2:$A$501,">="&DATE(Annee,1,1),Saisie!$A$2:$A$501,"<"&DATE(Annee,2,1))) | C26: =IF($A26="","",SUMIFS(Saisie!$E$2:$E$501,Saisie!$C$2:$C$501,$A26,Saisie!$A$2:$A$501,">="&DATE(Annee,2,1),Saisie!$A$2:$A$501,"<"&DATE(Annee,3,1))) | D26: =IF($A26="","",SUMIFS(Saisie!$E$2:$E$501,Saisie!$C$2:$C$501,$A26,Saisie!$A$2:$A$501,">="&DATE(Annee,3,1),Saisie!$A$2:$A$501,"<"&DATE(Annee,4,1))) | E26: =IF($A26="","",SUMIFS(Saisie!$E$2:$E$501,Saisie!$C$2:$C$501,$A26,Saisie!$A$2:$A$501,">="&DATE(Annee,4,1),Saisie!$A$2:$A$501,"<"&DATE(Annee,5,1))) | F26: =IF($A26="","",SUMIFS(Saisie!$E$2:$E$501,Saisie!$C$2:$C$501,$A26,Saisie!$A$2:$A$501,">="&DATE(Annee,5,1),Saisie!$A$2:$A$501,"<"&DATE(Annee,6,1))) | G26: =IF($A26="","",SUMIFS(Saisie!$E$2:$E$501,Saisie!$C$2:$C$501,$A26,Saisie!$A$2:$A$501,">="&DATE(Annee,6,1),Saisie!$A$2:$A$501,"<"&DATE(Annee,7,1))) | H26: =IF($A26="","",SUMIFS(Saisie!$E$2:$E$501,Saisie!$C$2:$C$501,$A26,Saisie!$A$2:$A$501,">="&DATE(Annee,7,1),Saisie!$A$2:$A$501,"<"&DATE(Annee,8,1))) | I26: =IF($A26="","",SUMIFS(Saisie!$E$2:$E$501,Saisie!$C$2:$C$501,$A26,Saisie!$A$2:$A$501,">="&DATE(Annee,8,1),Saisie!$A$2:$A$501,"<"&DATE(Annee,9,1))) | J26: =IF($A26="","",SUMIFS(Saisie!$E$2:$E$501,Saisie!$C$2:$C$501,$A26,Saisie!$A$2:$A$501,">="&DATE(Annee,9,1),Saisie!$A$2:$A$501,"<"&DATE(Annee,10,1))) | K26: =IF($A26="","",SUMIFS(Saisie!$E$2:$E$501,Saisie!$C$2:$C$501,$A26,Saisie!$A$2:$A$501,">="&DATE(Annee,10,1),Saisie!$A$2:$A$501,"<"&DATE(Annee,11,1))) | L26: =IF($A26="","",SUMIFS(Saisie!$E$2:$E$501,Saisie!$C$2:$C$501,$A26,Saisie!$A$2:$A$501,">="&DATE(Annee,11,1),Saisie!$A$2:$A$501,"<"&DATE(Annee,12,1))) | M26: =IF($A26="","",SUMIFS(Saisie!$E$2:$E$501,Saisie!$C$2:$C$501,$A26,Saisie!$A$2:$A$501,">="&DATE(Annee,12,1),Saisie!$A$2:$A$501,"<"&DATE(Annee,13,1))) | N26: =IF($A26="","",SUM(B26:M26))
A27: =IF(INDEX(Liste_Projets,23)="","",INDEX(Liste_Projets,23)) | B27: =IF($A27="","",SUMIFS(Saisie!$E$2:$E$501,Saisie!$C$2:$C$501,$A27,Saisie!$A$2:$A$501,">="&DATE(Annee,1,1),Saisie!$A$2:$A$501,"<"&DATE(Annee,2,1))) | C27: =IF($A27="","",SUMIFS(Saisie!$E$2:$E$501,Saisie!$C$2:$C$501,$A27,Saisie!$A$2:$A$501,">="&DATE(Annee,2,1),Saisie!$A$2:$A$501,"<"&DATE(Annee,3,1))) | D27: =IF($A27="","",SUMIFS(Saisie!$E$2:$E$501,Saisie!$C$2:$C$501,$A27,Saisie!$A$2:$A$501,">="&DATE(Annee,3,1),Saisie!$A$2:$A$501,"<"&DATE(Annee,4,1))) | E27: =IF($A27="","",SUMIFS(Saisie!$E$2:$E$501,Saisie!$C$2:$C$501,$A27,Saisie!$A$2:$A$501,">="&DATE(Annee,4,1),Saisie!$A$2:$A$501,"<"&DATE(Annee,5,1))) | F27: =IF($A27="","",SUMIFS(Saisie!$E$2:$E$501,Saisie!$C$2:$C$501,$A27,Saisie!$A$2:$A$501,">="&DATE(Annee,5,1),Saisie!$A$2:$A$501,"<"&DATE(Annee,6,1))) | G27: =IF($A27="","",SUMIFS(Saisie!$E$2:$E$501,Saisie!$C$2:$C$501,$A27,Saisie!$A$2:$A$501,">="&DATE(Annee,6,1),Saisie!$A$2:$A$501,"<"&DATE(Annee,7,1))) | H27: =IF($A27="","",SUMIFS(Saisie!$E$2:$E$501,Saisie!$C$2:$C$501,$A27,Saisie!$A$2:$A$501,">="&DATE(Annee,7,1),Saisie!$A$2:$A$501,"<"&DATE(Annee,8,1))) | I27: =IF($A27="","",SUMIFS(Saisie!$E$2:$E$501,Saisie!$C$2:$C$501,$A27,Saisie!$A$2:$A$501,">="&DATE(Annee,8,1),Saisie!$A$2:$A$501,"<"&DATE(Annee,9,1))) | J27: =IF($A27="","",SUMIFS(Saisie!$E$2:$E$501,Saisie!$C$2:$C$501,$A27,Saisie!$A$2:$A$501,">="&DATE(Annee,9,1),Saisie!$A$2:$A$501,"<"&DATE(Annee,10,1))) | K27: =IF($A27="","",SUMIFS(Saisie!$E$2:$E$501,Saisie!$C$2:$C$501,$A27,Saisie!$A$2:$A$501,">="&DATE(Annee,10,1),Saisie!$A$2:$A$501,"<"&DATE(Annee,11,1))) | L27: =IF($A27="","",SUMIFS(Saisie!$E$2:$E$501,Saisie!$C$2:$C$501,$A27,Saisie!$A$2:$A$501,">="&DATE(Annee,11,1),Saisie!$A$2:$A$501,"<"&DATE(Annee,12,1))) | M27: =IF($A27="","",SUMIFS(Saisie!$E$2:$E$501,Saisie!$C$2:$C$501,$A27,Saisie!$A$2:$A$501,">="&DATE(Annee,12,1),Saisie!$A$2:$A$501,"<"&DATE(Annee,13,1))) | N27: =IF($A27="","",SUM(B27:M27))
A28: =IF(INDEX(Liste_Projets,24)="","",INDEX(Liste_Projets,24)) | B28: =IF($A28="","",SUMIFS(Saisie!$E$2:$E$501,Saisie!$C$2:$C$501,$A28,Saisie!$A$2:$A$501,">="&DATE(Annee,1,1),Saisie!$A$2:$A$501,"<"&DATE(Annee,2,1))) | C28: =IF($A28="","",SUMIFS(Saisie!$E$2:$E$501,Saisie!$C$2:$C$501,$A28,Saisie!$A$2:$A$501,">="&DATE(Annee,2,1),Saisie!$A$2:$A$501,"<"&DATE(Annee,3,1))) | D28: =IF($A28="","",SUMIFS(Saisie!$E$2:$E$501,Saisie!$C$2:$C$501,$A28,Saisie!$A$2:$A$501,">="&DATE(Annee,3,1),Saisie!$A$2:$A$501,"<"&DATE(Annee,4,1))) | E28: =IF($A28="","",SUMIFS(Saisie!$E$2:$E$501,Saisie!$C$2:$C$501,$A28,Saisie!$A$2:$A$501,">="&DATE(Annee,4,1),Saisie!$A$2:$A$501,"<"&DATE(Annee,5,1))) | F28: =IF($A28="","",SUMIFS(Saisie!$E$2:$E$501,Saisie!$C$2:$C$501,$A28,Saisie!$A$2:$A$501,">="&DATE(Annee,5,1),Saisie!$A$2:$A$501,"<"&DATE(Annee,6,1))) | G28: =IF($A28="","",SUMIFS(Saisie!$E$2:$E$501,Saisie!$C$2:$C$501,$A28,Saisie!$A$2:$A$501,">="&DATE(Annee,6,1),Saisie!$A$2:$A$501,"<"&DATE(Annee,7,1))) | H28: =IF($A28="","",SUMIFS(Saisie!$E$2:$E$501,Saisie!$C$2:$C$501,$A28,Saisie!$A$2:$A$501,">="&DATE(Annee,7,1),Saisie!$A$2:$A$501,"<"&DATE(Annee,8,1))) | I28: =IF($A28="","",SUMIFS(Saisie!$E$2:$E$501,Saisie!$C$2:$C$501,$A28,Saisie!$A$2:$A$501,">="&DATE(Annee,8,1),Saisie!$A$2:$A$501,"<"&DATE(Annee,9,1))) | J28: =IF($A28="","",SUMIFS(Saisie!$E$2:$E$501,Saisie!$C$2:$C$501,$A28,Saisie!$A$2:$A$501,">="&DATE(Annee,9,1),Saisie!$A$2:$A$501,"<"&DATE(Annee,10,1))) | K28: =IF($A28="","",SUMIFS(Saisie!$E$2:$E$501,Saisie!$C$2:$C$501,$A28,Saisie!$A$2:$A$501,">="&DATE(Annee,10,1),Saisie!$A$2:$A$501,"<"&DATE(Annee,11,1))) | L28: =IF($A28="","",SUMIFS(Saisie!$E$2:$E$501,Saisie!$C$2:$C$501,$A28,Saisie!$A$2:$A$501,">="&DATE(Annee,11,1),Saisie!$A$2:$A$501,"<"&DATE(Annee,12,1))) | M28: =IF($A28="","",SUMIFS(Saisie!$E$2:$E$501,Saisie!$C$2:$C$501,$A28,Saisie!$A$2:$A$501,">="&DATE(Annee,12,1),Saisie!$A$2:$A$501,"<"&DATE(Annee,13,1))) | N28: =IF($A28="","",SUM(B28:M28))
A29: =IF(INDEX(Liste_Projets,25)="","",INDEX(Liste_Projets,25)) | B29: =IF($A29="","",SUMIFS(Saisie!$E$2:$E$501,Saisie!$C$2:$C$501,$A29,Saisie!$A$2:$A$501,">="&DATE(Annee,1,1),Saisie!$A$2:$A$501,"<"&DATE(Annee,2,1))) | C29: =IF($A29="","",SUMIFS(Saisie!$E$2:$E$501,Saisie!$C$2:$C$501,$A29,Saisie!$A$2:$A$501,">="&DATE(Annee,2,1),Saisie!$A$2:$A$501,"<"&DATE(Annee,3,1))) | D29: =IF($A29="","",SUMIFS(Saisie!$E$2:$E$501,Saisie!$C$2:$C$501,$A29,Saisie!$A$2:$A$501,">="&DATE(Annee,3,1),Saisie!$A$2:$A$501,"<"&DATE(Annee,4,1))) | E29: =IF($A29="","",SUMIFS(Saisie!$E$2:$E$501,Saisie!$C$2:$C$501,$A29,Saisie!$A$2:$A$501,">="&DATE(Annee,4,1),Saisie!$A$2:$A$501,"<"&DATE(Annee,5,1))) | F29: =IF($A29="","",SUMIFS(Saisie!$E$2:$E$501,Saisie!$C$2:$C$501,$A29,Saisie!$A$2:$A$501,">="&DATE(Annee,5,1),Saisie!$A$2:$A$501,"<"&DATE(Annee,6,1))) | G29: =IF($A29="","",SUMIFS(Saisie!$E$2:$E$501,Saisie!$C$2:$C$501,$A29,Saisie!$A$2:$A$501,">="&DATE(Annee,6,1),Saisie!$A$2:$A$501,"<"&DATE(Annee,7,1))) | H29: =IF($A29="","",SUMIFS(Saisie!$E$2:$E$501,Saisie!$C$2:$C$501,$A29,Saisie!$A$2:$A$501,">="&DATE(Annee,7,1),Saisie!$A$2:$A$501,"<"&DATE(Annee,8,1))) | I29: =IF($A29="","",SUMIFS(Saisie!$E$2:$E$501,Saisie!$C$2:$C$501,$A29,Saisie!$A$2:$A$501,">="&DATE(Annee,8,1),Saisie!$A$2:$A$501,"<"&DATE(Annee,9,1))) | J29: =IF($A29="","",SUMIFS(Saisie!$E$2:$E$501,Saisie!$C$2:$C$501,$A29,Saisie!$A$2:$A$501,">="&DATE(Annee,9,1),Saisie!$A$2:$A$501,"<"&DATE(Annee,10,1))) | K29: =IF($A29="","",SUMIFS(Saisie!$E$2:$E$501,Saisie!$C$2:$C$501,$A29,Saisie!$A$2:$A$501,">="&DATE(Annee,10,1),Saisie!$A$2:$A$501,"<"&DATE(Annee,11,1))) | L29: =IF($A29="","",SUMIFS(Saisie!$E$2:$E$501,Saisie!$C$2:$C$501,$A29,Saisie!$A$2:$A$501,">="&DATE(Annee,11,1),Saisie!$A$2:$A$501,"<"&DATE(Annee,12,1))) | M29: =IF($A29="","",SUMIFS(Saisie!$E$2:$E$501,Saisie!$C$2:$C$501,$A29,Saisie!$A$2:$A$501,">="&DATE(Annee,12,1),Saisie!$A$2:$A$501,"<"&DATE(Annee,13,1))) | N29: =IF($A29="","",SUM(B29:M29))
A30: =IF(INDEX(Liste_Projets,26)="","",INDEX(Liste_Projets,26)) | B30: =IF($A30="","",SUMIFS(Saisie!$E$2:$E$501,Saisie!$C$2:$C$501,$A30,Saisie!$A$2:$A$501,">="&DATE(Annee,1,1),Saisie!$A$2:$A$501,"<"&DATE(Annee,2,1))) | C30: =IF($A30="","",SUMIFS(Saisie!$E$2:$E$501,Saisie!$C$2:$C$501,$A30,Saisie!$A$2:$A$501,">="&DATE(Annee,2,1),Saisie!$A$2:$A$501,"<"&DATE(Annee,3,1))) | D30: =IF($A30="","",SUMIFS(Saisie!$E$2:$E$501,Saisie!$C$2:$C$501,$A30,Saisie!$A$2:$A$501,">="&DATE(Annee,3,1),Saisie!$A$2:$A$501,"<"&DATE(Annee,4,1))) | E30: =IF($A30="","",SUMIFS(Saisie!$E$2:$E$501,Saisie!$C$2:$C$501,$A30,Saisie!$A$2:$A$501,">="&DATE(Annee,4,1),Saisie!$A$2:$A$501,"<"&DATE(Annee,5,1))) | F30: =IF($A30="","",SUMIFS(Saisie!$E$2:$E$501,Saisie!$C$2:$C$501,$A30,Saisie!$A$2:$A$501,">="&DATE(Annee,5,1),Saisie!$A$2:$A$501,"<"&DATE(Annee,6,1))) | G30: =IF($A30="","",SUMIFS(Saisie!$E$2:$E$501,Saisie!$C$2:$C$501,$A30,Saisie!$A$2:$A$501,">="&DATE(Annee,6,1),Saisie!$A$2:$A$501,"<"&DATE(Annee,7,1))) | H30: =IF($A30="","",SUMIFS(Saisie!$E$2:$E$501,Saisie!$C$2:$C$501,$A30,Saisie!$A$2:$A$501,">="&DATE(Annee,7,1),Saisie!$A$2:$A$501,"<"&DATE(Annee,8,1))) | I30: =IF($A30="","",SUMIFS(Saisie!$E$2:$E$501,Saisie!$C$2:$C$501,$A30,Saisie!$A$2:$A$501,">="&DATE(Annee,8,1),Saisie!$A$2:$A$501,"<"&DATE(Annee,9,1))) | J30: =IF($A30="","",SUMIFS(Saisie!$E$2:$E$501,Saisie!$C$2:$C$501,$A30,Saisie!$A$2:$A$501,">="&DATE(Annee,9,1),Saisie!$A$2:$A$501,"<"&DATE(Annee,10,1))) | K30: =IF($A30="","",SUMIFS(Saisie!$E$2:$E$501,Saisie!$C$2:$C$501,$A30,Saisie!$A$2:$A$501,">="&DATE(Annee,10,1),Saisie!$A$2:$A$501,"<"&DATE(Annee,11,1))) | L30: =IF($A30="","",SUMIFS(Saisie!$E$2:$E$501,Saisie!$C$2:$C$501,$A30,Saisie!$A$2:$A$501,">="&DATE(Annee,11,1),Saisie!$A$2:$A$501,"<"&DATE(Annee,12,1))) | M30: =IF($A30="","",SUMIFS(Saisie!$E$2:$E$501,Saisie!$C$2:$C$501,$A30,Saisie!$A$2:$A$501,">="&DATE(Annee,12,1),Saisie!$A$2:$A$501,"<"&DATE(Annee,13,1))) | N30: =IF($A30="","",SUM(B30:M30))
A31: =IF(INDEX(Liste_Projets,27)="","",INDEX(Liste_Projets,27)) | B31: =IF($A31="","",SUMIFS(Saisie!$E$2:$E$501,Saisie!$C$2:$C$501,$A31,Saisie!$A$2:$A$501,">="&DATE(Annee,1,1),Saisie!$A$2:$A$501,"<"&DATE(Annee,2,1))) | C31: =IF($A31="","",SUMIFS(Saisie!$E$2:$E$501,Saisie!$C$2:$C$501,$A31,Saisie!$A$2:$A$501,">="&DATE(Annee,2,1),Saisie!$A$2:$A$501,"<"&DATE(Annee,3,1))) | D31: =IF($A31="","",SUMIFS(Saisie!$E$2:$E$501,Saisie!$C$2:$C$501,$A31,Saisie!$A$2:$A$501,">="&DATE(Annee,3,1),Saisie!$A$2:$A$501,"<"&DATE(Annee,4,1))) | E31: =IF($A31="","",SUMIFS(Saisie!$E$2:$E$501,Saisie!$C$2:$C$501,$A31,Saisie!$A$2:$A$501,">="&DATE(Annee,4,1),Saisie!$A$2:$A$501,"<"&DATE(Annee,5,1))) | F31: =IF($A31="","",SUMIFS(Saisie!$E$2:$E$501,Saisie!$C$2:$C$501,$A31,Saisie!$A$2:$A$501,">="&DATE(Annee,5,1),Saisie!$A$2:$A$501,"<"&DATE(Annee,6,1))) | G31: =IF($A31="","",SUMIFS(Saisie!$E$2:$E$501,Saisie!$C$2:$C$501,$A31,Saisie!$A$2:$A$501,">="&DATE(Annee,6,1),Saisie!$A$2:$A$501,"<"&DATE(Annee,7,1))) | H31: =IF($A31="","",SUMIFS(Saisie!$E$2:$E$501,Saisie!$C$2:$C$501,$A31,Saisie!$A$2:$A$501,">="&DATE(Annee,7,1),Saisie!$A$2:$A$501,"<"&DATE(Annee,8,1))) | I31: =IF($A31="","",SUMIFS(Saisie!$E$2:$E$501,Saisie!$C$2:$C$501,$A31,Saisie!$A$2:$A$501,">="&DATE(Annee,8,1),Saisie!$A$2:$A$501,"<"&DATE(Annee,9,1))) | J31: =IF($A31="","",SUMIFS(Saisie!$E$2:$E$501,Saisie!$C$2:$C$501,$A31,Saisie!$A$2:$A$501,">="&DATE(Annee,9,1),Saisie!$A$2:$A$501,"<"&DATE(Annee,10,1))) | K31: =IF($A31="","",SUMIFS(Saisie!$E$2:$E$501,Saisie!$C$2:$C$501,$A31,Saisie!$A$2:$A$501,">="&DATE(Annee,10,1),Saisie!$A$2:$A$501,"<"&DATE(Annee,11,1))) | L31: =IF($A31="","",SUMIFS(Saisie!$E$2:$E$501,Saisie!$C$2:$C$501,$A31,Saisie!$A$2:$A$501,">="&DATE(Annee,11,1),Saisie!$A$2:$A$501,"<"&DATE(Annee,12,1))) | M31: =IF($A31="","",SUMIFS(Saisie!$E$2:$E$501,Saisie!$C$2:$C$501,$A31,Saisie!$A$2:$A$501,">="&DATE(Annee,12,1),Saisie!$A$2:$A$501,"<"&DATE(Annee,13,1))) | N31: =IF($A31="","",SUM(B31:M31))
A32: =IF(INDEX(Liste_Projets,28)="","",INDEX(Liste_Projets,28)) | B32: =IF($A32="","",SUMIFS(Saisie!$E$2:$E$501,Saisie!$C$2:$C$501,$A32,Saisie!$A$2:$A$501,">="&DATE(Annee,1,1),Saisie!$A$2:$A$501,"<"&DATE(Annee,2,1))) | C32: =IF($A32="","",SUMIFS(Saisie!$E$2:$E$501,Saisie!$C$2:$C$501,$A32,Saisie!$A$2:$A$501,">="&DATE(Annee,2,1),Saisie!$A$2:$A$501,"<"&DATE(Annee,3,1))) | D32: =IF($A32="","",SUMIFS(Saisie!$E$2:$E$501,Saisie!$C$2:$C$501,$A32,Saisie!$A$2:$A$501,">="&DATE(Annee,3,1),Saisie!$A$2:$A$501,"<"&DATE(Annee,4,1))) | E32: =IF($A32="","",SUMIFS(Saisie!$E$2:$E$501,Saisie!$C$2:$C$501,$A32,Saisie!$A$2:$A$501,">="&DATE(Annee,4,1),Saisie!$A$2:$A$501,"<"&DATE(Annee,5,1))) | F32: =IF($A32="","",SUMIFS(Saisie!$E$2:$E$501,Saisie!$C$2:$C$501,$A32,Saisie!$A$2:$A$501,">="&DATE(Annee,5,1),Saisie!$A$2:$A$501,"<"&DATE(Annee,6,1))) | G32: =IF($A32="","",SUMIFS(Saisie!$E$2:$E$501,Saisie!$C$2:$C$501,$A32,Saisie!$A$2:$A$501,">="&DATE(Annee,6,1),Saisie!$A$2:$A$501,"<"&DATE(Annee,7,1))) | H32: =IF($A32="","",SUMIFS(Saisie!$E$2:$E$501,Saisie!$C$2:$C$501,$A32,Saisie!$A$2:$A$501,">="&DATE(Annee,7,1),Saisie!$A$2:$A$501,"<"&DATE(Annee,8,1))) | I32: =IF($A32="","",SUMIFS(Saisie!$E$2:$E$501,Saisie!$C$2:$C$501,$A32,Saisie!$A$2:$A$501,">="&DATE(Annee,8,1),Saisie!$A$2:$A$501,"<"&DATE(Annee,9,1))) | J32: =IF($A32="","",SUMIFS(Saisie!$E$2:$E$501,Saisie!$C$2:$C$501,$A32,Saisie!$A$2:$A$501,">="&DATE(Annee,9,1),Saisie!$A$2:$A$501,"<"&DATE(Annee,10,1))) | K32: =IF($A32="","",SUMIFS(Saisie!$E$2:$E$501,Saisie!$C$2:$C$501,$A32,Saisie!$A$2:$A$501,">="&DATE(Annee,10,1),Saisie!$A$2:$A$501,"<"&DATE(Annee,11,1))) | L32: =IF($A32="","",SUMIFS(Saisie!$E$2:$E$501,Saisie!$C$2:$C$501,$A32,Saisie!$A$2:$A$501,">="&DATE(Annee,11,1),Saisie!$A$2:$A$501,"<"&DATE(Annee,12,1))) | M32: =IF($A32="","",SUMIFS(Saisie!$E$2:$E$501,Saisie!$C$2:$C$501,$A32,Saisie!$A$2:$A$501,">="&DATE(Annee,12,1),Saisie!$A$2:$A$501,"<"&DATE(Annee,13,1))) | N32: =IF($A32="","",SUM(B32:M32))
A33: =IF(INDEX(Liste_Projets,29)="","",INDEX(Liste_Projets,29)) | B33: =IF($A33="","",SUMIFS(Saisie!$E$2:$E$501,Saisie!$C$2:$C$501,$A33,Saisie!$A$2:$A$501,">="&DATE(Annee,1,1),Saisie!$A$2:$A$501,"<"&DATE(Annee,2,1))) | C33: =IF($A33="","",SUMIFS(Saisie!$E$2:$E$501,Saisie!$C$2:$C$501,$A33,Saisie!$A$2:$A$501,">="&DATE(Annee,2,1),Saisie!$A$2:$A$501,"<"&DATE(Annee,3,1))) | D33: =IF($A33="","",SUMIFS(Saisie!$E$2:$E$501,Saisie!$C$2:$C$501,$A33,Saisie!$A$2:$A$501,">="&DATE(Annee,3,1),Saisie!$A$2:$A$501,"<"&DATE(Annee,4,1))) | E33: =IF($A33="","",SUMIFS(Saisie!$E$2:$E$501,Saisie!$C$2:$C$501,$A33,Saisie!$A$2:$A$501,">="&DATE(Annee,4,1),Saisie!$A$2:$A$501,"<"&DATE(Annee,5,1))) | F33: =IF($A33="","",SUMIFS(Saisie!$E$2:$E$501,Saisie!$C$2:$C$501,$A33,Saisie!$A$2:$A$501,">="&DATE(Annee,5,1),Saisie!$A$2:$A$501,"<"&DATE(Annee,6,1))) | G33: =IF($A33="","",SUMIFS(Saisie!$E$2:$E$501,Saisie!$C$2:$C$501,$A33,Saisie!$A$2:$A$501,">="&DATE(Annee,6,1),Saisie!$A$2:$A$501,"<"&DATE(Annee,7,1))) | H33: =IF($A33="","",SUMIFS(Saisie!$E$2:$E$501,Saisie!$C$2:$C$501,$A33,Saisie!$A$2:$A$501,">="&DATE(Annee,7,1),Saisie!$A$2:$A$501,"<"&DATE(Annee,8,1))) | I33: =IF($A33="","",SUMIFS(Saisie!$E$2:$E$501,Saisie!$C$2:$C$501,$A33,Saisie!$A$2:$A$501,">="&DATE(Annee,8,1),Saisie!$A$2:$A$501,"<"&DATE(Annee,9,1))) | J33: =IF($A33="","",SUMIFS(Saisie!$E$2:$E$501,Saisie!$C$2:$C$501,$A33,Saisie!$A$2:$A$501,">="&DATE(Annee,9,1),Saisie!$A$2:$A$501,"<"&DATE(Annee,10,1))) | K33: =IF($A33="","",SUMIFS(Saisie!$E$2:$E$501,Saisie!$C$2:$C$501,$A33,Saisie!$A$2:$A$501,">="&DATE(Annee,10,1),Saisie!$A$2:$A$501,"<"&DATE(Annee,11,1))) | L33: =IF($A33="","",SUMIFS(Saisie!$E$2:$E$501,Saisie!$C$2:$C$501,$A33,Saisie!$A$2:$A$501,">="&DATE(Annee,11,1),Saisie!$A$2:$A$501,"<"&DATE(Annee,12,1))) | M33: =IF($A33="","",SUMIFS(Saisie!$E$2:$E$501,Saisie!$C$2:$C$501,$A33,Saisie!$A$2:$A$501,">="&DATE(Annee,12,1),Saisie!$A$2:$A$501,"<"&DATE(Annee,13,1))) | N33: =IF($A33="","",SUM(B33:M33))
